<?xml version='1.0' encoding='UTF-8'?>
<robot xmlns:xacro="http://ros.org/wiki/xacro" name="scene">
  <!-- ridgeback robot begin -->
  <xacro:include filename="$(find ridgeback_dual_arm_description)/urdf/ridgeback_dual_arm.urdf.xacro" /> <!-- 内部修改 -->
  <!-- scence urdf living room -->
  <xacro:include filename="$(find env_description)/livingroom_env/main_fixed.xacro"/> <!-- 外部修改 -->

  <!-- Arguments -->
  <xacro:arg name="base_loc_x" default="0.0"/>
  <xacro:arg name="base_loc_y" default="0.0"/>
  <xacro:arg name="base_loc_orient" default="0.0"/>
  <xacro:arg name="robot_prefix" default=""/>

  <!-- Setup Environment -->
  <!--
    link order: world link -> virtual_base_x -> virtual_base_y -> virtual_base_theta -> base_link
  -->

  <link name="$(arg robot_prefix)virtual_base_theta"/>
  <joint name="$(arg robot_prefix)base_link_base_theta" type="revolute">
  <!-- <joint name="$(arg robot_prefix)base_link_base_theta" type="continuous"> -->
    <parent link="$(arg robot_prefix)virtual_base_theta" />
    <origin xyz="0.0 0.0 0.0" rpy="0 0 0" />
    <child link="base_link" />
    <axis xyz="0 0 1"/>
    <limit effort="20" velocity="5.0" lower="-3.14" upper="3.14"/>
    <!-- <limit effort="20" velocity="5.0"/> -->
  </joint>

  <link name="$(arg robot_prefix)virtual_base_y"/>
  <joint name="$(arg robot_prefix)base_theta_base_y" type="prismatic">
    <parent link="$(arg robot_prefix)virtual_base_y" />
    <origin xyz="0.0 0.0 0.0" rpy="0 0 0" />
    <child link="$(arg robot_prefix)virtual_base_theta" />
    <axis xyz="0 1 0"/>
    <limit effort="20" velocity="5.0" lower="-10" upper="10"/>
  </joint>

  <link name="$(arg robot_prefix)virtual_base_x"/>
  <joint name="$(arg robot_prefix)base_y_base_x" type="prismatic">
    <parent link="$(arg robot_prefix)virtual_base_x" />
    <origin xyz="0.0 0.0 0.0" rpy="0 0 0" />
    <child link="$(arg robot_prefix)virtual_base_y" />
    <axis xyz="1 0 0"/>
    <limit effort="20" velocity="5.0" lower="-10" upper="10"/>
  </joint>

  <!-- <link name="world"/> -->
  <joint name="world_to_base_footprint" type="fixed">
    <parent link="world"/>
    <child link="$(arg robot_prefix)virtual_base_x"/>
    <origin xyz="$(arg base_loc_x) $(arg base_loc_y) 0.01965" rpy="0 0 $(arg base_loc_orient)" />
  </joint>

  <!-- 圆柱行人建模 -->
  <link name="dynamic_pedestrian">
    <visual>
      <origin xyz="0 0 0" rpy="0 0 0" />
      <geometry>
        <cylinder radius="0.2" length="3.0"/>
      </geometry>
      <material name="blue">
        <color rgba="0 0 1 0.5" />
      </material>
    </visual>
    <collision>
      <origin xyz="0 0 0" rpy="0 0 0" />
      <geometry>
        <cylinder radius="0.2" length="3.0"/>
      </geometry>
    </collision>
  </link>
  <joint name="dynamic_pedestrian_joint" type="prismatic">
    <parent link="world"/>
    <child link="dynamic_pedestrian"/>
    <origin xyz="0.6 4.5 1.5" rpy="0 0 0" />
    <axis xyz="0 1 0"/>
    <limit effort="20" velocity="0.5" lower="-6" upper="6"/>
  </joint>

  <!-- ridgeback robot end -->
</robot>
