<?xml version="1.0" ?>
<!-- =================================================================================== -->
<!-- |    This document was autogenerated by xacro from vkc_big_task_place_door.urdf.xacro | -->
<!-- |    EDITING THIS FILE BY HAND IS NOT RECOMMENDED                                 | -->
<!-- =================================================================================== -->
<robot name="scene">
  <material name="dark_grey">
    <color rgba="0.2 0.2 0.2 1.0"/>
  </material>
  <material name="light_grey">
    <color rgba="0.4 0.4 0.4 1.0"/>
  </material>
  <material name="red">
    <color rgba="0.8 0.0 0.0 1.0"/>
  </material>
  <material name="white">
    <color rgba="0.9 0.9 0.9 1.0"/>
  </material>
  <material name="yellow">
    <color rgba="0.8 0.8 0.0 1.0"/>
  </material>
  <material name="black">
    <color rgba="0.15 0.15 0.15 1.0"/>
  </material>
  <link name="front_rocker_link">
    <visual>
      <origin rpy="1.5707963267948966 0 1.5707963267948966" xyz="0 0 0"/>
      <geometry>
        <mesh filename="package://ridgeback_description/meshes/rocker.stl"/>
      </geometry>
      <material name="black"/>
    </visual>
    <inertial>
      <origin rpy="1.5707963267948966 0 1.5707963267948966" xyz="0 0 0"/>
      <mass value="10.267"/>
      <inertia ixx="0.0288" ixy="2.20484e-6" ixz="-1.3145e-5" iyy="0.4324" iyz="1.8944e-3" izz="0.4130"/>
    </inertial>
  </link>
  <joint name="front_rocker" type="fixed">
    <parent link="axle_link"/>
    <child link="front_rocker_link"/>
    <origin rpy="0 0 0" xyz="0.319 0 0"/>
    <axis xyz="1 0 0"/>
    <limit effort="0" lower="-0.08726" upper="0.08726" velocity="0"/>
  </joint>
  <link name="front_left_wheel_link">
    <visual>
      <origin rpy="1.5707963267948966 0 0" xyz="0 0 0"/>
      <geometry>
        <mesh filename="package://ridgeback_description/meshes/wheel.stl"/>
      </geometry>
      <material name="black"/>
    </visual>
    <!-- <collision>
        <origin xyz="0 0 0" rpy="${PI/2} 0 0"/>
        <geometry>
          <cylinder radius="${wheel_radius}" length="${wheel_width}"/>
        </geometry>
      </collision> -->
    <inertial>
      <origin rpy="0 0 0" xyz="0 0 0"/>
      <mass value="2.3"/>
      <inertia ixx="3.3212e-3" ixy="0" ixz="0" iyy="6.6424e-3" iyz="0" izz="3.3212e-3"/>
    </inertial>
  </link>
  <joint name="front_left_wheel" type="fixed">
    <parent link="front_rocker_link"/>
    <child link="front_left_wheel_link"/>
    <origin rpy="0 0 0" xyz="0 0.27549999999999997 0"/>
    <axis xyz="0 1 0"/>
  </joint>
  <transmission name="front_wheel_trans">
    <type>transmission_interface/SimpleTransmission</type>
    <joint name="front_left_wheel">
      <hardwareInterface>hardware_interface/VelocityJointInterface</hardwareInterface>
    </joint>
    <actuator name="front_left_actuator">
      <mechanicalReduction>1</mechanicalReduction>
    </actuator>
  </transmission>
  <link name="front_right_wheel_link">
    <visual>
      <origin rpy="1.5707963267948966 0 0" xyz="0 0 0"/>
      <geometry>
        <mesh filename="package://ridgeback_description/meshes/wheel.stl"/>
      </geometry>
      <material name="black"/>
    </visual>
    <!-- <collision>
        <origin xyz="0 0 0" rpy="${PI/2} 0 0"/>
        <geometry>
          <cylinder radius="${wheel_radius}" length="${wheel_width}"/>
        </geometry>
      </collision> -->
    <inertial>
      <origin rpy="0 0 0" xyz="0 0 0"/>
      <mass value="2.3"/>
      <inertia ixx="3.3212e-3" ixy="0" ixz="0" iyy="6.6424e-3" iyz="0" izz="3.3212e-3"/>
    </inertial>
  </link>
  <joint name="front_right_wheel" type="fixed">
    <parent link="front_rocker_link"/>
    <child link="front_right_wheel_link"/>
    <origin rpy="0 0 0" xyz="0 -0.27549999999999997 0"/>
    <axis xyz="0 1 0"/>
  </joint>
  <transmission name="front_wheel_trans">
    <type>transmission_interface/SimpleTransmission</type>
    <joint name="front_right_wheel">
      <hardwareInterface>hardware_interface/VelocityJointInterface</hardwareInterface>
    </joint>
    <actuator name="front_right_actuator">
      <mechanicalReduction>1</mechanicalReduction>
    </actuator>
  </transmission>
  <link name="rear_rocker_link">
    <visual>
      <origin rpy="1.5707963267948966 0 1.5707963267948966" xyz="0 0 0"/>
      <geometry>
        <mesh filename="package://ridgeback_description/meshes/rocker.stl"/>
      </geometry>
      <material name="black"/>
    </visual>
    <inertial>
      <origin rpy="1.5707963267948966 0 1.5707963267948966" xyz="0 0 0"/>
      <mass value="10.267"/>
      <inertia ixx="0.0288" ixy="2.20484e-6" ixz="-1.3145e-5" iyy="0.4324" iyz="1.8944e-3" izz="0.4130"/>
    </inertial>
  </link>
  <joint name="rear_rocker" type="fixed">
    <parent link="axle_link"/>
    <child link="rear_rocker_link"/>
    <origin rpy="0 0 0" xyz="-0.319 0 0"/>
    <axis xyz="1 0 0"/>
    <limit effort="0" velocity="0"/>
  </joint>
  <link name="rear_left_wheel_link">
    <visual>
      <origin rpy="1.5707963267948966 0 0" xyz="0 0 0"/>
      <geometry>
        <mesh filename="package://ridgeback_description/meshes/wheel.stl"/>
      </geometry>
      <material name="black"/>
    </visual>
    <!-- <collision>
        <origin xyz="0 0 0" rpy="${PI/2} 0 0"/>
        <geometry>
          <cylinder radius="${wheel_radius}" length="${wheel_width}"/>
        </geometry>
      </collision> -->
    <inertial>
      <origin rpy="0 0 0" xyz="0 0 0"/>
      <mass value="2.3"/>
      <inertia ixx="3.3212e-3" ixy="0" ixz="0" iyy="6.6424e-3" iyz="0" izz="3.3212e-3"/>
    </inertial>
  </link>
  <joint name="rear_left_wheel" type="fixed">
    <parent link="rear_rocker_link"/>
    <child link="rear_left_wheel_link"/>
    <origin rpy="0 0 0" xyz="0 0.27549999999999997 0"/>
    <axis xyz="0 1 0"/>
  </joint>
  <transmission name="rear_wheel_trans">
    <type>transmission_interface/SimpleTransmission</type>
    <joint name="rear_left_wheel">
      <hardwareInterface>hardware_interface/VelocityJointInterface</hardwareInterface>
    </joint>
    <actuator name="rear_left_actuator">
      <mechanicalReduction>1</mechanicalReduction>
    </actuator>
  </transmission>
  <link name="rear_right_wheel_link">
    <visual>
      <origin rpy="1.5707963267948966 0 0" xyz="0 0 0"/>
      <geometry>
        <mesh filename="package://ridgeback_description/meshes/wheel.stl"/>
      </geometry>
      <material name="black"/>
    </visual>
    <!-- <collision>
        <origin xyz="0 0 0" rpy="${PI/2} 0 0"/>
        <geometry>
          <cylinder radius="${wheel_radius}" length="${wheel_width}"/>
        </geometry>
      </collision> -->
    <inertial>
      <origin rpy="0 0 0" xyz="0 0 0"/>
      <mass value="2.3"/>
      <inertia ixx="3.3212e-3" ixy="0" ixz="0" iyy="6.6424e-3" iyz="0" izz="3.3212e-3"/>
    </inertial>
  </link>
  <joint name="rear_right_wheel" type="fixed">
    <parent link="rear_rocker_link"/>
    <child link="rear_right_wheel_link"/>
    <origin rpy="0 0 0" xyz="0 -0.27549999999999997 0"/>
    <axis xyz="0 1 0"/>
  </joint>
  <transmission name="rear_wheel_trans">
    <type>transmission_interface/SimpleTransmission</type>
    <joint name="rear_right_wheel">
      <hardwareInterface>hardware_interface/VelocityJointInterface</hardwareInterface>
    </joint>
    <actuator name="rear_right_actuator">
      <mechanicalReduction>1</mechanicalReduction>
    </actuator>
  </transmission>
  <link name="base_link">
    <collision>
      <origin xyz="0 0 0.15"/>
      <geometry>
        <!-- <mesh filename="package://ridgeback_description/meshes/body-collision.stl"/>  0.15相对于base_link所在的frame的-->
        <box size="0.95 0.8 0.5"/>
      </geometry>
    </collision>
  </link>
  <joint name="base_link_joint" type="fixed">
    <origin rpy="0 0 0" xyz="0 0 0"/>
    <parent link="base_link"/>
    <child link="chassis_link"/>
  </joint>
  <!-- customed self collision 碰撞检测 -->
  <joint name="front_left_sphere_joint" type="fixed">
    <origin rpy="0 0 0" xyz="0.2 0.15 0.15"/>
    <parent link="base_link"/>
    <child link="front_left_sphere_collision"/>
  </joint>
  <link name="front_left_sphere_collision">
    <visual>
      <origin rpy="0 0 0" xyz="0 0 0"/>
      <geometry>
        <sphere radius="0.4"/>
      </geometry>
    </visual>
  </link>
  <joint name="front_right_sphere_joint" type="fixed">
    <origin rpy="0 0 0" xyz="0.2 -0.15 0.15"/>
    <parent link="base_link"/>
    <child link="front_right_sphere_collision"/>
  </joint>
  <link name="front_right_sphere_collision">
    <visual>
      <origin rpy="0 0 0" xyz="0 0 0"/>
      <geometry>
        <sphere radius="0.4"/>
      </geometry>
    </visual>
  </link>
  <joint name="rear_left_sphere_joint" type="fixed">
    <origin rpy="0 0 0" xyz="-0.2 0.15 0.15"/>
    <parent link="base_link"/>
    <child link="rear_left_sphere_collision"/>
  </joint>
  <link name="rear_left_sphere_collision">
    <visual>
      <origin rpy="0 0 0" xyz="0 0 0"/>
      <geometry>
        <sphere radius="0.4"/>
      </geometry>
    </visual>
  </link>
  <joint name="rear_right_sphere_joint" type="fixed">
    <origin rpy="0 0 0" xyz="-0.2 -0.15 0.15"/>
    <parent link="base_link"/>
    <child link="rear_right_sphere_collision"/>
  </joint>
  <link name="rear_right_sphere_collision">
    <visual>
      <origin rpy="0 0 0" xyz="0 0 0"/>
      <geometry>
        <sphere radius="0.4"/>
      </geometry>
    </visual>
  </link>
  <!-- <joint name="rear_sphere_joint" type="fixed">
    <origin xyz="-0.15 0 0.15" rpy="0 0 0" />
    <parent link="base_link"/>
    <child link="rear_sphere_collision" />
  </joint>

  <link name="rear_sphere_collision">
    <visual>
      <origin xyz="0 0 0" rpy="0 0 0" />
      <geometry>
        <sphere radius="0.5" />
      </geometry>
    </visual>
  </link> -->
  <link name="chassis_link">
    <visual>
      <origin rpy="0 0 0" xyz="0 0 0"/>
      <geometry>
        <mesh filename="package://ridgeback_description/meshes/body.stl"/>
      </geometry>
      <material name="black"/>
    </visual>
    <inertial>
      <origin rpy="1.5707963267948966 0 1.5707963267948966" xyz="0.012 0.002 0.067"/>
      <mass value="165.304"/>
      <inertia ixx="4.4744" ixy="0.03098" ixz="0.003647" iyy="7.1624" iyz="0.1228" izz="4.6155"/>
    </inertial>
  </link>
  <joint name="right_side_cover_link_joint" type="fixed">
    <origin rpy="0 0 0" xyz="0 0 0"/>
    <parent link="chassis_link"/>
    <child link="right_side_cover_link"/>
  </joint>
  <joint name="left_side_cover_link_joint" type="fixed">
    <origin rpy="0 0 0" xyz="0 0 0"/>
    <parent link="chassis_link"/>
    <child link="left_side_cover_link"/>
  </joint>
  <link name="left_side_cover_link">
    <visual>
      <origin rpy="0 0 3.141592653589793" xyz="0 0 0"/>
      <geometry>
        <mesh filename="package://ridgeback_description/meshes/side-cover.stl"/>
      </geometry>
      <material name="yellow"/>
    </visual>
  </link>
  <link name="right_side_cover_link">
    <visual>
      <origin rpy="0 0 0" xyz="0 0 0"/>
      <geometry>
        <mesh filename="package://ridgeback_description/meshes/side-cover.stl"/>
      </geometry>
      <material name="yellow"/>
    </visual>
  </link>
  <joint name="front_cover_link_joint" type="fixed">
    <origin rpy="0 0 0" xyz="0 0 0"/>
    <parent link="chassis_link"/>
    <child link="front_cover_link"/>
  </joint>
  <link name="front_cover_link">
    <visual>
      <origin rpy="0 0 0" xyz="0 0 0"/>
      <geometry>
        <mesh filename="package://ridgeback_description/meshes/end-cover.stl"/>
      </geometry>
      <material name="black"/>
    </visual>
  </link>
  <joint name="rear_cover_link_joint" type="fixed">
    <origin rpy="0 0 0" xyz="0 0 0"/>
    <parent link="chassis_link"/>
    <child link="rear_cover_link"/>
  </joint>
  <link name="rear_cover_link">
    <visual>
      <origin rpy="0 0 3.141592653589793" xyz="0 0 0"/>
      <geometry>
        <mesh filename="package://ridgeback_description/meshes/end-cover.stl"/>
      </geometry>
      <material name="black"/>
    </visual>
  </link>
  <joint name="front_lights_link_joint" type="fixed">
    <origin rpy="0 0 0" xyz="0 0 0"/>
    <parent link="chassis_link"/>
    <child link="front_lights_link"/>
  </joint>
  <joint name="rear_lights_link_joint" type="fixed">
    <origin rpy="0 0 0" xyz="0 0 0"/>
    <parent link="chassis_link"/>
    <child link="rear_lights_link"/>
  </joint>
  <link name="front_lights_link">
    <visual>
      <origin rpy="0 0 0" xyz="0 0 0"/>
      <geometry>
        <mesh filename="package://ridgeback_description/meshes/lights.stl"/>
      </geometry>
      <material name="white"/>
    </visual>
  </link>
  <link name="rear_lights_link">
    <visual>
      <origin rpy="0 0 3.141592653589793" xyz="0 0 0"/>
      <geometry>
        <mesh filename="package://ridgeback_description/meshes/lights.stl"/>
      </geometry>
      <material name="red"/>
    </visual>
  </link>
  <joint name="top_link_joint" type="fixed">
    <origin rpy="0 0 0" xyz="0 0 0"/>
    <parent link="chassis_link"/>
    <child link="top_link"/>
  </joint>
  <link name="top_link">
    <visual>
      <origin rpy="0 0 0" xyz="0 0 0"/>
      <geometry>
        <mesh filename="package://ridgeback_description/meshes/top.stl"/>
      </geometry>
      <material name="black"/>
    </visual>
    <!-- <collision>
      <origin xyz="0 0 0" rpy="0 0 0" />
      <geometry>
        <mesh filename="package://ridgeback_description/meshes/top.stl"/>
      </geometry>
    </collision> -->
  </link>
  <joint name="axle_joint" type="fixed">
    <origin rpy="0 0 0" xyz="0 0 0.05"/>
    <parent link="chassis_link"/>
    <child link="axle_link"/>
  </joint>
  <link name="axle_link">
    <visual>
      <origin rpy="0 1.5707963267948966 0" xyz="0 0 0"/>
      <geometry>
        <mesh filename="package://ridgeback_description/meshes/axle.stl"/>
      </geometry>
      <material name="black"/>
    </visual>
  </link>
  <link name="imu_link">
    <inertial>
      <mass value="0.001"/>
      <origin rpy="0 0 0" xyz="0 0 0"/>
      <inertia ixx="1e-09" ixy="0.0" ixz="0.0" iyy="1e-09" iyz="0.0" izz="1e-09"/>
    </inertial>
  </link>
  <joint name="imu_joint" type="fixed">
    <parent link="chassis_link"/>
    <child link="imu_link"/>
    <origin rpy="0 0 0" xyz="0.2085 -0.2902 0.1681"/>
  </joint>
  <link name="mid_mount"/>
  <joint name="mid_mount_joint" type="fixed">
    <parent link="base_link"/>
    <child link="mid_mount"/>
    <origin rpy="0 0 0" xyz="0 0 0.28"/>
  </joint>
  <gazebo>
    <plugin filename="libgazebo_ros_control.so" name="gazebo_ros_control">
      <robotNamespace>/</robotNamespace>
    </plugin>
    <plugin filename="libridgeback_ros_force_based_move.so" name="ridgeback_ros_force_based_move">
      <robotNamespace>/</robotNamespace>
      <commandTopic>cmd_vel</commandTopic>
      <odometryTopic>odom</odometryTopic>
      <odometryFrame>odom</odometryFrame>
      <odometryRate>25.0</odometryRate>
      <robotBaseFrame>base_link</robotBaseFrame>
      <cmdVelTimeOut>0.25</cmdVelTimeOut>
      <!-- Don't publish a transform: the controller does it. -->
      <publishOdometryTf>0</publishOdometryTf>
      <yaw_velocity_p_gain>500.0</yaw_velocity_p_gain>
      <x_velocity_p_gain>10000.0</x_velocity_p_gain>
      <y_velocity_p_gain>10000.0</y_velocity_p_gain>
    </plugin>
    <plugin filename="libhector_gazebo_ros_imu.so" name="imu_controller">
      <robotNamespace>/</robotNamespace>
      <updateRate>50.0</updateRate>
      <bodyName>imu_link</bodyName>
      <topicName>imu/data</topicName>
      <frameId>base_link</frameId>
      <accelDrift>0.005 0.005 0.005</accelDrift>
      <accelGaussianNoise>0.005 0.005 0.005</accelGaussianNoise>
      <rateDrift>0.00005 0.00005 0.00005</rateDrift>
      <rateGaussianNoise>0.00005 0.00005 0.00005</rateGaussianNoise>
      <headingDrift>0.005</headingDrift>
      <headingGaussianNoise>0.005</headingGaussianNoise>
    </plugin>
    <plugin filename="libgazebo_ros_joint_state_publisher.so" name="gazebo_ros_joint_state_publisher">
      <jointName>front_rocker</jointName>
      <robotNamespace>/</robotNamespace>
      <updateRate>50.0</updateRate>
    </plugin>
  </gazebo>
  <!-- All static links get collapsed down to base_link in Gazebo, so that's
       the one to apply the colour to (in Gazebo 5+). -->
  <gazebo reference="base_link">
    <material>Gazebo/DarkGrey</material>
    <gravity>true</gravity>
  </gazebo>
  <!-- Individual link colouring still needed in Gazebo 2.x -->
  <gazebo reference="chassis_link">
    <material>Gazebo/DarkGrey</material>
  </gazebo>
  <gazebo reference="top_link">
    <material>Gazebo/DarkGrey</material>
  </gazebo>
  <gazebo reference="left_side_cover_link">
    <material>Gazebo/Yellow</material>
  </gazebo>
  <gazebo reference="right_side_cover_link">
    <material>Gazebo/Yellow</material>
  </gazebo>
  <gazebo reference="front_cover_link">
    <material>Gazebo/DarkGrey</material>
  </gazebo>
  <gazebo reference="rear_cover_link">
    <material>Gazebo/DarkGrey</material>
  </gazebo>
  <gazebo reference="front_lights_link">
    <material>Gazebo/White</material>
  </gazebo>
  <gazebo reference="rear_lights_link">
    <material>Gazebo/Red</material>
  </gazebo>
  <gazebo reference="front_rocker_link">
    <material>Gazebo/DarkGrey</material>
  </gazebo>
  <gazebo reference="rear_rocker_link">
    <material>Gazebo/DarkGrey</material>
  </gazebo>
  <gazebo reference="axle_link">
    <material>Gazebo/DarkGrey</material>
  </gazebo>
  <!-- Wheel friction to zero, as movement is handled by applying forces at
       the body level. -->
  <gazebo reference="front_left_wheel_link">
    <material>Gazebo/DarkGrey</material>
    <mu1>0.0</mu1>
    <mu2>0.0</mu2>
  </gazebo>
  <gazebo reference="front_right_wheel_link">
    <material>Gazebo/DarkGrey</material>
    <mu1>0.0</mu1>
    <mu2>0.0</mu2>
  </gazebo>
  <gazebo reference="rear_left_wheel_link">
    <material>Gazebo/DarkGrey</material>
    <mu1>0.0</mu1>
    <mu2>0.0</mu2>
  </gazebo>
  <gazebo reference="rear_right_wheel_link">
    <material>Gazebo/DarkGrey</material>
    <mu1>0.0</mu1>
    <mu2>0.0</mu2>
  </gazebo>
  <!-- This is an wheel-level solution to possibly revisit at a future date. -->
  <!--<gazebo>
    <plugin name="mecanum_gazebo" filename="libmecanum_force_plugin.so">
      <wheelJointName>front_left_wheel</wheelJointName>
      <forceScaleFactor>1</forceScaleFactor>
    </plugin>
    <plugin name="mecanum_gazebo" filename="libmecanum_force_plugin.so">
      <wheelJointName>front_right_wheel</wheelJointName>
      <forceScaleFactor>-1</forceScaleFactor>
    </plugin>
    <plugin name="mecanum_gazebo" filename="libmecanum_force_plugin.so">
      <wheelJointName>rear_left_wheel</wheelJointName>
      <forceScaleFactor>-1</forceScaleFactor>
    </plugin>
    <plugin name="mecanum_gazebo" filename="libmecanum_force_plugin.so">
      <wheelJointName>rear_right_wheel</wheelJointName>
      <forceScaleFactor>1</forceScaleFactor>
    </plugin>
  </gazebo> -->
  <!--
    As you add to this URDF, please be aware that both the robot and
    simulation include it. You must retain compatibility with all of
    the following launch files:

    ridgeback_viz/launch/view_model.launch
    ridgeback_gazebo/launch/ridgeback_world.launch
    ridgeback_base/launch/base.launch
  -->
  <!-- This file is a placeholder which is included by default from
       ridgeback.urdf.xacro. If a robot is being customized and requires
       additional URDF, set the RIDGEBACK_URDF_EXTRAS environment variable
       to the full path of the file you would like included. -->
  <material name="grey">
    <color rgba="0.6 0.6 0.6 1"/>
  </material>
  <!-- 外部，修改成fixed -->
  <link name="base_footprint"/>
  <joint name="footprint_joint" type="fixed">
    <origin rpy="0 0 0" xyz="0 0 -0.01965"/>
    <parent link="base_link"/>
    <child link="base_footprint"/>
  </joint>
  <!-- include pan tilt -->
  <!-- <xacro:pan_tilt parent="base_footprint">
    <origin xyz="0.25 0 1.02221" rpy="0 0 0"/>
  </xacro:pan_tilt> -->
  <!-- kinect dk -->
  <!-- <xacro:kinect_dk parent="pan_tilt_surface">
    <origin xyz="0 0 0" rpy="0 0 0"/>
  </xacro:kinect_dk> -->
  <!-- body -->
  <link name="body_link">
    <visual>
      <origin rpy="0 0 0" xyz="0 0 0"/>
      <geometry>
        <mesh filename="package://ridgeback_dual_arm_description/mesh/ridgeback-2xur5e-all-simp-urdf.stl"/>
        <!-- <mesh filename="package://ridgeback_dual_arm_description/mesh/ridgeback-2xur5e-all-urdf.stl" /> -->
      </geometry>
      <material name="">
        <color rgba="0.2 0.2 0.2 1"/>
      </material>
    </visual>
    <collision>
      <origin rpy="0 0 0" xyz="0 0 0"/>
      <geometry>
        <mesh filename="package://ridgeback_dual_arm_description/mesh/ridgeback-2xur5e-all-urdf.stl" scale="1 0.5 1"/>
      </geometry>
    </collision>
  </link>
  <joint name="body_joint" type="fixed">
    <origin rpy="0 0 0" xyz="0 0 0"/>
    <parent link="base_footprint"/>
    <child link="body_link"/>
  </joint>
  <!-- left_body -->
  <link name="left_body_link"/>
  <joint name="left_body_joint" type="fixed">
    <origin rpy="2.356194490192345 0 0" xyz="0.2 0.22 1.233"/>
    <parent link="base_footprint"/>
    <child link="left_body_link"/>
  </joint>
  <!-- right_body -->
  <link name="right_body_link"/>
  <joint name="right_body_joint" type="fixed">
    <origin rpy="-2.356194490192345 0 0" xyz="0.2 -0.22 1.233"/>
    <parent link="base_footprint"/>
    <child link="right_body_link"/>
  </joint>
  <!-- left arm -->
  <!-- <xacro:ur5e_robot prefix="left_arm_" /> -->
  <!-- <joint name="left_arm_joint" type="fixed">
      <origin xyz="0.25 0.208336 0.957336" rpy="-${M_PI/4*3} 0 0"/>
      <parent link="base_footprint"/>
      <child link="left_arm_base_link"/>
  </joint> -->
  <!-- <joint name="left_arm_joint" type="fixed">
    <origin xyz="0 0 0" rpy="${M_PI/2} ${M_PI/2} 0" />
    <parent link="left_body_link" />
    <child link="left_arm_base_link" />
  </joint> -->
  <!-- left gipper flange -->
  <!-- <link name="left_gripper_flange">
    <visual>
      <origin xyz="0 0 0" rpy="0 0 0" />
      <geometry>
        <mesh filename="package://ridgeback_dual_arm_description/mesh/3-finger-gripper_fixed-urdf.stl" />
      </geometry>
      <material name="">
        <color rgba="0.2 0.2 0.2 1" />
      </material>
    </visual>
  </link>
  <joint name="left_gripper_flange_joint" type="fixed">
    <origin xyz="0 0 0" rpy="0 0 0" />
    <parent link="left_arm_tool0" />
    <child link="left_gripper_flange" />
  </joint> -->
  <!-- left gripper -->
  <!-- <xacro:robotiq-3f-gripper_articulated prefix="left_gripper_" />
  <joint name="left_gripper_joint" type="fixed">
    <origin xyz="0 0 0.068825" rpy="${M_PI/2} 0 -${M_PI/4}" />
    <parent link="left_gripper_flange" />
    <child link="left_gripper_palm" />
  </joint> -->
  <!--
    Base UR robot series xacro macro.

    NOTE: this is NOT a URDF. It cannot directly be loaded by consumers
    expecting a flattened '.urdf' file. See the top-level '.xacro' for that
    (but note: that .xacro must still be processed by the xacro command).

    For use in '.launch' files: use one of the 'load_urX.launch' convenience
    launch files.

    This file models the base kinematic chain of a UR robot, which then gets
    parameterised by various configuration files to convert it into a UR3(e),
    UR5(e), UR10(e) or UR16e.

    NOTE: the default kinematic parameters (ie: link lengths, frame locations,
    offets, etc) do not correspond to any particular robot. They are defaults
    only. There WILL be non-zero offsets between the Forward Kinematics results
    in TF (ie: robot_state_publisher) and the values reported by the Teach
    Pendant.

    For accurate (and robot-specific) transforms, the 'kinematics_parameters_file'
    parameter MUST point to a .yaml file containing the appropriate values for
    the targetted robot.

    If using the UniversalRobots/Universal_Robots_ROS_Driver, follow the steps
    described in the readme of that repository to extract the kinematic
    calibration from the controller and generate the required .yaml file.

    Main author of the migration to yaml configs: Ludovic Delval.

    Contributors to previous versions (in no particular order):

     - Felix Messmer
     - Kelsey Hawkins
     - Wim Meeussen
     - Shaun Edwards
     - Nadia Hammoudeh Garcia
     - Dave Hershberger
     - G. vd. Hoorn
     - Philip Long
     - Dave Coleman
     - Miguel Prada
     - Mathias Luedtke
     - Marcel Schnirring
     - Felix von Drigalski
     - Felix Exner
     - Jimmy Da Silva
     - Ajit Krisshna N L
     - Muhammad Asif Rana
  -->
  <!--
    NOTE: the macro defined in this file is NOT part of the public API of this
          package. Users CANNOT rely on this file being available, or stored in
          this location. Nor can they rely on the existence of the macro.
  -->
  <transmission name="right_arm_shoulder_pan_trans">
    <type>transmission_interface/SimpleTransmission</type>
    <joint name="right_arm_shoulder_pan_joint">
      <hardwareInterface>hardware_interface/PositionJointInterface</hardwareInterface>
    </joint>
    <actuator name="right_arm_shoulder_pan_motor">
      <mechanicalReduction>1</mechanicalReduction>
    </actuator>
  </transmission>
  <transmission name="right_arm_shoulder_lift_trans">
    <type>transmission_interface/SimpleTransmission</type>
    <joint name="right_arm_shoulder_lift_joint">
      <hardwareInterface>hardware_interface/PositionJointInterface</hardwareInterface>
    </joint>
    <actuator name="right_arm_shoulder_lift_motor">
      <mechanicalReduction>1</mechanicalReduction>
    </actuator>
  </transmission>
  <transmission name="right_arm_elbow_trans">
    <type>transmission_interface/SimpleTransmission</type>
    <joint name="right_arm_elbow_joint">
      <hardwareInterface>hardware_interface/PositionJointInterface</hardwareInterface>
    </joint>
    <actuator name="right_arm_elbow_motor">
      <mechanicalReduction>1</mechanicalReduction>
    </actuator>
  </transmission>
  <transmission name="right_arm_wrist_1_trans">
    <type>transmission_interface/SimpleTransmission</type>
    <joint name="right_arm_wrist_1_joint">
      <hardwareInterface>hardware_interface/PositionJointInterface</hardwareInterface>
    </joint>
    <actuator name="right_arm_wrist_1_motor">
      <mechanicalReduction>1</mechanicalReduction>
    </actuator>
  </transmission>
  <transmission name="right_arm_wrist_2_trans">
    <type>transmission_interface/SimpleTransmission</type>
    <joint name="right_arm_wrist_2_joint">
      <hardwareInterface>hardware_interface/PositionJointInterface</hardwareInterface>
    </joint>
    <actuator name="right_arm_wrist_2_motor">
      <mechanicalReduction>1</mechanicalReduction>
    </actuator>
  </transmission>
  <transmission name="right_arm_wrist_3_trans">
    <type>transmission_interface/SimpleTransmission</type>
    <joint name="right_arm_wrist_3_joint">
      <hardwareInterface>hardware_interface/PositionJointInterface</hardwareInterface>
    </joint>
    <actuator name="right_arm_wrist_3_motor">
      <mechanicalReduction>1</mechanicalReduction>
    </actuator>
  </transmission>
  <!-- links: main serial chain -->
  <link name="right_arm_base_link"/>
  <link name="right_arm_base_link_inertia">
    <visual>
      <origin rpy="0 0 3.141592653589793" xyz="0 0 0"/>
      <geometry>
        <mesh filename="package://ur_description/meshes/ur5e/visual/base.dae"/>
      </geometry>
      <material name="LightGrey">
        <color rgba="0.7 0.7 0.7 1.0"/>
      </material>
    </visual>
    <collision>
      <origin rpy="0 0 3.141592653589793" xyz="0 0 0"/>
      <geometry>
        <mesh filename="package://ur_description/meshes/ur5e/collision/base.stl"/>
      </geometry>
    </collision>
    <inertial>
      <mass value="4.0"/>
      <origin rpy="0 0 0" xyz="0 0 0"/>
      <inertia ixx="0.00443333156" ixy="0.0" ixz="0.0" iyy="0.00443333156" iyz="0.0" izz="0.0072"/>
    </inertial>
  </link>
  <link name="right_arm_shoulder_link">
    <visual>
      <origin rpy="0 0 3.141592653589793" xyz="0 0 0"/>
      <geometry>
        <mesh filename="package://ur_description/meshes/ur5e/visual/shoulder.dae"/>
      </geometry>
      <material name="LightGrey">
        <color rgba="0.7 0.7 0.7 1.0"/>
      </material>
    </visual>
    <collision>
      <origin rpy="0 0 3.141592653589793" xyz="0 0 0"/>
      <geometry>
        <mesh filename="package://ur_description/meshes/ur5e/collision/shoulder.stl"/>
      </geometry>
    </collision>
    <inertial>
      <mass value="3.7"/>
      <origin rpy="0 0 0" xyz="0 0 0"/>
      <inertia ixx="0.010267495893" ixy="0.0" ixz="0.0" iyy="0.010267495893" iyz="0.0" izz="0.00666"/>
    </inertial>
  </link>
  <link name="right_arm_upper_arm_link">
    <visual>
      <origin rpy="1.5707963267948966 0 -1.5707963267948966" xyz="0 0 0.138"/>
      <geometry>
        <mesh filename="package://ur_description/meshes/ur5e/visual/upperarm.dae"/>
      </geometry>
      <material name="LightGrey">
        <color rgba="0.7 0.7 0.7 1.0"/>
      </material>
    </visual>
    <collision>
      <origin rpy="1.5707963267948966 0 -1.5707963267948966" xyz="0 0 0.138"/>
      <geometry>
        <mesh filename="package://ur_description/meshes/ur5e/collision/upperarm.stl"/>
      </geometry>
    </collision>
    <inertial>
      <mass value="8.393"/>
      <origin rpy="0 1.5707963267948966 0" xyz="-0.2125 0.0 0.138"/>
      <inertia ixx="0.1338857818623325" ixy="0.0" ixz="0.0" iyy="0.1338857818623325" iyz="0.0" izz="0.0151074"/>
    </inertial>
  </link>
  <link name="right_arm_forearm_link">
    <visual>
      <origin rpy="1.5707963267948966 0 -1.5707963267948966" xyz="0 0 0.007"/>
      <geometry>
        <mesh filename="package://ur_description/meshes/ur5e/visual/forearm.dae"/>
      </geometry>
      <material name="LightGrey">
        <color rgba="0.7 0.7 0.7 1.0"/>
      </material>
    </visual>
    <collision>
      <origin rpy="1.5707963267948966 0 -1.5707963267948966" xyz="0 0 0.007"/>
      <geometry>
        <mesh filename="package://ur_description/meshes/ur5e/collision/forearm.stl"/>
      </geometry>
    </collision>
    <inertial>
      <mass value="2.275"/>
      <origin rpy="0 1.5707963267948966 0" xyz="-0.1961 0.0 0.007"/>
      <inertia ixx="0.031209355099586295" ixy="0.0" ixz="0.0" iyy="0.031209355099586295" iyz="0.0" izz="0.004095"/>
    </inertial>
  </link>
  <link name="right_arm_wrist_1_link">
    <visual>
      <!-- TODO: Move this to a parameter -->
      <origin rpy="1.5707963267948966 0 0" xyz="0 0 -0.127"/>
      <geometry>
        <mesh filename="package://ur_description/meshes/ur5e/visual/wrist1.dae"/>
      </geometry>
      <material name="LightGrey">
        <color rgba="0.7 0.7 0.7 1.0"/>
      </material>
    </visual>
    <collision>
      <origin rpy="1.5707963267948966 0 0" xyz="0 0 -0.127"/>
      <geometry>
        <mesh filename="package://ur_description/meshes/ur5e/collision/wrist1.stl"/>
      </geometry>
    </collision>
    <inertial>
      <mass value="1.219"/>
      <origin rpy="0 0 0" xyz="0 0 0"/>
      <inertia ixx="0.0025598989760400002" ixy="0.0" ixz="0.0" iyy="0.0025598989760400002" iyz="0.0" izz="0.0021942"/>
    </inertial>
  </link>
  <link name="right_arm_wrist_2_link">
    <visual>
      <origin rpy="0 0 0" xyz="0 0 -0.0997"/>
      <geometry>
        <mesh filename="package://ur_description/meshes/ur5e/visual/wrist2.dae"/>
      </geometry>
      <material name="LightGrey">
        <color rgba="0.7 0.7 0.7 1.0"/>
      </material>
    </visual>
    <collision>
      <origin rpy="0 0 0" xyz="0 0 -0.0997"/>
      <geometry>
        <mesh filename="package://ur_description/meshes/ur5e/collision/wrist2.stl"/>
      </geometry>
    </collision>
    <inertial>
      <mass value="1.219"/>
      <origin rpy="0 0 0" xyz="0 0 0"/>
      <inertia ixx="0.0025598989760400002" ixy="0.0" ixz="0.0" iyy="0.0025598989760400002" iyz="0.0" izz="0.0021942"/>
    </inertial>
  </link>
  <link name="right_arm_wrist_3_link">
    <visual>
      <origin rpy="1.5707963267948966 0 0" xyz="0 0 -0.0989"/>
      <geometry>
        <mesh filename="package://ur_description/meshes/ur5e/visual/wrist3.dae"/>
      </geometry>
      <material name="LightGrey">
        <color rgba="0.7 0.7 0.7 1.0"/>
      </material>
    </visual>
    <collision>
      <origin rpy="1.5707963267948966 0 0" xyz="0 0 -0.0989"/>
      <geometry>
        <mesh filename="package://ur_description/meshes/ur5e/collision/wrist3.stl"/>
      </geometry>
    </collision>
    <inertial>
      <mass value="0.1879"/>
      <origin rpy="0 0 0" xyz="0.0 0.0 -0.0229"/>
      <inertia ixx="9.890410052167731e-05" ixy="0.0" ixz="0.0" iyy="9.890410052167731e-05" iyz="0.0" izz="0.0001321171875"/>
    </inertial>
  </link>
  <!-- joints: main serial chain -->
  <joint name="right_arm_base_link-base_link_inertia" type="fixed">
    <parent link="right_arm_base_link"/>
    <child link="right_arm_base_link_inertia"/>
    <!-- 'base_link' is REP-103 aligned (so X+ forward), while the internal
           frames of the robot/controller have X+ pointing backwards.
           Use the joint between 'base_link' and 'base_link_inertia' (a dummy
           link/frame) to introduce the necessary rotation over Z (of pi rad).
      -->
    <origin rpy="0 0 3.141592653589793" xyz="0 0 0"/>
  </joint>
  <joint name="right_arm_shoulder_pan_joint" type="revolute">
    <parent link="right_arm_base_link_inertia"/>
    <child link="right_arm_shoulder_link"/>
    <origin rpy="0 0 0" xyz="0 0 0.1625"/>
    <axis xyz="0 0 1"/>
    <limit effort="150.0" lower="-3.141592653589793" upper="3.141592653589793" velocity="3.141592653589793"/>
    <dynamics damping="0" friction="0"/>
  </joint>
  <joint name="right_arm_shoulder_lift_joint" type="revolute">
    <parent link="right_arm_shoulder_link"/>
    <child link="right_arm_upper_arm_link"/>
    <origin rpy="1.570796327 0 0" xyz="0 0 0"/>
    <axis xyz="0 0 1"/>
    <limit effort="150.0" lower="-3.141592653589793" upper="3.141592653589793" velocity="3.141592653589793"/>
    <dynamics damping="0" friction="0"/>
  </joint>
  <!-- shoulder碰撞膨胀  -->
  <joint name="right_arm_shoulder_sphere_joint" type="fixed">
    <parent link="right_arm_upper_arm_link"/>
    <child link="right_arm_shoulder_sphere_link"/>
    <origin rpy="0 0 0" xyz="0 0 0.08"/>
  </joint>
  <link name="right_arm_shoulder_sphere_link">
    <visual>
      <geometry>
        <sphere radius="0.15"/>
      </geometry>
      <material name="yellow">
        <color rgba="1 1 0 0.5"/>
      </material>
    </visual>
  </link>
  <joint name="right_arm_elbow_joint" type="revolute">
    <parent link="right_arm_upper_arm_link"/>
    <child link="right_arm_forearm_link"/>
    <origin rpy="0 0 0" xyz="-0.425 0 0"/>
    <axis xyz="0 0 1"/>
    <limit effort="150.0" lower="-3.141592653589793" upper="3.141592653589793" velocity="3.141592653589793"/>
    <dynamics damping="0" friction="0"/>
  </joint>
  <!-- elbow forearm碰撞膨胀 -->
  <joint name="right_arm_forearm_sphere_joint" type="fixed">
    <parent link="right_arm_forearm_link"/>
    <child link="right_arm_forearm_sphere_link"/>
    <origin rpy="0 0 0" xyz="0 0.02 0.09"/>
  </joint>
  <link name="right_arm_forearm_sphere_link">
    <visual>
      <origin rpy="0 0 0" xyz="0 0 0"/>
      <geometry>
        <sphere radius="0.15"/>
      </geometry>
      <material name="yellow">
        <color rgba="1 1 0 0.5"/>
      </material>
    </visual>
  </link>
  <joint name="right_arm_wrist_1_joint" type="revolute">
    <parent link="right_arm_forearm_link"/>
    <child link="right_arm_wrist_1_link"/>
    <origin rpy="0 0 0" xyz="-0.3922 0 0.1333"/>
    <axis xyz="0 0 1"/>
    <limit effort="28.0" lower="-3.141592653589793" upper="3.141592653589793" velocity="3.141592653589793"/>
    <dynamics damping="0" friction="0"/>
  </joint>
  <!-- wrist link碰撞膨胀 -->
  <joint name="right_arm_wrist_sphere_joint" type="fixed">
    <parent link="right_arm_wrist_1_link"/>
    <child link="right_arm_wrist_sphere_link"/>
    <origin rpy="0 0 0" xyz="0 -0.04 -0.01"/>
  </joint>
  <link name="right_arm_wrist_sphere_link">
    <visual>
      <geometry>
        <sphere radius="0.15"/>
      </geometry>
      <material name="yellow">
        <color rgba="1 1 0 0.5"/>
      </material>
    </visual>
  </link>
  <joint name="right_arm_wrist_2_joint" type="revolute">
    <parent link="right_arm_wrist_1_link"/>
    <child link="right_arm_wrist_2_link"/>
    <origin rpy="1.570796327 0 0" xyz="0 -0.0997 -2.044881182297852e-11"/>
    <axis xyz="0 0 1"/>
    <limit effort="28.0" lower="-3.141592653589793" upper="3.141592653589793" velocity="3.141592653589793"/>
    <dynamics damping="0" friction="0"/>
  </joint>
  <joint name="right_arm_wrist_3_joint" type="revolute">
    <parent link="right_arm_wrist_2_link"/>
    <child link="right_arm_wrist_3_link"/>
    <origin rpy="1.570796326589793 3.141592653589793 3.141592653589793" xyz="0 0.0996 -2.042830148012698e-11"/>
    <axis xyz="0 0 1"/>
    <limit effort="28.0" lower="-3.141592653589793" upper="3.141592653589793" velocity="3.141592653589793"/>
    <dynamics damping="0" friction="0"/>
  </joint>
  <!-- ROS-Industrial 'base' frame: base_link to UR 'Base' Coordinates transform -->
  <link name="right_arm_base"/>
  <joint name="right_arm_base_link-base_fixed_joint" type="fixed">
    <!-- Note the rotation over Z of pi radians: as base_link is REP-103
           aligned (ie: has X+ forward, Y+ left and Z+ up), this is needed
           to correctly align 'base' with the 'Base' coordinate system of
           the UR controller.
      -->
    <origin rpy="0 0 3.141592653589793" xyz="0 0 0"/>
    <parent link="right_arm_base_link"/>
    <child link="right_arm_base"/>
  </joint>
  <!-- ROS-Industrial 'flange' frame: attachment point for EEF models -->
  <link name="right_arm_flange"/>
  <joint name="right_arm_wrist_3-flange" type="fixed">
    <parent link="right_arm_wrist_3_link"/>
    <child link="right_arm_flange"/>
    <origin rpy="0 -1.5707963267948966 -1.5707963267948966" xyz="0 0 0"/>
  </joint>
  <!-- flange tool 碰撞膨胀-->
  <joint name="right_arm_flange_gripper_sphere_joint" type="fixed">
    <parent link="right_arm_flange"/>
    <child link="right_arm_flange_gripper_sphere"/>
    <origin rpy="0 0 0" xyz="0.12 0 0"/>
  </joint>
  <link name="right_arm_flange_gripper_sphere">
    <visual>
      <geometry>
        <sphere radius="0.13"/>
      </geometry>
      <material name="yellow">
        <color rgba="1 1 0 0.5"/>
      </material>
    </visual>
  </link>
  <!-- ROS-Industrial 'tool0' frame: all-zeros tool frame -->
  <link name="right_arm_tool0"/>
  <joint name="right_arm_flange-tool0" type="fixed">
    <!-- default toolframe: X+ left, Y+ up, Z+ front -->
    <origin rpy="1.5707963267948966 0 1.5707963267948966" xyz="0 0 0"/>
    <parent link="right_arm_flange"/>
    <child link="right_arm_tool0"/>
  </joint>
  <!-- <joint name="right_arm_joint" type="fixed">
      <origin xyz="0.25 -0.208336 0.957336" rpy="${M_PI/4*3} 0 0"/>
      <parent link="base_footprint"/>
      <child link="right_arm_base_link"/>
  </joint> -->
  <joint name="right_arm_joint" type="fixed">
    <origin rpy="-1.5707963267948966 -1.5707963267948966 0" xyz="0 0 0"/>
    <parent link="right_body_link"/>
    <child link="right_arm_base_link"/>
  </joint>
  <!-- right gipper flange -->
  <link name="right_gripper_flange">
    <visual>
      <origin rpy="0 0 0" xyz="0 0 0"/>
      <geometry>
        <mesh filename="package://ridgeback_dual_arm_description/mesh/3-finger-gripper_fixed-urdf.stl"/>
      </geometry>
      <material name="">
        <color rgba="0.2 0.2 0.2 1"/>
      </material>
    </visual>
    <collision>
      <origin rpy="0 0 0" xyz="0 0 0"/>
      <geometry>
        <mesh filename="package://ridgeback_dual_arm_description/mesh/3-finger-gripper_fixed-urdf.stl"/>
      </geometry>
    </collision>
  </link>
  <joint name="right_gripper_flange_joint" type="fixed">
    <origin rpy="0 0 0" xyz="0 0 0"/>
    <parent link="right_arm_tool0"/>
    <child link="right_gripper_flange"/>
  </joint>
  <!-- link list -->
  <link name="right_gripper_finger_1_link_0">
    <visual>
      <origin rpy="0 0 0" xyz="0.020 0 0"/>
      <geometry>
        <mesh filename="package://robotiq_3f_gripper_visualization/meshes/robotiq-3f-gripper_articulated/visual/link_0.dae"/>
      </geometry>
      <material name="gray">
        <color rgba="0.2 0.2 0.2 1"/>
      </material>
    </visual>
    <collision>
      <origin rpy="0 0 0" xyz="0.020 0 0"/>
      <geometry>
        <mesh filename="package://robotiq_3f_gripper_visualization/meshes/robotiq-3f-gripper_articulated/collision/link_0.STL"/>
      </geometry>
      <material name="yellow">
        <color rgba="0 1 1 1"/>
      </material>
    </collision>
    <inertial>
      <origin rpy="0 0 0" xyz="0 0 0"/>
      <mass value="0.05"/>
      <inertia ixx="0.01" ixy="-0.00002" ixz="0.00001" iyy="0.0008" iyz="0" izz="0.001"/>
    </inertial>
  </link>
  <link name="right_gripper_finger_1_link_1">
    <visual>
      <origin rpy="0 0 -0.52" xyz="0.050 -.028 0"/>
      <geometry>
        <mesh filename="package://robotiq_3f_gripper_visualization/meshes/robotiq-3f-gripper_articulated/visual/link_1.dae"/>
      </geometry>
      <material name="gray"/>
    </visual>
    <collision>
      <origin rpy="0 0 -0.52" xyz="0.050 -.028 0"/>
      <geometry>
        <mesh filename="package://robotiq_3f_gripper_visualization/meshes/robotiq-3f-gripper_articulated/collision/link_1.STL"/>
      </geometry>
      <material name="yellow"/>
    </collision>
    <inertial>
      <origin rpy="0 0 0" xyz="0 0 0"/>
      <mass value="0.15"/>
      <inertia ixx="0.001859" ixy="-0.000376" ixz="0.000028" iyy="0.012756" iyz="0" izz="0.0024"/>
    </inertial>
  </link>
  <link name="right_gripper_finger_1_link_2">
    <!--
			NOTE: This link has an offset in the z-direction based on the models that were
			used to generate grap-it poses.  With the offset below the model appears visually
			correct, but it is suspect.
			-->
    <visual>
      <origin rpy="0 0 0" xyz="0.039 0 0.0075"/>
      <geometry>
        <mesh filename="package://robotiq_3f_gripper_visualization/meshes/robotiq-3f-gripper_articulated/visual/link_2.dae"/>
      </geometry>
      <material name="gray"/>
    </visual>
    <collision>
      <origin rpy="0 0 0" xyz="0.039 0 0.0075"/>
      <geometry>
        <mesh filename="package://robotiq_3f_gripper_visualization/meshes/robotiq-3f-gripper_articulated/collision/link_2.STL"/>
      </geometry>
      <material name="yellow"/>
    </collision>
    <inertial>
      <origin rpy="0 0 0" xyz="0 0 0"/>
      <mass value="0.15"/>
      <inertia ixx="0.001859" ixy="-0.000376" ixz="0.000028" iyy="0.012756" iyz="0" izz="0.0024"/>
    </inertial>
  </link>
  <link name="right_gripper_finger_1_link_3">
    <visual>
      <origin rpy="0 0 0.52" xyz="0 0 0"/>
      <geometry>
        <mesh filename="package://robotiq_3f_gripper_visualization/meshes/robotiq-3f-gripper_articulated/visual/link_3.dae"/>
      </geometry>
      <material name="gray"/>
    </visual>
    <collision>
      <origin rpy="0 0 0.52" xyz="0 0 0"/>
      <geometry>
        <mesh filename="package://robotiq_3f_gripper_visualization/meshes/robotiq-3f-gripper_articulated/collision/link_3.STL"/>
      </geometry>
      <material name="yellow"/>
    </collision>
    <inertial>
      <origin rpy="0 0 0" xyz="0 0 0"/>
      <mass value="0.05"/>
      <inertia ixx="0.001239" ixy="-0.000251" ixz="0.000019" iyy="0.00085" iyz="0" izz="0.001632"/>
    </inertial>
  </link>
  <!-- end of link list -->
  <!-- joint list -->
  <joint name="right_gripper_finger_1_joint_1" type="fixed">
    <parent link="right_gripper_finger_1_link_0"/>
    <child link="right_gripper_finger_1_link_1"/>
    <axis xyz="0 0 1"/>
    <origin rpy="0 0 0" xyz="0.020 0 0"/>
    <limit effort="100" lower="0.0495" upper="1.2218" velocity="100"/>
  </joint>
  <joint name="right_gripper_finger_1_joint_2" type="fixed">
    <parent link="right_gripper_finger_1_link_1"/>
    <child link="right_gripper_finger_1_link_2"/>
    <axis xyz="0 0 1"/>
    <origin rpy="0 0 -0.52" xyz="0.050 -.028 0"/>
    <limit effort="100" lower="0.0" upper="1.5708" velocity="100"/>
  </joint>
  <joint name="right_gripper_finger_1_joint_3" type="fixed">
    <parent link="right_gripper_finger_1_link_2"/>
    <child link="right_gripper_finger_1_link_3"/>
    <axis xyz="0 0 1"/>
    <origin rpy="0 0 0" xyz="0.039 0 0"/>
    <limit effort="100" lower="-1.2217" upper="-0.0523" velocity="100"/>
  </joint>
  <!-- end of joint list -->
  <!-- link list -->
  <link name="right_gripper_finger_2_link_0">
    <visual>
      <origin rpy="0 0 0" xyz="0.020 0 0"/>
      <geometry>
        <mesh filename="package://robotiq_3f_gripper_visualization/meshes/robotiq-3f-gripper_articulated/visual/link_0.dae"/>
      </geometry>
      <material name="gray">
        <color rgba="0.2 0.2 0.2 1"/>
      </material>
    </visual>
    <collision>
      <origin rpy="0 0 0" xyz="0.020 0 0"/>
      <geometry>
        <mesh filename="package://robotiq_3f_gripper_visualization/meshes/robotiq-3f-gripper_articulated/collision/link_0.STL"/>
      </geometry>
      <material name="yellow">
        <color rgba="0 1 1 1"/>
      </material>
    </collision>
    <inertial>
      <origin rpy="0 0 0" xyz="0 0 0"/>
      <mass value="0.05"/>
      <inertia ixx="0.01" ixy="-0.00002" ixz="0.00001" iyy="0.0008" iyz="0" izz="0.001"/>
    </inertial>
  </link>
  <link name="right_gripper_finger_2_link_1">
    <visual>
      <origin rpy="0 0 -0.52" xyz="0.050 -.028 0"/>
      <geometry>
        <mesh filename="package://robotiq_3f_gripper_visualization/meshes/robotiq-3f-gripper_articulated/visual/link_1.dae"/>
      </geometry>
      <material name="gray"/>
    </visual>
    <collision>
      <origin rpy="0 0 -0.52" xyz="0.050 -.028 0"/>
      <geometry>
        <mesh filename="package://robotiq_3f_gripper_visualization/meshes/robotiq-3f-gripper_articulated/collision/link_1.STL"/>
      </geometry>
      <material name="yellow"/>
    </collision>
    <inertial>
      <origin rpy="0 0 0" xyz="0 0 0"/>
      <mass value="0.15"/>
      <inertia ixx="0.001859" ixy="-0.000376" ixz="0.000028" iyy="0.012756" iyz="0" izz="0.0024"/>
    </inertial>
  </link>
  <link name="right_gripper_finger_2_link_2">
    <!--
			NOTE: This link has an offset in the z-direction based on the models that were
			used to generate grap-it poses.  With the offset below the model appears visually
			correct, but it is suspect.
			-->
    <visual>
      <origin rpy="0 0 0" xyz="0.039 0 0.0075"/>
      <geometry>
        <mesh filename="package://robotiq_3f_gripper_visualization/meshes/robotiq-3f-gripper_articulated/visual/link_2.dae"/>
      </geometry>
      <material name="gray"/>
    </visual>
    <collision>
      <origin rpy="0 0 0" xyz="0.039 0 0.0075"/>
      <geometry>
        <mesh filename="package://robotiq_3f_gripper_visualization/meshes/robotiq-3f-gripper_articulated/collision/link_2.STL"/>
      </geometry>
      <material name="yellow"/>
    </collision>
    <inertial>
      <origin rpy="0 0 0" xyz="0 0 0"/>
      <mass value="0.15"/>
      <inertia ixx="0.001859" ixy="-0.000376" ixz="0.000028" iyy="0.012756" iyz="0" izz="0.0024"/>
    </inertial>
  </link>
  <link name="right_gripper_finger_2_link_3">
    <visual>
      <origin rpy="0 0 0.52" xyz="0 0 0"/>
      <geometry>
        <mesh filename="package://robotiq_3f_gripper_visualization/meshes/robotiq-3f-gripper_articulated/visual/link_3.dae"/>
      </geometry>
      <material name="gray"/>
    </visual>
    <collision>
      <origin rpy="0 0 0.52" xyz="0 0 0"/>
      <geometry>
        <mesh filename="package://robotiq_3f_gripper_visualization/meshes/robotiq-3f-gripper_articulated/collision/link_3.STL"/>
      </geometry>
      <material name="yellow"/>
    </collision>
    <inertial>
      <origin rpy="0 0 0" xyz="0 0 0"/>
      <mass value="0.05"/>
      <inertia ixx="0.001239" ixy="-0.000251" ixz="0.000019" iyy="0.00085" iyz="0" izz="0.001632"/>
    </inertial>
  </link>
  <!-- end of link list -->
  <!-- joint list -->
  <joint name="right_gripper_finger_2_joint_1" type="fixed">
    <parent link="right_gripper_finger_2_link_0"/>
    <child link="right_gripper_finger_2_link_1"/>
    <axis xyz="0 0 1"/>
    <origin rpy="0 0 0" xyz="0.020 0 0"/>
    <limit effort="100" lower="0.0495" upper="1.2218" velocity="100"/>
  </joint>
  <joint name="right_gripper_finger_2_joint_2" type="fixed">
    <parent link="right_gripper_finger_2_link_1"/>
    <child link="right_gripper_finger_2_link_2"/>
    <axis xyz="0 0 1"/>
    <origin rpy="0 0 -0.52" xyz="0.050 -.028 0"/>
    <limit effort="100" lower="0.0" upper="1.5708" velocity="100"/>
  </joint>
  <joint name="right_gripper_finger_2_joint_3" type="fixed">
    <parent link="right_gripper_finger_2_link_2"/>
    <child link="right_gripper_finger_2_link_3"/>
    <axis xyz="0 0 1"/>
    <origin rpy="0 0 0" xyz="0.039 0 0"/>
    <limit effort="100" lower="-1.2217" upper="-0.0523" velocity="100"/>
  </joint>
  <!-- end of joint list -->
  <!-- link list -->
  <link name="right_gripper_finger_middle_link_0">
    <visual>
      <origin rpy="0 0 0" xyz="0.020 0 0"/>
      <geometry>
        <mesh filename="package://robotiq_3f_gripper_visualization/meshes/robotiq-3f-gripper_articulated/visual/link_0.dae"/>
      </geometry>
      <material name="gray">
        <color rgba="0.2 0.2 0.2 1"/>
      </material>
    </visual>
    <collision>
      <origin rpy="0 0 0" xyz="0.020 0 0"/>
      <geometry>
        <mesh filename="package://robotiq_3f_gripper_visualization/meshes/robotiq-3f-gripper_articulated/collision/link_0.STL"/>
      </geometry>
      <material name="yellow">
        <color rgba="0 1 1 1"/>
      </material>
    </collision>
    <inertial>
      <origin rpy="0 0 0" xyz="0 0 0"/>
      <mass value="0.05"/>
      <inertia ixx="0.01" ixy="-0.00002" ixz="0.00001" iyy="0.0008" iyz="0" izz="0.001"/>
    </inertial>
  </link>
  <link name="right_gripper_finger_middle_link_1">
    <visual>
      <origin rpy="0 0 -0.52" xyz="0.050 -.028 0"/>
      <geometry>
        <mesh filename="package://robotiq_3f_gripper_visualization/meshes/robotiq-3f-gripper_articulated/visual/link_1.dae"/>
      </geometry>
      <material name="gray"/>
    </visual>
    <collision>
      <origin rpy="0 0 -0.52" xyz="0.050 -.028 0"/>
      <geometry>
        <mesh filename="package://robotiq_3f_gripper_visualization/meshes/robotiq-3f-gripper_articulated/collision/link_1.STL"/>
      </geometry>
      <material name="yellow"/>
    </collision>
    <inertial>
      <origin rpy="0 0 0" xyz="0 0 0"/>
      <mass value="0.15"/>
      <inertia ixx="0.001859" ixy="-0.000376" ixz="0.000028" iyy="0.012756" iyz="0" izz="0.0024"/>
    </inertial>
  </link>
  <link name="right_gripper_finger_middle_link_2">
    <!--
			NOTE: This link has an offset in the z-direction based on the models that were
			used to generate grap-it poses.  With the offset below the model appears visually
			correct, but it is suspect.
			-->
    <visual>
      <origin rpy="0 0 0" xyz="0.039 0 0.0075"/>
      <geometry>
        <mesh filename="package://robotiq_3f_gripper_visualization/meshes/robotiq-3f-gripper_articulated/visual/link_2.dae"/>
      </geometry>
      <material name="gray"/>
    </visual>
    <collision>
      <origin rpy="0 0 0" xyz="0.039 0 0.0075"/>
      <geometry>
        <mesh filename="package://robotiq_3f_gripper_visualization/meshes/robotiq-3f-gripper_articulated/collision/link_2.STL"/>
      </geometry>
      <material name="yellow"/>
    </collision>
    <inertial>
      <origin rpy="0 0 0" xyz="0 0 0"/>
      <mass value="0.15"/>
      <inertia ixx="0.001859" ixy="-0.000376" ixz="0.000028" iyy="0.012756" iyz="0" izz="0.0024"/>
    </inertial>
  </link>
  <link name="right_gripper_finger_middle_link_3">
    <visual>
      <origin rpy="0 0 0.52" xyz="0 0 0"/>
      <geometry>
        <mesh filename="package://robotiq_3f_gripper_visualization/meshes/robotiq-3f-gripper_articulated/visual/link_3.dae"/>
      </geometry>
      <material name="gray"/>
    </visual>
    <collision>
      <origin rpy="0 0 0.52" xyz="0 0 0"/>
      <geometry>
        <mesh filename="package://robotiq_3f_gripper_visualization/meshes/robotiq-3f-gripper_articulated/collision/link_3.STL"/>
      </geometry>
      <material name="yellow"/>
    </collision>
    <inertial>
      <origin rpy="0 0 0" xyz="0 0 0"/>
      <mass value="0.05"/>
      <inertia ixx="0.001239" ixy="-0.000251" ixz="0.000019" iyy="0.00085" iyz="0" izz="0.001632"/>
    </inertial>
  </link>
  <!-- end of link list -->
  <!-- joint list -->
  <joint name="right_gripper_finger_middle_joint_1" type="fixed">
    <parent link="right_gripper_finger_middle_link_0"/>
    <child link="right_gripper_finger_middle_link_1"/>
    <axis xyz="0 0 1"/>
    <origin rpy="0 0 0" xyz="0.020 0 0"/>
    <limit effort="100" lower="0.0495" upper="1.2218" velocity="100"/>
  </joint>
  <joint name="right_gripper_finger_middle_joint_2" type="fixed">
    <parent link="right_gripper_finger_middle_link_1"/>
    <child link="right_gripper_finger_middle_link_2"/>
    <axis xyz="0 0 1"/>
    <origin rpy="0 0 -0.52" xyz="0.050 -.028 0"/>
    <limit effort="100" lower="0.0" upper="1.5708" velocity="100"/>
  </joint>
  <joint name="right_gripper_finger_middle_joint_3" type="fixed">
    <parent link="right_gripper_finger_middle_link_2"/>
    <child link="right_gripper_finger_middle_link_3"/>
    <axis xyz="0 0 1"/>
    <origin rpy="0 0 0" xyz="0.039 0 0"/>
    <limit effort="100" lower="-1.2217" upper="-0.0523" velocity="100"/>
  </joint>
  <!-- end of joint list -->
  <!-- link list -->
  <link name="right_gripper_palm">
    <visual>
      <geometry>
        <mesh filename="package://robotiq_3f_gripper_visualization/meshes/robotiq-3f-gripper_articulated/visual/palm.dae"/>
      </geometry>
      <material name="gray">
        <color rgba="0.2 0.2 0.2 1"/>
      </material>
    </visual>
    <collision>
      <geometry>
        <mesh filename="package://robotiq_3f_gripper_visualization/meshes/robotiq-3f-gripper_articulated/collision/palm.STL"/>
      </geometry>
      <material name="yellow">
        <color rgba="0 1 1 1"/>
      </material>
    </collision>
  </link>
  <link name="right_gripper_tool0"/>
  <inertial>
    <origin rpy="0 0 0" xyz="0 0 0"/>
    <mass value="1.3"/>
    <inertia ixx="0.006012" ixy="0.000079" ixz="-0.00024" iyy="0.012892" iyz="0" izz="0.002435"/>
  </inertial>
  <!-- end of link list -->
  <!-- joint list -->
  <joint name="right_gripper_palm_finger_1_joint" type="fixed">
    <parent link="right_gripper_palm"/>
    <child link="right_gripper_finger_1_link_0"/>
    <axis xyz="0 1 0"/>
    <origin rpy="0 3.1416 -1.57" xyz="-0.0455 0.0214 0.036"/>
    <limit effort="100" lower="-0.1784" upper="0.192" velocity="100"/>
  </joint>
  <joint name="right_gripper_palm_finger_2_joint" type="fixed">
    <parent link="right_gripper_palm"/>
    <child link="right_gripper_finger_2_link_0"/>
    <axis xyz="0 1 0"/>
    <origin rpy="0 3.1416 -1.57" xyz="-0.0455 0.0214 -0.036"/>
    <limit effort="100" lower="-0.192" upper="0.1784" velocity="100"/>
  </joint>
  <joint name="right_gripper_palm_finger_middle_joint" type="fixed">
    <parent link="right_gripper_palm"/>
    <child link="right_gripper_finger_middle_link_0"/>
    <axis xyz="0 0 1"/>
    <origin rpy="0 0 1.57" xyz="0.0455 0.0214 0"/>
  </joint>
  <joint name="right_gripper_palm_tool0" type="fixed">
    <parent link="right_gripper_palm"/>
    <child link="right_gripper_tool0"/>
    <origin rpy="0 0 1.5707" xyz="0.0 0.0875 0.0"/>
  </joint>
  <!-- end of joint list -->
  <joint name="right_gripper_joint" type="fixed">
    <origin rpy="1.5707963267948966 0 -0.7853981633974483" xyz="0 0 0.068825"/>
    <parent link="right_gripper_flange"/>
    <child link="right_gripper_palm"/>
  </joint>
  <link name="world"/>
  <!-- <xacro:include filename="$(find env_description)/livingroom_env/assets/interactive/drawer/drawer.xacro" /> -->
  <!-- <xacro:include filename="$(find env_description)/livingroom_env/assets/rigid/teapoy.xacro" /> -->
  <!-- <xacro:include filename="$(find env_description)/livingroom_env/assets/rigid/stick.xacro" /> -->
  <link name="ikea_table_box_base_link"/>
  <joint name="ikea_table_box_base_joint" type="fixed">
    <origin rpy="0 0 3.1415926" xyz="2 -2.7 0"/>
    <parent link="world"/>
    <child link="ikea_table_box_base_link"/>
    <axis xyz="0 0 0"/>
  </joint>
  <link name="ikea_table_box_link">
    <visual>
      <origin rpy="0 0 0" xyz="0 0 -0.265"/>
      <geometry>
        <box size="0.43 1 0.53"/>
      </geometry>
      <material name="">
        <color rgba="0.564705882352941 0.564705882352941 0.564705882352941 1"/>
      </material>
    </visual>
    <collision>
      <origin rpy="0 0 0" xyz="0 0 -0.265"/>
      <geometry>
        <box size="0.43 1 0.53"/>
      </geometry>
    </collision>
  </link>
  <joint name="ikea_table_box_joint" type="fixed">
    <origin rpy="0 0 0" xyz="0 0 0.53"/>
    <parent link="ikea_table_box_base_link"/>
    <child link="ikea_table_box_link"/>
    <axis xyz="0 0 0"/>
  </joint>
  <!-- <link name="${prefix}_box_link">
      <visual>
        <origin xyz="0 0 ${-box_height/2}" rpy="0 0 0" />
        <geometry>
            <box size="${box_length} ${box_width} ${box_height}"/>
        </geometry>
        <material name="">
          <color rgba="0.564705882352941 0.564705882352941 0.564705882352941 1" />
        </material>
      </visual>
      <collision>
        <origin xyz="0 0 0" rpy="0 0 0" />
        <geometry>
          <box size="${box_length} ${box_width} ${box_height}"/>
        </geometry>
      </collision>
    </link>
    <joint name="${prefix}_box_joint" type="fixed">
      <origin xyz="0 0 ${box_height}" rpy="0 0 0" />
      <parent link="${prefix}_box_base_link" />
      <child link="${prefix}_box_link" />
      <axis xyz="0 0 0" />
    </joint> -->
  <link name="office_table_table_base_link"/>
  <joint name="office_table_table_base_joint" type="fixed">
    <origin rpy="0 0 3.1415926" xyz="1.8 2 0.75"/>
    <parent link="world"/>
    <child link="office_table_table_base_link"/>
    <axis xyz="0 0 0"/>
  </joint>
  <link name="office_table_table_link">
    <inertial>
      <origin rpy="0 0 0" xyz="0 1.66533453693773E-16 0.739609856262833"/>
      <mass value="97.4000000000001"/>
      <inertia ixx="10.6298985078713" ixy="-1.55850332639318E-14" ixz="1.61645738949227E-14" iyy="22.2248985078712" iyz="1.27560526488281E-14" izz="29.9373333333332"/>
    </inertial>
    <visual>
      <origin rpy="0 0 0" xyz="0 0 0"/>
      <geometry>
        <mesh filename="package://env_description/tieta_env/assets/rigid/table_link.STL" scale="0.8 0.6 0.9375"/>
      </geometry>
      <material name="">
        <color rgba="0.564705882352941 0.564705882352941 0.564705882352941 1"/>
      </material>
    </visual>
    <collision>
      <origin rpy="0 0 0" xyz="0 0 0"/>
      <geometry>
        <mesh filename="package://env_description/tieta_env/assets/rigid/table_link.STL" scale="0.85 0.7 0.9375"/>
      </geometry>
    </collision>
  </link>
  <joint name="office_table_table_joint" type="fixed">
    <origin rpy="0 0 1.57" xyz="0 0 -0.75"/>
    <parent link="office_table_table_base_link"/>
    <child link="office_table_table_link"/>
    <axis xyz="0 0 0"/>
  </joint>
  <link name="Tvbox_Tvbox_base_link"/>
  <joint name="Tvbox_Tvbox_base_joint" type="fixed">
    <origin rpy="0 0 3.1415926" xyz="2.2 -1.1 0"/>
    <parent link="world"/>
    <child link="Tvbox_Tvbox_base_link"/>
    <axis xyz="0 0 0"/>
  </joint>
  <link name="Tvbox_Tvbox_upper_link">
    <visual>
      <origin rpy="0 0 0" xyz="0 0 0"/>
      <geometry>
        <box size="0.13 1.72 1.07"/>
      </geometry>
      <material name="">
        <color rgba="0.564705882352941 0.564705882352941 0.564705882352941 1"/>
      </material>
    </visual>
    <collision>
      <origin rpy="0 0 0" xyz="0 0 0"/>
      <geometry>
        <box scale="1 1 1" size="0.13 1.72 1.07"/>
      </geometry>
    </collision>
  </link>
  <joint name="Tvbox_Tvbox_upper_joint" type="fixed">
    <origin rpy="0 0 0" xyz="-0.065 0 1.315"/>
    <parent link="Tvbox_Tvbox_base_link"/>
    <child link="Tvbox_Tvbox_upper_link"/>
    <axis xyz="0 0 0"/>
  </joint>
  <link name="Tvbox_Tvbox_bottom_link">
    <visual>
      <origin rpy="0 0 0" xyz="0 0 0"/>
      <geometry>
        <box size="0.78 1.2 0.78"/>
      </geometry>
      <material name="">
        <color rgba="0.564705882352941 0.564705882352941 0.564705882352941 1"/>
      </material>
    </visual>
    <collision>
      <origin rpy="0 0 0" xyz="0 0 0"/>
      <geometry>
        <box scale="1 1 1" size="0.78 1.2 0.78"/>
      </geometry>
    </collision>
  </link>
  <joint name="Tvbox_Tvbox_bottom_joint" type="fixed">
    <origin rpy="0 0 0" xyz="0 0 -0.925"/>
    <parent link="Tvbox_Tvbox_upper_link"/>
    <child link="Tvbox_Tvbox_bottom_link"/>
    <axis xyz="0 0 0"/>
  </joint>
  <link name="tissue_box_base_link"/>
  <joint name="tissue_box_base_joint" type="fixed">
    <origin rpy="0 0 0.0" xyz="1.85609010174 2.3 0.851320510859"/>
    <parent link="world"/>
    <child link="tissue_box_base_link"/>
    <axis xyz="0 0 0"/>
  </joint>
  <link name="tissue_box_link">
    <visual>
      <origin rpy="0 0 0" xyz="0 0 0"/>
      <geometry>
        <box size="0.12 0.14 0.1"/>
      </geometry>
      <material name="">
        <color rgba="0.564705882352941 0.564705882352941 0.564705882352941 1"/>
      </material>
    </visual>
    <collision>
      <origin rpy="0 0 0" xyz="0 0 0"/>
      <geometry>
        <box size="0.15 0.16 0.12"/>
      </geometry>
    </collision>
  </link>
  <joint name="tissue_box_joint" type="fixed">
    <origin rpy="0 0 0" xyz="0 0 -0.05"/>
    <parent link="tissue_box_base_link"/>
    <child link="tissue_box_link"/>
    <axis xyz="0 0 0"/>
  </joint>
  <link name="tissue_empty_box_base_link"/>
  <joint name="tissue_empty_box_base_joint" type="fixed">
    <origin rpy="0 0 0.0" xyz="1.85609010174 2.5 0.851320510859"/>
    <parent link="world"/>
    <child link="tissue_empty_box_base_link"/>
    <axis xyz="0 0 0"/>
  </joint>
  <link name="tissue_empty_box_link">
    <visual>
      <origin rpy="0 0 0" xyz="0 0 0"/>
      <geometry>
        <box size="0.14 0.24 0.1"/>
      </geometry>
      <material name="">
        <color rgba="0.564705882352941 0.564705882352941 0.564705882352941 1"/>
      </material>
    </visual>
    <collision>
      <origin rpy="0 0 0" xyz="0 0 0"/>
      <geometry>
        <box scale="1 1 1" size="0.16 0.26 0.12"/>
      </geometry>
    </collision>
  </link>
  <joint name="tissue_empty_box_joint" type="fixed">
    <origin rpy="0 0 0" xyz="0 0 -0.05"/>
    <parent link="tissue_empty_box_base_link"/>
    <child link="tissue_empty_box_link"/>
    <axis xyz="0 0 0"/>
  </joint>
  <link name="closet_base_link">
    <inertial>
      <origin rpy="0 0 0" xyz="0.194178515040246 0.584999999999999 1.21348104180704"/>
      <mass value="294.108283185308"/>
      <inertia ixx="266.662530970608" ixy="2.44252017176031E-14" ixz="1.41508571383804" iyy="229.907989654031" iyz="-6.54631169708434E-14" izz="57.236758061963"/>
    </inertial>
    <visual>
      <origin rpy="0 0 0" xyz="0 0 0"/>
      <geometry>
        <mesh filename="package://env_description/tieta_env/assets/interactive/closet/meshes/base_link.STL"/>
      </geometry>
      <material name="">
        <color rgba="1 1 1 1"/>
      </material>
    </visual>
    <collision name="collision1">
      <origin rpy="0 0 0" xyz="0 0 0"/>
      <geometry>
        <mesh filename="package://env_description/tieta_env/assets/interactive/closet/meshes/base_link.STL" scale="0.2 1 1"/>
      </geometry>
    </collision>
    <collision name="collision2">
      <origin rpy="0 0 0" xyz="0.40 0 0"/>
      <geometry>
        <mesh filename="package://env_description/tieta_env/assets/interactive/closet/meshes/bottom_left_door_link.STL" scale="20 1 1"/>
      </geometry>
    </collision>
  </link>
  <joint name="closet_base_joint" type="fixed">
    <origin rpy="0 0 3.1415926" xyz="2.05 1.2 0"/>
    <parent link="world"/>
    <child link="closet_base_link"/>
    <axis xyz="0 0 0"/>
  </joint>
  <link name="closet_plane_link">
    <inertial>
      <origin rpy="0 0 0" xyz="0.194178515040246 0.584999999999999 1.21348104180704"/>
      <mass value="294.108283185308"/>
      <inertia ixx="266.662530970608" ixy="2.44252017176031E-14" ixz="1.41508571383804" iyy="229.907989654031" iyz="-6.54631169708434E-14" izz="57.236758061963"/>
    </inertial>
    <visual>
      <origin rpy="0 0 0" xyz="0 0 0"/>
      <geometry>
        <box size="0.52 0.52 0.01"/>
      </geometry>
      <material name="">
        <color rgba="1 1 1 1"/>
      </material>
    </visual>
    <collision>
      <origin rpy="0 0 0" xyz="0 0 0"/>
      <geometry>
        <box scale="1.1 1 2" size="0.52 0.52 0.01"/>
      </geometry>
    </collision>
  </link>
  <joint name="closet_plane_joint" type="fixed">
    <origin rpy="0 0 0" xyz="0.26 0.78 0.95"/>
    <parent link="closet_base_link"/>
    <child link="closet_plane_link"/>
    <axis xyz="0 0 0"/>
  </joint>
  <link name="closet_top_left_door_link">
    <inertial>
      <origin rpy="0 0 0" xyz="-0.00450128837595587 0.274578590933319 0.244932718144518"/>
      <mass value="5.48642920367321"/>
      <inertia ixx="0.25302023864289" ixy="-1.94088168924543E-06" ixz="1.66159270299727E-06" iyy="0.109901800608201" iyz="-0.000101357154882833" izz="0.143484221430936"/>
    </inertial>
    <visual>
      <origin rpy="0 0 0" xyz="0 0 0"/>
      <geometry>
        <mesh filename="package://env_description/tieta_env/assets/interactive/closet/meshes/top_left_door_link.STL"/>
      </geometry>
      <material name="">
        <color rgba="1 1 1 1"/>
      </material>
    </visual>
    <collision>
      <origin rpy="0 0 0" xyz="0 0 0"/>
      <geometry>
        <mesh filename="package://env_description/tieta_env/assets/interactive/closet/meshes/top_left_door_link.STL"/>
      </geometry>
    </collision>
  </link>
  <joint name="closet_top_left_door_joint" type="fixed">
    <origin rpy="0 0 0" xyz="0.5745 0.0305 1.99"/>
    <parent link="closet_base_link"/>
    <child link="closet_top_left_door_link"/>
    <axis xyz="0 0 -1"/>
    <limit effort="30" lower="0.0" upper="3.14" velocity="10"/>
  </joint>
  <link name="closet_top_left_handle">
    <inertial>
      <origin rpy="0 0 0" xyz="0.00955678974336438 0 2.26330649466533E-06"/>
      <mass value="0.0101205665745806"/>
      <inertia ixx="3.69207813332895E-06" ixy="4.35319965292841E-21" ixz="-5.55852026511251E-12" iyy="4.85274053427323E-06" iyz="4.35547781179855E-21" izz="1.51613518793949E-06"/>
    </inertial>
    <visual>
      <origin rpy="0 0 0" xyz="0 0 0"/>
      <geometry>
        <mesh filename="package://env_description/tieta_env/assets/interactive/closet/meshes/top_left_handle.STL"/>
      </geometry>
      <material name="">
        <color rgba="1 1 1 1"/>
      </material>
    </visual>
    <collision>
      <origin rpy="0 0 0" xyz="0 0 0"/>
      <geometry>
        <mesh filename="package://env_description/tieta_env/assets/interactive/closet/meshes/top_left_handle.STL"/>
      </geometry>
    </collision>
  </link>
  <joint name="closet_top_left_handle_joint" type="fixed">
    <origin rpy="0 0 0" xyz="0.0105 0.506999999999999 0.281498172103289"/>
    <parent link="closet_top_left_door_link"/>
    <child link="closet_top_left_handle"/>
    <axis xyz="0 0 0"/>
  </joint>
  <link name="closet_top_right_door_link">
    <inertial>
      <origin rpy="0 0 0" xyz="-0.00450128837595543 -0.274578590933319 0.244932718144518"/>
      <mass value="5.48642920367321"/>
      <inertia ixx="0.25302023864289" ixy="1.94088168924509E-06" ixz="1.66159270299727E-06" iyy="0.109901800608201" iyz="0.000101357154882817" izz="0.143484221430936"/>
    </inertial>
    <visual>
      <origin rpy="0 0 0" xyz="0 0 0"/>
      <geometry>
        <mesh filename="package://env_description/tieta_env/assets/interactive/closet/meshes/top_right_door_link.STL"/>
      </geometry>
      <material name="">
        <color rgba="1 1 1 1"/>
      </material>
    </visual>
    <collision>
      <origin rpy="0 0 0" xyz="0 0 -0.03"/>
      <geometry>
        <mesh filename="package://env_description/tieta_env/assets/interactive/closet/meshes/top_right_door_link.STL" scale="3 1 1.1"/>
      </geometry>
    </collision>
  </link>
  <joint name="closet_top_right_door_joint" type="fixed">
    <origin rpy="0 0 0" xyz="0.5745 1.1395 1.99"/>
    <parent link="closet_base_link"/>
    <child link="closet_top_right_door_link"/>
    <axis xyz="0 0 1"/>
    <limit effort="30" lower="0.0" upper="3.14" velocity="10"/>
  </joint>
  <link name="closet_top_right_handle">
    <inertial>
      <origin rpy="0 0 0" xyz="0.00955678974336482 -3.33066907387547E-16 2.26330649422124E-06"/>
      <mass value="0.0101205665745807"/>
      <inertia ixx="3.69207813332882E-06" ixy="4.11359919739862E-21" ixz="-5.55852026534859E-12" iyy="4.85274053427329E-06" iyz="3.11231300260592E-21" izz="1.51613518793932E-06"/>
    </inertial>
    <visual>
      <origin rpy="0 0 0" xyz="0 0 0"/>
      <geometry>
        <mesh filename="package://env_description/tieta_env/assets/interactive/closet/meshes/top_right_handle.STL"/>
      </geometry>
      <material name="">
        <color rgba="1 1 1 1"/>
      </material>
    </visual>
    <collision>
      <origin rpy="0 0 0" xyz="0 0 0"/>
      <geometry>
        <mesh filename="package://env_description/tieta_env/assets/interactive/closet/meshes/top_right_handle.STL"/>
      </geometry>
    </collision>
  </link>
  <joint name="closet_top_right_handle_joint" type="fixed">
    <origin rpy="0 0 0" xyz="0.0105000000000004 -0.507 0.281498172103289"/>
    <parent link="closet_top_right_door_link"/>
    <child link="closet_top_right_handle"/>
    <axis xyz="0 0 0"/>
  </joint>
  <link name="closet_bottom_left_door_link">
    <inertial>
      <origin rpy="0 0 0" xyz="-0.00450034302806168 0.274520924711771 0.919930632103056"/>
      <mass value="20.6064292036732"/>
      <inertia ixx="6.3513401599766" ixy="-1.94047407074802E-06" ixz="6.43290129099749E-06" iyy="5.81358969708387" iyz="-0.000392406978750845" izz="0.539124246302347"/>
    </inertial>
    <visual>
      <origin rpy="0 0 0" xyz="0 0 0"/>
      <geometry>
        <mesh filename="package://env_description/tieta_env/assets/interactive/closet/meshes/bottom_left_door_link.STL"/>
      </geometry>
      <material name="">
        <color rgba="1 1 1 1"/>
      </material>
    </visual>
    <collision>
      <!-- <origin xyz="0.013 -0.05 0" rpy="0 0 0" /> -->
      <origin rpy="0 0 0" xyz="0.0 0.0 0"/>
      <geometry>
        <mesh filename="package://env_description/tieta_env/assets/interactive/closet/meshes/bottom_left_door_link.STL" scale="2.0 1.05 1.0"/>
      </geometry>
    </collision>
  </link>
  <joint name="closet_bottom_left_door_joint" type="fixed">
    <origin rpy="0 0 0" xyz="0.5745 0.0305000000000002 0.0849999999999999"/>
    <parent link="closet_base_link"/>
    <child link="closet_bottom_left_door_link"/>
    <axis xyz="0 0 -1"/>
    <limit effort="30" lower="0.0" upper="3.14" velocity="10"/>
  </joint>
  <link name="closet_bottom_left_handle">
    <inertial>
      <origin rpy="0 0 0" xyz="0.00955678974336482 -2.22044604925031E-16 2.26330649422124E-06"/>
      <mass value="0.0101205665745809"/>
      <inertia ixx="3.69207813332893E-06" ixy="3.08073100413027E-21" ixz="-5.5585202656004E-12" iyy="4.85274053427342E-06" iyz="5.95075922556884E-22" izz="1.51613518793931E-06"/>
    </inertial>
    <visual>
      <origin rpy="0 0 0" xyz="0 0 0"/>
      <geometry>
        <mesh filename="package://env_description/tieta_env/assets/interactive/closet/meshes/bottom_left_handle.STL"/>
      </geometry>
      <material name="">
        <color rgba="1 1 1 1"/>
      </material>
    </visual>
    <!-- <collision>
        <origin xyz="0 0 0" rpy="0 0 0" />
        <geometry>
          <mesh filename="${mesh_dir}/bottom_left_handle.STL" />
        </geometry>
      </collision> -->
  </link>
  <joint name="closet_bottom_left_handle_joint" type="fixed">
    <origin rpy="0 0 0" xyz="0.0105 0.507 1.0515"/>
    <parent link="closet_bottom_left_door_link"/>
    <child link="closet_bottom_left_handle"/>
    <axis xyz="0 0 0"/>
  </joint>
  <link name="closet_bottom_right_door_link">
    <inertial>
      <origin rpy="0 0 0" xyz="-0.00450034302806168 -0.27452092471177 0.919930632103056"/>
      <mass value="20.6064292036732"/>
      <inertia ixx="6.3513401599766" ixy="1.94047407074222E-06" ixz="6.43290129099753E-06" iyy="5.81358969708387" iyz="0.000392406978750521" izz="0.539124246302347"/>
    </inertial>
    <visual>
      <origin rpy="0 0 0" xyz="0 0 0"/>
      <geometry>
        <mesh filename="package://env_description/tieta_env/assets/interactive/closet/meshes/bottom_right_door_link.STL" scale="1 1 1"/>
      </geometry>
      <material name="">
        <color rgba="1 1 1 1"/>
      </material>
    </visual>
    <!-- <collision>
        <origin xyz="0 0.1 0" rpy="0 0 0" />
        <geometry>
          <mesh filename="${mesh_dir}/bottom_right_door_link.STL" scale="1.0 1.0 1"/>
        </geometry>
      </collision> -->
    <collision>
      <origin rpy="0 0 0" xyz="0 0.1 0"/>
      <geometry>
        <mesh filename="package://env_description/tieta_env/assets/interactive/closet/meshes/bottom_right_door_link.STL" scale="3.0 1.5 1"/>
      </geometry>
    </collision>
  </link>
  <joint name="closet_bottom_right_door_joint" type="revolute">
    <origin rpy="0 0 0" xyz="0.5745 1.1395 0.085"/>
    <parent link="closet_base_link"/>
    <child link="closet_bottom_right_door_link"/>
    <axis xyz="0 0 1"/>
    <limit effort="30" lower="0.0" upper="3.14" velocity="10"/>
  </joint>
  <link name="closet_bottom_right_handle">
    <inertial>
      <origin rpy="0 0 0" xyz="0.00955678974336482 0 2.26330649422124E-06"/>
      <mass value="0.0101205665745808"/>
      <inertia ixx="3.69207813332901E-06" ixy="2.04776361972461E-21" ixz="-5.55852026494191E-12" iyy="4.85274053427337E-06" iyz="-5.48739223596335E-21" izz="1.51613518793942E-06"/>
    </inertial>
    <visual>
      <origin rpy="0 0 0" xyz="0 0 0"/>
      <geometry>
        <mesh filename="package://env_description/tieta_env/assets/interactive/closet/meshes/bottom_right_handle.STL"/>
      </geometry>
      <material name="">
        <color rgba="1 1 1 1"/>
      </material>
    </visual>
    <collision>
      <origin rpy="0 0 0" xyz="0 0 0"/>
      <geometry>
        <mesh filename="package://env_description/tieta_env/assets/interactive/closet/meshes/bottom_right_handle.STL" scale="3.5 2.8 2.8"/>
      </geometry>
    </collision>
  </link>
  <joint name="closet_bottom_right_handle_joint" type="fixed">
    <!-- <origin xyz="0.0105 -0.507 1.05149817210329" rpy="0 0 0" /> -->
    <!-- <origin xyz="0.0105 -0.524 1.05149817210329" rpy="0 0 0" /> -->
    <!-- <origin xyz="0.0105 -0.500 1.05149817210329" rpy="0 0 0" /> -->
    <origin rpy="0 0 0" xyz="0.0105 -0.507 1.05149817210329"/>
    <parent link="closet_bottom_right_door_link"/>
    <child link="closet_bottom_right_handle"/>
    <axis xyz="0 0 0"/>
  </joint>
  <link name="door_lfet_bottom">
  </link>
  <joint name="door_lfet_bottom_joint" type="fixed">
    <parent link="closet_bottom_right_door_link"/>
    <child link="door_lfet_bottom"/>
    <origin rpy="0 0 0" xyz="0.0 -0.56 0.0"/>
  </joint>
  <!-- <xacro:foldable_table prefix="foldable_table" x="0" y="-2" z="0.75" theta="0" /> -->
  <!-- <xacro:chair prefix="chair" x="0" y="2" theta="0" /> -->
  <!-- <xacro:drawer prefix="drawer" x="1.7" y="0.35" z="0.68" theta="3.1415926" /> -->
  <!-- <xacro:stick prefix="stick" xyz="0 0 0" rpy="0 0 0" /> -->
  <link name="wall_link_north">
    <visual>
      <origin rpy="0 0 0" xyz="0 0 0"/>
      <geometry>
        <box size="0.2 11.1 2"/>
      </geometry>
      <material name="custom_color">
        <color rgba="0.943 0.765 0.461 1"/>
      </material>
    </visual>
    <collision>
      <origin rpy="0 0 0" xyz="0 0 0"/>
      <geometry>
        <box size="0.2 11.1 2"/>
      </geometry>
    </collision>
  </link>
  <joint name="north_wall_world_joint" type="fixed">
    <origin rpy="0 0 0" xyz="2.7 0 1"/>
    <parent link="world"/>
    <child link="wall_link_north"/>
    <axis xyz="0 0 0"/>
  </joint>
  <link name="wall_link_east">
    <visual>
      <origin rpy="0 0 0" xyz="0 0 0"/>
      <geometry>
        <box size="0.2 5 2"/>
      </geometry>
      <material name="custom_color">
        <color rgba="0.943 0.765 0.461 1"/>
      </material>
    </visual>
    <collision>
      <origin rpy="0 0 0" xyz="0 0 0"/>
      <geometry>
        <box size="0.2 5 2"/>
      </geometry>
    </collision>
  </link>
  <joint name="east_wall_world_joint" type="fixed">
    <origin rpy="0 0 1.57" xyz="0 -5 1"/>
    <parent link="world"/>
    <child link="wall_link_east"/>
    <axis xyz="0 0 0"/>
  </joint>
  <!-- <link name="wall_link_south">
    <visual>
      <origin xyz="0 0 0" rpy="0 0 0" />
      <geometry>
        <box size="0.2 11.1 2" />
      </geometry>
    </visual>
    <collision>
      <origin xyz="0 0 0" rpy="0 0 0" />
      <geometry>
        <box size="0.2 11.1 2" />
      </geometry>
    </collision>
  </link>
  <joint name="south_wall_world_joint" type="fixed">
    <origin xyz="-2.5 0 1" rpy="0 0 0" />
    <parent link="world" />
    <child link="wall_link_south" />
    <axis xyz="0 0 0" />
  </joint> -->
  <link name="wall_link_west">
    <visual>
      <origin rpy="0 0 0" xyz="0.5 0 0"/>
      <geometry>
        <box size="0.2 5 2"/>
      </geometry>
      <material name="custom_color">
        <color rgba="0.943 0.765 0.461 1"/>
      </material>
    </visual>
    <collision>
      <origin rpy="0 0 0" xyz="0.5 0 0"/>
      <geometry>
        <box size="0.2 5 2"/>
      </geometry>
    </collision>
  </link>
  <joint name="west_wall_world_joint" type="fixed">
    <origin rpy="0 0 1.57" xyz="0 4.5 1"/>
    <parent link="world"/>
    <child link="wall_link_west"/>
    <axis xyz="0 0 0"/>
  </joint>
  <!-- 外部修改 -->
  <!-- Setup Environment -->
  <!--
    link order: world link -> virtual_base_x -> virtual_base_y -> virtual_base_theta -> base_link
  -->
  <link name="virtual_base_theta"/>
  <joint name="base_link_base_theta" type="revolute">
    <!-- <joint name="$(arg robot_prefix)base_link_base_theta" type="continuous"> -->
    <parent link="virtual_base_theta"/>
    <origin rpy="0 0 0" xyz="0.0 0.0 0.0"/>
    <child link="base_link"/>
    <axis xyz="0 0 1"/>
    <limit effort="20" lower="-3.14" upper="3.14" velocity="5.0"/>
    <!-- <limit effort="20" velocity="5.0"/> -->
  </joint>
  <link name="virtual_base_y"/>
  <joint name="base_theta_base_y" type="prismatic">
    <parent link="virtual_base_y"/>
    <origin rpy="0 0 0" xyz="0.0 0.0 0.0"/>
    <child link="virtual_base_theta"/>
    <axis xyz="0 1 0"/>
    <limit effort="20" lower="-10" upper="10" velocity="5.0"/>
  </joint>
  <link name="virtual_base_x"/>
  <joint name="base_y_base_x" type="prismatic">
    <parent link="virtual_base_x"/>
    <origin rpy="0 0 0" xyz="0.0 0.0 0.0"/>
    <child link="virtual_base_y"/>
    <axis xyz="1 0 0"/>
    <limit effort="20" lower="-10" upper="10" velocity="5.0"/>
  </joint>
  <!-- <link name="world"/> -->
  <joint name="world_to_base_footprint" type="fixed">
    <parent link="world"/>
    <child link="virtual_base_x"/>
    <origin rpy="0 0 0.0" xyz="0.0 0.0 0.01965"/>
  </joint>
  <!-- 圆柱行人建模 -->
  <link name="dynamic_pedestrian">
    <visual>
      <origin rpy="0 0 0" xyz="0 0 0"/>
      <geometry>
        <cylinder length="3.0" radius="0.2"/>
      </geometry>
      <material name="blue">
        <color rgba="0 0 1 0.5"/>
      </material>
    </visual>
    <collision>
      <origin rpy="0 0 0" xyz="0 0 0"/>
      <geometry>
        <cylinder length="3.0" radius="0.2"/>
      </geometry>
    </collision>
  </link>
  <joint name="dynamic_pedestrian_joint_y" type="prismatic">
    <parent link="dynamic_pedestrian_world_x"/>
    <child link="dynamic_pedestrian"/>
    <origin rpy="0 0 0" xyz="0.0 0.0 1.5"/>
    <axis xyz="0 1 0"/>
    <limit effort="20" lower="-8" upper="0.5" velocity="0.3"/>
  </joint>
  <link name="dynamic_pedestrian_world_x"/>
  <joint name="dynamic_pedestrian_joint_x" type="prismatic">
    <parent link="world"/>
    <child link="dynamic_pedestrian_world_x"/>
    <origin rpy="0 0 0" xyz="-0.1 4.5 0.0"/>
    <axis xyz="1 0 0"/>
    <limit effort="20" lower="-3" upper="2" velocity="0.3"/>
  </joint>
  <!-- pervious is 0.6 -->
  <link name="closet_right_rear">
  </link>
  <joint name="closet_right_rear_joint" type="fixed">
    <parent link="world"/>
    <child link="closet_right_rear"/>
    <origin rpy="0 0 0" xyz="2.05 0.03 0.085"/>
  </joint>
  <link name="closet_right_front">
  </link>
  <joint name="closet_right_front_joint" type="fixed">
    <parent link="world"/>
    <child link="closet_right_front"/>
    <origin rpy="0 0 0" xyz="1.4755 0.03 0.085"/>
  </joint>
  <link name="closet_left_front">
  </link>
  <joint name="closet_left_front_joint" type="fixed">
    <parent link="world"/>
    <child link="closet_left_front"/>
    <origin rpy="0 0 0" xyz="1.4755 1.2 0.085"/>
  </joint>
  <link name="tv_surface_link">
  </link>
  <joint name="tv_surface_link_joint" type="fixed">
    <parent link="world"/>
    <child link="tv_surface_link"/>
    <origin rpy="0 0 0" xyz="1.875 -1.1 0.39"/>
  </joint>
  <!-- ridgeback robot end -->
</robot>

