<?xml version="1.0" encoding="utf-8" ?>
<!-- =================================================================================== -->
<!-- |    This document was autogenerated by xacro from /home/ridgeback/catkin_ws/src/ridgeback_dual_arm_description/urdf/vkc_robot.urdf.xacro | -->
<!-- |    EDITING THIS FILE BY HAND IS NOT RECOMMENDED                                 | -->
<!-- =================================================================================== -->
<robot name="scene">
    <material name="dark_grey">
        <color rgba="0.2 0.2 0.2 1.0" />
    </material>
    <material name="light_grey">
        <color rgba="0.4 0.4 0.4 1.0" />
    </material>
    <material name="red">
        <color rgba="0.8 0.0 0.0 1.0" />
    </material>
    <material name="white">
        <color rgba="0.9 0.9 0.9 1.0" />
    </material>
    <material name="yellow">
        <color rgba="0.8 0.8 0.0 1.0" />
    </material>
    <material name="black">
        <color rgba="0.15 0.15 0.15 1.0" />
    </material>
    <link name="front_rocker_link">
        <visual>
            <origin rpy="1.57079632679 0 1.57079632679" xyz="0 0 0" />
            <geometry>
                <mesh filename="package://ridgeback_description/meshes/rocker.stl" />
            </geometry>
            <material name="black" />
        </visual>
        <inertial>
            <origin rpy="1.57079632679 0 1.57079632679" xyz="0 0 0" />
            <mass value="10.267" />
            <inertia ixx="0.0288" ixy="2.20484e-6" ixz="-1.3145e-5" iyy="0.4324" iyz="1.8944e-3" izz="0.4130" />
        </inertial>
    </link>
    <joint name="front_rocker" type="revolute">
        <parent link="axle_link" />
        <child link="front_rocker_link" />
        <origin rpy="0 0 0" xyz="0.319 0 0" />
        <axis xyz="1 0 0" />
        <limit effort="0" lower="-0.08726" upper="0.08726" velocity="0" />
    </joint>
    <link name="front_left_wheel_link">
        <visual>
            <origin rpy="1.57079632679 0 0" xyz="0 0 0" />
            <geometry>
                <mesh filename="package://ridgeback_description/meshes/wheel.stl" />
            </geometry>
            <material name="black" />
        </visual>
        <collision>
            <origin rpy="1.57079632679 0 0" xyz="0 0 0" />
            <geometry>
                <cylinder length="0.079" radius="0.0759" />
            </geometry>
        </collision>
        <inertial>
            <origin rpy="0 0 0" xyz="0 0 0" />
            <mass value="2.3" />
            <inertia ixx="3.3212e-3" ixy="0" ixz="0" iyy="6.6424e-3" iyz="0" izz="3.3212e-3" />
        </inertial>
    </link>
    <joint name="front_left_wheel" type="continuous">
        <parent link="front_rocker_link" />
        <child link="front_left_wheel_link" />
        <origin rpy="0 0 0" xyz="0 0.2755 0" />
        <axis xyz="0 1 0" />
    </joint>
    <transmission name="front_wheel_trans">
        <type>transmission_interface/SimpleTransmission</type>
        <joint name="front_left_wheel">
            <hardwareInterface>hardware_interface/VelocityJointInterface</hardwareInterface>
        </joint>
        <actuator name="front_left_actuator">
            <mechanicalReduction>1</mechanicalReduction>
            <hardwareInterface>hardware_interface/EffortJointInterface</hardwareInterface>
        </actuator>
    </transmission>
    <link name="front_right_wheel_link">
        <visual>
            <origin rpy="1.57079632679 0 0" xyz="0 0 0" />
            <geometry>
                <mesh filename="package://ridgeback_description/meshes/wheel.stl" />
            </geometry>
            <material name="black" />
        </visual>
        <collision>
            <origin rpy="1.57079632679 0 0" xyz="0 0 0" />
            <geometry>
                <cylinder length="0.079" radius="0.0759" />
            </geometry>
        </collision>
        <inertial>
            <origin rpy="0 0 0" xyz="0 0 0" />
            <mass value="2.3" />
            <inertia ixx="3.3212e-3" ixy="0" ixz="0" iyy="6.6424e-3" iyz="0" izz="3.3212e-3" />
        </inertial>
    </link>
    <joint name="front_right_wheel" type="continuous">
        <parent link="front_rocker_link" />
        <child link="front_right_wheel_link" />
        <origin rpy="0 0 0" xyz="0 -0.2755 0" />
        <axis xyz="0 1 0" />
    </joint>
    <transmission name="front_wheel_trans">
        <type>transmission_interface/SimpleTransmission</type>
        <joint name="front_right_wheel">
            <hardwareInterface>hardware_interface/VelocityJointInterface</hardwareInterface>
        </joint>
        <actuator name="front_right_actuator">
            <mechanicalReduction>1</mechanicalReduction>
            <hardwareInterface>hardware_interface/EffortJointInterface</hardwareInterface>
        </actuator>
    </transmission>
    <link name="rear_rocker_link">
        <visual>
            <origin rpy="1.57079632679 0 1.57079632679" xyz="0 0 0" />
            <geometry>
                <mesh filename="package://ridgeback_description/meshes/rocker.stl" />
            </geometry>
            <material name="black" />
        </visual>
        <inertial>
            <origin rpy="1.57079632679 0 1.57079632679" xyz="0 0 0" />
            <mass value="10.267" />
            <inertia ixx="0.0288" ixy="2.20484e-6" ixz="-1.3145e-5" iyy="0.4324" iyz="1.8944e-3" izz="0.4130" />
        </inertial>
    </link>
    <joint name="rear_rocker" type="fixed">
        <parent link="axle_link" />
        <child link="rear_rocker_link" />
        <origin rpy="0 0 0" xyz="-0.319 0 0" />
        <axis xyz="1 0 0" />
        <limit effort="0" velocity="0" />
    </joint>
    <link name="rear_left_wheel_link">
        <visual>
            <origin rpy="1.57079632679 0 0" xyz="0 0 0" />
            <geometry>
                <mesh filename="package://ridgeback_description/meshes/wheel.stl" />
            </geometry>
            <material name="black" />
        </visual>
        <collision>
            <origin rpy="1.57079632679 0 0" xyz="0 0 0" />
            <geometry>
                <cylinder length="0.079" radius="0.0759" />
            </geometry>
        </collision>
        <inertial>
            <origin rpy="0 0 0" xyz="0 0 0" />
            <mass value="2.3" />
            <inertia ixx="3.3212e-3" ixy="0" ixz="0" iyy="6.6424e-3" iyz="0" izz="3.3212e-3" />
        </inertial>
    </link>
    <joint name="rear_left_wheel" type="continuous">
        <parent link="rear_rocker_link" />
        <child link="rear_left_wheel_link" />
        <origin rpy="0 0 0" xyz="0 0.2755 0" />
        <axis xyz="0 1 0" />
    </joint>
    <transmission name="rear_wheel_trans">
        <type>transmission_interface/SimpleTransmission</type>
        <joint name="rear_left_wheel">
            <hardwareInterface>hardware_interface/VelocityJointInterface</hardwareInterface>
        </joint>
        <actuator name="rear_left_actuator">
            <mechanicalReduction>1</mechanicalReduction>
            <hardwareInterface>hardware_interface/EffortJointInterface</hardwareInterface>
        </actuator>
    </transmission>
    <link name="rear_right_wheel_link">
        <visual>
            <origin rpy="1.57079632679 0 0" xyz="0 0 0" />
            <geometry>
                <mesh filename="package://ridgeback_description/meshes/wheel.stl" />
            </geometry>
            <material name="black" />
        </visual>
        <collision>
            <origin rpy="1.57079632679 0 0" xyz="0 0 0" />
            <geometry>
                <cylinder length="0.079" radius="0.0759" />
            </geometry>
        </collision>
        <inertial>
            <origin rpy="0 0 0" xyz="0 0 0" />
            <mass value="2.3" />
            <inertia ixx="3.3212e-3" ixy="0" ixz="0" iyy="6.6424e-3" iyz="0" izz="3.3212e-3" />
        </inertial>
    </link>
    <joint name="rear_right_wheel" type="continuous">
        <parent link="rear_rocker_link" />
        <child link="rear_right_wheel_link" />
        <origin rpy="0 0 0" xyz="0 -0.2755 0" />
        <axis xyz="0 1 0" />
    </joint>
    <transmission name="rear_wheel_trans">
        <type>transmission_interface/SimpleTransmission</type>
        <joint name="rear_right_wheel">
            <hardwareInterface>hardware_interface/VelocityJointInterface</hardwareInterface>
        </joint>
        <actuator name="rear_right_actuator">
            <mechanicalReduction>1</mechanicalReduction>
            <hardwareInterface>hardware_interface/EffortJointInterface</hardwareInterface>
        </actuator>
    </transmission>
    <link name="base_link" />
    <joint name="base_link_joint" type="fixed">
        <origin rpy="0 0 0" xyz="0 0 0" />
        <parent link="base_link" />
        <child link="chassis_link" />
    </joint>
    <link name="chassis_link">
        <visual>
            <origin rpy="0 0 0" xyz="0 0 0" />
            <geometry>
                <mesh filename="package://ridgeback_description/meshes/body.stl" />
            </geometry>
            <material name="black" />
        </visual>
        <collision>
            <origin xyz="0 0 0" />
            <geometry>
                <mesh filename="package://ridgeback_description/meshes/body-collision.stl" />
            </geometry>
        </collision>
        <inertial>
            <origin rpy="1.57079632679 0 1.57079632679" xyz="0.012 0.002 0.067" />
            <mass value="165.304" />
            <inertia ixx="4.4744" ixy="0.03098" ixz="0.003647" iyy="7.1624" iyz="0.1228" izz="4.6155" />
        </inertial>
    </link>
    <joint name="right_side_cover_link_joint" type="fixed">
        <origin rpy="0 0 0" xyz="0 0 0" />
        <parent link="chassis_link" />
        <child link="right_side_cover_link" />
    </joint>
    <joint name="left_side_cover_link_joint" type="fixed">
        <origin rpy="0 0 0" xyz="0 0 0" />
        <parent link="chassis_link" />
        <child link="left_side_cover_link" />
    </joint>
    <link name="left_side_cover_link">
        <visual>
            <origin rpy="0 0 3.14159265359" xyz="0 0 0" />
            <geometry>
                <mesh filename="package://ridgeback_description/meshes/side-cover.stl" />
            </geometry>
            <material name="yellow" />
        </visual>
    </link>
    <link name="right_side_cover_link">
        <visual>
            <origin rpy="0 0 0" xyz="0 0 0" />
            <geometry>
                <mesh filename="package://ridgeback_description/meshes/side-cover.stl" />
            </geometry>
            <material name="yellow" />
        </visual>
    </link>
    <joint name="front_cover_link_joint" type="fixed">
        <origin rpy="0 0 0" xyz="0 0 0" />
        <parent link="chassis_link" />
        <child link="front_cover_link" />
    </joint>
    <link name="front_cover_link">
        <visual>
            <origin rpy="0 0 0" xyz="0 0 0" />
            <geometry>
                <mesh filename="package://ridgeback_description/meshes/end-cover.stl" />
            </geometry>
            <material name="black" />
        </visual>
    </link>
    <joint name="rear_cover_link_joint" type="fixed">
        <origin rpy="0 0 0" xyz="0 0 0" />
        <parent link="chassis_link" />
        <child link="rear_cover_link" />
    </joint>
    <link name="rear_cover_link">
        <visual>
            <origin rpy="0 0 3.14159265359" xyz="0 0 0" />
            <geometry>
                <mesh filename="package://ridgeback_description/meshes/end-cover.stl" />
            </geometry>
            <material name="black" />
        </visual>
    </link>
    <joint name="front_lights_link_joint" type="fixed">
        <origin rpy="0 0 0" xyz="0 0 0" />
        <parent link="chassis_link" />
        <child link="front_lights_link" />
    </joint>
    <joint name="rear_lights_link_joint" type="fixed">
        <origin rpy="0 0 0" xyz="0 0 0" />
        <parent link="chassis_link" />
        <child link="rear_lights_link" />
    </joint>
    <link name="front_lights_link">
        <visual>
            <origin rpy="0 0 0" xyz="0 0 0" />
            <geometry>
                <mesh filename="package://ridgeback_description/meshes/lights.stl" />
            </geometry>
            <material name="white" />
        </visual>
    </link>
    <link name="rear_lights_link">
        <visual>
            <origin rpy="0 0 3.14159265359" xyz="0 0 0" />
            <geometry>
                <mesh filename="package://ridgeback_description/meshes/lights.stl" />
            </geometry>
            <material name="red" />
        </visual>
    </link>
    <joint name="top_link_joint" type="fixed">
        <origin rpy="0 0 0" xyz="0 0 0" />
        <parent link="chassis_link" />
        <child link="top_link" />
    </joint>
    <link name="top_link">
        <visual>
            <origin rpy="0 0 0" xyz="0 0 0" />
            <geometry>
                <mesh filename="package://ridgeback_description/meshes/top.stl" />
            </geometry>
            <material name="black" />
        </visual>
        <collision>
            <origin rpy="0 0 0" xyz="0 0 0" />
            <geometry>
                <mesh filename="package://ridgeback_description/meshes/top.stl" />
            </geometry>
        </collision>
        <inertial>
            <mass value="0.1" />
            <origin xyz="0 0 0" rpy="0 0 0" />
            <inertia ixx="0.03" iyy="0.03" izz="0.03" ixy="0.0" ixz="0.0" iyz="0.0" />
        </inertial>
    </link>
    <joint name="axle_joint" type="fixed">
        <origin rpy="0 0 0" xyz="0 0 0.05" />
        <parent link="chassis_link" />
        <child link="axle_link" />
    </joint>
    <link name="axle_link">
        <visual>
            <origin rpy="0 1.57079632679 0" xyz="0 0 0" />
            <geometry>
                <mesh filename="package://ridgeback_description/meshes/axle.stl" />
            </geometry>
            <material name="black" />
        </visual>
    </link>
    <link name="imu_link">
        <inertial>
            <mass value="0.001" />
            <origin rpy="0 0 0" xyz="0 0 0" />
            <inertia ixx="1e-09" ixy="0.0" ixz="0.0" iyy="1e-09" iyz="0.0" izz="1e-09" />
        </inertial>
    </link>
    <joint name="imu_joint" type="fixed">
        <parent link="chassis_link" />
        <child link="imu_link" />
        <origin rpy="0 0 0" xyz="0.2085 -0.2902 0.1681" />
    </joint>
    <link name="mid_mount" />
    <joint name="mid_mount_joint" type="fixed">
        <parent link="base_link" />
        <child link="mid_mount" />
        <origin rpy="0 0 0" xyz="0 0 0.28" />
    </joint>
    <gazebo>
        <plugin filename="libgazebo_ros_control.so" name="gazebo_ros_control">
            <robotNamespace>/</robotNamespace>
        </plugin>
        <plugin filename="libridgeback_ros_force_based_move.so" name="ridgeback_ros_force_based_move">
            <robotNamespace>/</robotNamespace>
            <commandTopic>cmd_vel</commandTopic>
            <odometryTopic>odom</odometryTopic>
            <odometryFrame>odom</odometryFrame>
            <odometryRate>25.0</odometryRate>
            <robotBaseFrame>base_link</robotBaseFrame>
            <cmdVelTimeOut>0.25</cmdVelTimeOut>
            <!-- Don't publish a transform: the controller does it. -->
            <publishOdometryTf>0</publishOdometryTf>
            <yaw_velocity_p_gain>500.0</yaw_velocity_p_gain>
            <x_velocity_p_gain>10000.0</x_velocity_p_gain>
            <y_velocity_p_gain>10000.0</y_velocity_p_gain>
        </plugin>
        <plugin filename="libhector_gazebo_ros_imu.so" name="imu_controller">
            <robotNamespace>/</robotNamespace>
            <updateRate>50.0</updateRate>
            <bodyName>imu_link</bodyName>
            <topicName>imu/data</topicName>
            <frameId>base_link</frameId>
            <accelDrift>0.005 0.005 0.005</accelDrift>
            <accelGaussianNoise>0.005 0.005 0.005</accelGaussianNoise>
            <rateDrift>0.00005 0.00005 0.00005</rateDrift>
            <rateGaussianNoise>0.00005 0.00005 0.00005</rateGaussianNoise>
            <headingDrift>0.005</headingDrift>
            <headingGaussianNoise>0.005</headingGaussianNoise>
        </plugin>
        <plugin filename="libgazebo_ros_joint_state_publisher.so" name="gazebo_ros_joint_state_publisher">
            <jointName>front_rocker</jointName>
            <robotNamespace>/</robotNamespace>
            <updateRate>50.0</updateRate>
        </plugin>
    </gazebo>
    <!-- All static links get collapsed down to base_link in Gazebo, so that's
       the one to apply the colour to (in Gazebo 5+). -->
    <gazebo reference="base_link">
        <material>Gazebo/DarkGrey</material>
        <gravity>true</gravity>
    </gazebo>
    <!-- Individual link colouring still needed in Gazebo 2.x -->
    <gazebo reference="chassis_link">
        <material>Gazebo/DarkGrey</material>
    </gazebo>
    <gazebo reference="top_link">
        <material>Gazebo/DarkGrey</material>
    </gazebo>
    <gazebo reference="left_side_cover_link">
        <material>Gazebo/Yellow</material>
    </gazebo>
    <gazebo reference="right_side_cover_link">
        <material>Gazebo/Yellow</material>
    </gazebo>
    <gazebo reference="front_cover_link">
        <material>Gazebo/DarkGrey</material>
    </gazebo>
    <gazebo reference="rear_cover_link">
        <material>Gazebo/DarkGrey</material>
    </gazebo>
    <gazebo reference="front_lights_link">
        <material>Gazebo/White</material>
    </gazebo>
    <gazebo reference="rear_lights_link">
        <material>Gazebo/Red</material>
    </gazebo>
    <gazebo reference="front_rocker_link">
        <material>Gazebo/DarkGrey</material>
    </gazebo>
    <gazebo reference="rear_rocker_link">
        <material>Gazebo/DarkGrey</material>
    </gazebo>
    <gazebo reference="axle_link">
        <material>Gazebo/DarkGrey</material>
    </gazebo>
    <!-- Wheel friction to zero, as movement is handled by applying forces at
       the body level. -->
    <gazebo reference="front_left_wheel_link">
        <material>Gazebo/DarkGrey</material>
        <mu1>0.0</mu1>
        <mu2>0.0</mu2>
    </gazebo>
    <gazebo reference="front_right_wheel_link">
        <material>Gazebo/DarkGrey</material>
        <mu1>0.0</mu1>
        <mu2>0.0</mu2>
    </gazebo>
    <gazebo reference="rear_left_wheel_link">
        <material>Gazebo/DarkGrey</material>
        <mu1>0.0</mu1>
        <mu2>0.0</mu2>
    </gazebo>
    <gazebo reference="rear_right_wheel_link">
        <material>Gazebo/DarkGrey</material>
        <mu1>0.0</mu1>
        <mu2>0.0</mu2>
    </gazebo>
    <!-- This is an wheel-level solution to possibly revisit at a future date. -->
    <!--<gazebo>
    <plugin name="mecanum_gazebo" filename="libmecanum_force_plugin.so">
      <wheelJointName>front_left_wheel</wheelJointName>
      <forceScaleFactor>1</forceScaleFactor>
    </plugin>
    <plugin name="mecanum_gazebo" filename="libmecanum_force_plugin.so">
      <wheelJointName>front_right_wheel</wheelJointName>
      <forceScaleFactor>-1</forceScaleFactor>
    </plugin>
    <plugin name="mecanum_gazebo" filename="libmecanum_force_plugin.so">
      <wheelJointName>rear_left_wheel</wheelJointName>
      <forceScaleFactor>-1</forceScaleFactor>
    </plugin>
    <plugin name="mecanum_gazebo" filename="libmecanum_force_plugin.so">
      <wheelJointName>rear_right_wheel</wheelJointName>
      <forceScaleFactor>1</forceScaleFactor>
    </plugin>
  </gazebo> -->
    <!--
    As you add to this URDF, please be aware that both the robot and
    simulation include it. You must retain compatibility with all of
    the following launch files:

    ridgeback_viz/launch/view_model.launch
    ridgeback_gazebo/launch/ridgeback_world.launch
    ridgeback_base/launch/base.launch
  -->
    <!-- This file is a placeholder which is included by default from
       ridgeback.urdf.xacro. If a robot is being customized and requires
       additional URDF, set the RIDGEBACK_URDF_EXTRAS environment variable
       to the full path of the file you would like included. -->
    <material name="grey">
        <color rgba="0.6 0.6 0.6 1" />
    </material>
    <link name="base_footprint" />
    <joint name="footprint_joint" type="fixed">
        <origin rpy="0 0 0" xyz="0 0 -0.01965" />
        <parent link="base_link" />
        <child link="base_footprint" />
    </joint>
    <link name="base" />
    <joint name="right_base_joint" type="fixed">
        <origin rpy="0 0 0" xyz="0 0 0" />
        <parent link="base_link" />
        <child link="base" />
    </joint>
    <!--link name="base"/>
  <joint name="right_base_joint" type="fixed">
      <origin xyz="0 0 0" rpy="0 0 0"/>
      <parent link="right_arm_base_link"/>
      <child link="right_arm_base"/>
  </joint>  -->
    <joint name="pan_tilt_base_joint" type="fixed">
        <origin rpy="0 0 0" xyz="0.2 0 1.35" />
        <parent link="base_footprint" />
        <child link="pan_tilt_base_link" />
    </joint>
    <link name="pan_tilt_base_link">
        <visual>
            <origin rpy="0 0 -1.57079632679" xyz="0 0 0" />
            <geometry>
                <mesh filename="package://pan_tilt_description/urdf/mesh/base.stl" />
            </geometry>
            <material name="">
                <color rgba="0.2 0.2 0.2 1" />
            </material>
        </visual>
    </link>
    <link name="pan_tilt_yaw_link">
        <visual>
            <origin rpy="0 0 -1.57079632679" xyz="0 0 0" />
            <geometry>
                <mesh filename="package://pan_tilt_description/urdf/mesh/yaw.stl" />
            </geometry>
            <material name="">
                <color rgba="0.2 0.2 0.2 1" />
            </material>
        </visual>
    </link>
    <joint name="pan_tilt_yaw_joint" type="revolute">
        <origin rpy="0.0 0.0 0.0" xyz="0.0 0.0 0.023" />
        <parent link="pan_tilt_base_link" />
        <child link="pan_tilt_yaw_link" />
        <axis xyz="0 0 1" />
        <limit effort="0.0" lower="-1.0471975512" upper="1.0471975512" velocity="0.523598775598" />
    </joint>
    <link name="pan_tilt_pitch_link">
        <visual>
            <origin rpy="0 0 -1.57079632679" xyz="0 0 0" />
            <geometry>
                <mesh filename="package://pan_tilt_description/urdf/mesh/pitch.stl" />
            </geometry>
            <material name="">
                <color rgba="0.2 0.2 0.2 1" />
            </material>
        </visual>
    </link>
    <joint name="pan_tilt_pitch_joint" type="revolute">
        <origin rpy="0.0 0.0 0.0" xyz="0.0 0.0 0.062" />
        <parent link="pan_tilt_yaw_link" />
        <child link="pan_tilt_pitch_link" />
        <axis xyz="0 1 0" />
        <limit effort="0.0" lower="-1.0471975512" upper="1.0471975512" velocity="0.523598775598" />
    </joint>
    <link name="pan_tilt_surface" />
    <joint name="pan_tilt_surface_joint" type="fixed">
        <origin rpy="0 0 0" xyz="0.0 0.0 0.032" />
        <parent link="pan_tilt_pitch_link" />
        <child link="pan_tilt_surface" />
    </joint>
    <link name="dk_camera_mount" />
    <joint name="dk_camera_mount_joint" type="fixed">
        <parent link="pan_tilt_surface" />
        <child link="dk_camera_mount" />
        <origin rpy="0 0 0" xyz="0 0 0" />
    </joint>
    <link name="dk_camera_body">
        <visual>
            <origin xyz="0.0 0.0 0.0" />
            <geometry>
                <box size="0.10046 0.10230 0.0260" />
            </geometry>
            <material name="white" />
        </visual>
    </link>
    <joint name="dk_mount_to_camera_base" type="fixed">
        <parent link="dk_camera_mount" />
        <child link="dk_camera_base" />
        <origin rpy="0.0 0.0 0.0" xyz="0.0623 0.0 0.0065" />
    </joint>
    <link name="dk_camera_base">
        <visual>
            <origin xyz="-0.013 0.0 0.0" />
            <geometry>
                <box size="0.026 0.103 0.039" />
            </geometry>
            <material name="grey" />
        </visual>
    </link>
    <joint name="dk_camera_body_to_body" type="fixed">
        <parent link="dk_camera_base" />
        <child link="dk_camera_body" />
        <origin rpy="0.0 0.0 0.0" xyz="-0.07715 0.0 0.0065" />
    </joint>
    <link name="dk_camera_visor">
        <visual>
            <origin xyz="-0.0128 0.0 0.0" />
            <geometry>
                <box size="0.026 0.101 0.037" />
            </geometry>
            <material name="black" />
        </visual>
    </link>
    <joint name="dk_camera_base_to_visor" type="fixed">
        <parent link="dk_camera_base" />
        <child link="dk_camera_visor" />
        <origin rpy="0.0 0.0 0.0" xyz="0.0 0.0 0." />
    </joint>
    <!-- body -->
    <link name="body_link">
        <visual>
            <origin rpy="0 0 0" xyz="0 0 0" />
            <geometry>
                <mesh filename="package://ridgeback_dual_arm_description/mesh/ridgeback-2xur5e-all-urdf.stl" />
            </geometry>
            <material name="">
                <color rgba="0.2 0.2 0.2 1" />
            </material>
        </visual>
    </link>
    <joint name="body_joint" type="fixed">
        <origin rpy="0 0 0" xyz="0 0 0" />
        <parent link="base_footprint" />
        <child link="body_link" />
    </joint>
    <!-- left_body -->
    <link name="left_body_link" />
    <joint name="left_body_joint" type="fixed">
        <origin rpy="2.35619449019 0 0" xyz="0.2 0.22 1.233" />
        <parent link="base_footprint" />
        <child link="left_body_link" />
    </joint>
    <!-- right_body -->
    <link name="right_body_link" />
    <joint name="right_body_joint" type="fixed">
        <origin rpy="0.785398163397 0 0" xyz="0.2 -0.22 1.233" />
        <parent link="base_footprint" />
        <child link="right_body_link" />
    </joint>
    <!--
    Base UR robot series xacro macro.

    NOTE: this is NOT a URDF. It cannot directly be loaded by consumers
    expecting a flattened '.urdf' file. See the top-level '.xacro' for that
    (but note: that .xacro must still be processed by the xacro command).

    For use in '.launch' files: use one of the 'load_urX.launch' convenience
    launch files.

    This file models the base kinematic chain of a UR robot, which then gets
    parameterised by various configuration files to convert it into a UR3(e),
    UR5(e), UR10(e) or UR16e.

    NOTE: the default kinematic parameters (ie: link lengths, frame locations,
    offets, etc) do not correspond to any particular robot. They are defaults
    only. There WILL be non-zero offsets between the Forward Kinematics results
    in TF (ie: robot_state_publisher) and the values reported by the Teach
    Pendant.

    For accurate (and robot-specific) transforms, the 'kinematics_parameters_file'
    parameter MUST point to a .yaml file containing the appropriate values for
    the targetted robot.

    If using the UniversalRobots/Universal_Robots_ROS_Driver, follow the steps
    described in the readme of that repository to extract the kinematic
    calibration from the controller and generate the required .yaml file.

    Main author of the migration to yaml configs: Ludovic Delval.

    Contributors to previous versions (in no particular order):

     - Felix Messmer
     - Kelsey Hawkins
     - Wim Meeussen
     - Shaun Edwards
     - Nadia Hammoudeh Garcia
     - Dave Hershberger
     - G. vd. Hoorn
     - Philip Long
     - Dave Coleman
     - Miguel Prada
     - Mathias Luedtke
     - Marcel Schnirring
     - Felix von Drigalski
     - Felix Exner
     - Jimmy Da Silva
     - Ajit Krisshna N L
     - Muhammad Asif Rana
  -->
    <!--
    NOTE: the macro defined in this file is NOT part of the public API of this
          package. Users CANNOT rely on this file being available, or stored in
          this location. Nor can they rely on the existence of the macro.
  -->
    <transmission name="left_arm_shoulder_pan_trans">
        <type>transmission_interface/SimpleTransmission</type>
        <joint name="left_arm_shoulder_pan_joint">
            <hardwareInterface>hardware_interface/PositionJointInterface</hardwareInterface>
        </joint>
        <actuator name="left_arm_shoulder_pan_motor">
            <mechanicalReduction>1</mechanicalReduction>
            <hardwareInterface>hardware_interface/EffortJointInterface</hardwareInterface>
        </actuator>
    </transmission>
    <transmission name="left_arm_shoulder_lift_trans">
        <type>transmission_interface/SimpleTransmission</type>
        <joint name="left_arm_shoulder_lift_joint">
            <hardwareInterface>hardware_interface/PositionJointInterface</hardwareInterface>
        </joint>
        <actuator name="left_arm_shoulder_lift_motor">
            <mechanicalReduction>1</mechanicalReduction>
            <hardwareInterface>hardware_interface/EffortJointInterface</hardwareInterface>
        </actuator>
    </transmission>
    <transmission name="left_arm_elbow_trans">
        <type>transmission_interface/SimpleTransmission</type>
        <joint name="left_arm_elbow_joint">
            <hardwareInterface>hardware_interface/PositionJointInterface</hardwareInterface>
        </joint>
        <actuator name="left_arm_elbow_motor">
            <mechanicalReduction>1</mechanicalReduction>
            <hardwareInterface>hardware_interface/EffortJointInterface</hardwareInterface>
        </actuator>
    </transmission>
    <transmission name="left_arm_wrist_1_trans">
        <type>transmission_interface/SimpleTransmission</type>
        <joint name="left_arm_wrist_1_joint">
            <hardwareInterface>hardware_interface/PositionJointInterface</hardwareInterface>
        </joint>
        <actuator name="left_arm_wrist_1_motor">
            <mechanicalReduction>1</mechanicalReduction>
            <hardwareInterface>hardware_interface/EffortJointInterface</hardwareInterface>
        </actuator>
    </transmission>
    <transmission name="left_arm_wrist_2_trans">
        <type>transmission_interface/SimpleTransmission</type>
        <joint name="left_arm_wrist_2_joint">
            <hardwareInterface>hardware_interface/PositionJointInterface</hardwareInterface>
        </joint>
        <actuator name="left_arm_wrist_2_motor">
            <mechanicalReduction>1</mechanicalReduction>
            <hardwareInterface>hardware_interface/EffortJointInterface</hardwareInterface>
        </actuator>
    </transmission>
    <transmission name="left_arm_wrist_3_trans">
        <type>transmission_interface/SimpleTransmission</type>
        <joint name="left_arm_wrist_3_joint">
            <hardwareInterface>hardware_interface/PositionJointInterface</hardwareInterface>
        </joint>
        <actuator name="left_arm_wrist_3_motor">
            <mechanicalReduction>1</mechanicalReduction>
            <hardwareInterface>hardware_interface/EffortJointInterface</hardwareInterface>
        </actuator>
    </transmission>
    <!-- links: main serial chain -->
    <link name="left_arm_base_link" />
    <link name="left_arm_base_link_inertia">
        <visual>
            <origin rpy="0 0 3.14159265359" xyz="0 0 0" />
            <geometry>
                <mesh filename="package://ur_description/meshes/ur5e/visual/base.dae" />
            </geometry>
            <material name="LightGrey">
                <color rgba="0.7 0.7 0.7 1.0" />
            </material>
        </visual>
        <collision>
            <origin rpy="0 0 3.14159265359" xyz="0 0 0" />
            <geometry>
                <mesh filename="package://ur_description/meshes/ur5e/collision/base.stl" />
            </geometry>
        </collision>
        <inertial>
            <mass value="4.0" />
            <origin rpy="0 0 0" xyz="0 0 0" />
            <inertia ixx="0.00443333156" ixy="0.0" ixz="0.0" iyy="0.00443333156" iyz="0.0" izz="0.0072" />
        </inertial>
    </link>
    <link name="left_arm_shoulder_link">
        <visual>
            <origin rpy="0 0 3.14159265359" xyz="0 0 0" />
            <geometry>
                <mesh filename="package://ur_description/meshes/ur5e/visual/shoulder.dae" />
            </geometry>
            <material name="LightGrey">
                <color rgba="0.7 0.7 0.7 1.0" />
            </material>
        </visual>
        <collision>
            <origin rpy="0 0 3.14159265359" xyz="0 0 0" />
            <geometry>
                <mesh filename="package://ur_description/meshes/ur5e/collision/shoulder.stl" />
            </geometry>
        </collision>
        <inertial>
            <mass value="3.7" />
            <origin rpy="0 0 0" xyz="0 0 0" />
            <inertia ixx="0.010267495893" ixy="0.0" ixz="0.0" iyy="0.010267495893" iyz="0.0" izz="0.00666" />
        </inertial>
    </link>
    <link name="left_arm_upper_arm_link">
        <visual>
            <origin rpy="1.57079632679 0 -1.57079632679" xyz="0 0 0.138" />
            <geometry>
                <mesh filename="package://ur_description/meshes/ur5e/visual/upperarm.dae" />
            </geometry>
            <material name="LightGrey">
                <color rgba="0.7 0.7 0.7 1.0" />
            </material>
        </visual>
        <collision>
            <origin rpy="1.57079632679 0 -1.57079632679" xyz="0 0 0.138" />
            <geometry>
                <mesh filename="package://ur_description/meshes/ur5e/collision/upperarm.stl" />
            </geometry>
        </collision>
        <inertial>
            <mass value="8.393" />
            <origin rpy="0 1.57079632679 0" xyz="-0.2125 0.0 0.138" />
            <inertia ixx="0.133885781862" ixy="0.0" ixz="0.0" iyy="0.133885781862" iyz="0.0" izz="0.0151074" />
        </inertial>
    </link>
    <link name="left_arm_forearm_link">
        <visual>
            <origin rpy="1.57079632679 0 -1.57079632679" xyz="0 0 0.007" />
            <geometry>
                <mesh filename="package://ur_description/meshes/ur5e/visual/forearm.dae" />
            </geometry>
            <material name="LightGrey">
                <color rgba="0.7 0.7 0.7 1.0" />
            </material>
        </visual>
        <collision>
            <origin rpy="1.57079632679 0 -1.57079632679" xyz="0 0 0.007" />
            <geometry>
                <mesh filename="package://ur_description/meshes/ur5e/collision/forearm.stl" />
            </geometry>
        </collision>
        <inertial>
            <mass value="2.275" />
            <origin rpy="0 1.57079632679 0" xyz="-0.1961 0.0 0.007" />
            <inertia ixx="0.0312093550996" ixy="0.0" ixz="0.0" iyy="0.0312093550996" iyz="0.0" izz="0.004095" />
        </inertial>
    </link>
    <link name="left_arm_wrist_1_link">
        <visual>
            <!-- TODO: Move this to a parameter -->
            <origin rpy="1.57079632679 0 0" xyz="0 0 -0.127" />
            <geometry>
                <mesh filename="package://ur_description/meshes/ur5e/visual/wrist1.dae" />
            </geometry>
            <material name="LightGrey">
                <color rgba="0.7 0.7 0.7 1.0" />
            </material>
        </visual>
        <collision>
            <origin rpy="1.57079632679 0 0" xyz="0 0 -0.127" />
            <geometry>
                <mesh filename="package://ur_description/meshes/ur5e/collision/wrist1.stl" />
            </geometry>
        </collision>
        <inertial>
            <mass value="1.219" />
            <origin rpy="0 0 0" xyz="0 0 0" />
            <inertia ixx="0.00255989897604" ixy="0.0" ixz="0.0" iyy="0.00255989897604" iyz="0.0" izz="0.0021942" />
        </inertial>
    </link>
    <link name="left_arm_wrist_2_link">
        <visual>
            <origin rpy="0 0 0" xyz="0 0 -0.0997" />
            <geometry>
                <mesh filename="package://ur_description/meshes/ur5e/visual/wrist2.dae" />
            </geometry>
            <material name="LightGrey">
                <color rgba="0.7 0.7 0.7 1.0" />
            </material>
        </visual>
        <collision>
            <origin rpy="0 0 0" xyz="0 0 -0.0997" />
            <geometry>
                <mesh filename="package://ur_description/meshes/ur5e/collision/wrist2.stl" />
            </geometry>
        </collision>
        <inertial>
            <mass value="1.219" />
            <origin rpy="0 0 0" xyz="0 0 0" />
            <inertia ixx="0.00255989897604" ixy="0.0" ixz="0.0" iyy="0.00255989897604" iyz="0.0" izz="0.0021942" />
        </inertial>
    </link>
    <link name="left_arm_wrist_3_link">
        <visual>
            <origin rpy="1.57079632679 0 0" xyz="0 0 -0.0989" />
            <geometry>
                <mesh filename="package://ur_description/meshes/ur5e/visual/wrist3.dae" />
            </geometry>
            <material name="LightGrey">
                <color rgba="0.7 0.7 0.7 1.0" />
            </material>
        </visual>
        <collision>
            <origin rpy="1.57079632679 0 0" xyz="0 0 -0.0989" />
            <geometry>
                <mesh filename="package://ur_description/meshes/ur5e/collision/wrist3.stl" />
            </geometry>
        </collision>
        <inertial>
            <mass value="0.1879" />
            <origin rpy="0 0 0" xyz="0.0 0.0 -0.0229" />
            <inertia ixx="9.89041005217e-05" ixy="0.0" ixz="0.0" iyy="9.89041005217e-05" iyz="0.0" izz="0.0001321171875" />
        </inertial>
    </link>
    <!-- joints: main serial chain -->
    <joint name="left_arm_base_link-base_link_inertia" type="fixed">
        <parent link="left_arm_base_link" />
        <child link="left_arm_base_link_inertia" />
        <!-- 'base_link' is REP-103 aligned (so X+ forward), while the internal
           frames of the robot/controller have X+ pointing backwards.
           Use the joint between 'base_link' and 'base_link_inertia' (a dummy
           link/frame) to introduce the necessary rotation over Z (of pi rad).
      -->
        <origin rpy="0 0 3.14159265359" xyz="0 0 0" />
    </joint>
    <joint name="left_arm_shoulder_pan_joint" type="revolute">
        <parent link="left_arm_base_link_inertia" />
        <child link="left_arm_shoulder_link" />
        <origin rpy="0 0 0" xyz="0 0 0.1625" />
        <axis xyz="0 0 1" />
        <limit effort="150.0" lower="-6.28318530718" upper="6.28318530718" velocity="3.14159265359" />
        <dynamics damping="0" friction="0" />
    </joint>
    <joint name="left_arm_shoulder_lift_joint" type="revolute">
        <parent link="left_arm_shoulder_link" />
        <child link="left_arm_upper_arm_link" />
        <origin rpy="1.570796327 0 0" xyz="0 0 0" />
        <axis xyz="0 0 1" />
        <limit effort="150.0" lower="-6.28318530718" upper="6.28318530718" velocity="3.14159265359" />
        <dynamics damping="0" friction="0" />
    </joint>
    <joint name="left_arm_elbow_joint" type="revolute">
        <parent link="left_arm_upper_arm_link" />
        <child link="left_arm_forearm_link" />
        <origin rpy="0 0 0" xyz="-0.425 0 0" />
        <axis xyz="0 0 1" />
        <limit effort="150.0" lower="-3.14159265359" upper="3.14159265359" velocity="3.14159265359" />
        <dynamics damping="0" friction="0" />
    </joint>
    <joint name="left_arm_wrist_1_joint" type="revolute">
        <parent link="left_arm_forearm_link" />
        <child link="left_arm_wrist_1_link" />
        <origin rpy="0 0 0" xyz="-0.3922 0 0.1333" />
        <axis xyz="0 0 1" />
        <limit effort="28.0" lower="-6.28318530718" upper="6.28318530718" velocity="3.14159265359" />
        <dynamics damping="0" friction="0" />
    </joint>
    <joint name="left_arm_wrist_2_joint" type="revolute">
        <parent link="left_arm_wrist_1_link" />
        <child link="left_arm_wrist_2_link" />
        <origin rpy="1.570796327 0 0" xyz="0 -0.0997 -2.0448811823e-11" />
        <axis xyz="0 0 1" />
        <limit effort="28.0" lower="-6.28318530718" upper="6.28318530718" velocity="3.14159265359" />
        <dynamics damping="0" friction="0" />
    </joint>
    <joint name="left_arm_wrist_3_joint" type="revolute">
        <parent link="left_arm_wrist_2_link" />
        <child link="left_arm_wrist_3_link" />
        <origin rpy="1.57079632659 3.14159265359 3.14159265359" xyz="0 0.0996 -2.04283014801e-11" />
        <axis xyz="0 0 1" />
        <limit effort="28.0" lower="-6.28318530718" upper="6.28318530718" velocity="3.14159265359" />
        <dynamics damping="0" friction="0" />
    </joint>
    <!-- ROS-Industrial 'base' frame: base_link to UR 'Base' Coordinates transform -->
    <link name="left_arm_base" />
    <joint name="left_arm_base_link-base_fixed_joint" type="fixed">
        <!-- Note the rotation over Z of pi radians: as base_link is REP-103
           aligned (ie: has X+ forward, Y+ left and Z+ up), this is needed
           to correctly align 'base' with the 'Base' coordinate system of
           the UR controller.
      -->
        <origin rpy="0 0 3.14159265359" xyz="0 0 0" />
        <parent link="left_arm_base_link" />
        <child link="left_arm_base" />
    </joint>
    <!-- ROS-Industrial 'flange' frame: attachment point for EEF models -->
    <link name="left_arm_flange" />
    <joint name="left_arm_wrist_3-flange" type="fixed">
        <parent link="left_arm_wrist_3_link" />
        <child link="left_arm_flange" />
        <origin rpy="0 -1.57079632679 -1.57079632679" xyz="0 0 0" />
    </joint>
    <!-- ROS-Industrial 'tool0' frame: all-zeros tool frame -->
    <link name="left_arm_tool0" />
    <joint name="left_arm_flange-tool0" type="fixed">
        <!-- default toolframe: X+ left, Y+ up, Z+ front -->
        <origin rpy="1.57079632679 0 1.57079632679" xyz="0 0 0" />
        <parent link="left_arm_flange" />
        <child link="left_arm_tool0" />
    </joint>
    <joint name="left_arm_joint" type="fixed">
        <origin rpy="1.57079632679 1.57079632679 0" xyz="0 0 0" />
        <parent link="left_body_link" />
        <child link="left_arm_base_link" />
    </joint>
    <!-- left gipper flange -->
    <link name="left_gripper_flange">
        <visual>
            <origin rpy="0 0 0" xyz="0 0 0" />
            <geometry>
                <mesh filename="package://ridgeback_dual_arm_description/mesh/3-finger-gripper_fixed-urdf.stl" />
            </geometry>
            <material name="">
                <color rgba="0.2 0.2 0.2 1" />
            </material>
        </visual>
    </link>
    <joint name="left_gripper_flange_joint" type="fixed">
        <origin rpy="0 0 0" xyz="0 0 0" />
        <parent link="left_arm_tool0" />
        <child link="left_gripper_flange" />
    </joint>
    <!-- link list -->
    <link name="left_gripper_finger_1_link_0">
        <visual>
            <origin rpy="0 0 0" xyz="0.020 0 0" />
            <geometry>
                <mesh filename="package://robotiq_3f_gripper_visualization/meshes/robotiq-3f-gripper_articulated/visual/link_0.dae" />
            </geometry>
            <material name="gray">
                <color rgba="0.2 0.2 0.2 1" />
            </material>
        </visual>
        <collision>
            <origin rpy="0 0 0" xyz="0.020 0 0" />
            <geometry>
                <mesh filename="package://robotiq_3f_gripper_visualization/meshes/robotiq-3f-gripper_articulated/collision/link_0.STL" />
            </geometry>
            <material name="yellow">
                <color rgba="0 1 1 1" />
            </material>
        </collision>
        <inertial>
            <origin rpy="0 0 0" xyz="0 0 0" />
            <mass value="0.05" />
            <inertia ixx="0.01" ixy="-0.00002" ixz="0.00001" iyy="0.0008" iyz="0" izz="0.001" />
        </inertial>
    </link>
    <link name="left_gripper_finger_1_link_1">
        <visual>
            <origin rpy="0 0 -0.52" xyz="0.050 -.028 0" />
            <geometry>
                <mesh filename="package://robotiq_3f_gripper_visualization/meshes/robotiq-3f-gripper_articulated/visual/link_1.dae" />
            </geometry>
            <material name="gray" />
        </visual>
        <collision>
            <origin rpy="0 0 -0.52" xyz="0.050 -.028 0" />
            <geometry>
                <mesh filename="package://robotiq_3f_gripper_visualization/meshes/robotiq-3f-gripper_articulated/collision/link_1.STL" />
            </geometry>
            <material name="yellow" />
        </collision>
        <inertial>
            <origin rpy="0 0 0" xyz="0 0 0" />
            <mass value="0.15" />
            <inertia ixx="0.001859" ixy="-0.000376" ixz="0.000028" iyy="0.012756" iyz="0" izz="0.0024" />
        </inertial>
    </link>
    <link name="left_gripper_finger_1_link_2">
        <!--
			NOTE: This link has an offset in the z-direction based on the models that were
			used to generate grap-it poses.  With the offset below the model appears visually
			correct, but it is suspect.
			-->
        <visual>
            <origin rpy="0 0 0" xyz="0.039 0 0.0075" />
            <geometry>
                <mesh filename="package://robotiq_3f_gripper_visualization/meshes/robotiq-3f-gripper_articulated/visual/link_2.dae" />
            </geometry>
            <material name="gray" />
        </visual>
        <collision>
            <origin rpy="0 0 0" xyz="0.039 0 0.0075" />
            <geometry>
                <mesh filename="package://robotiq_3f_gripper_visualization/meshes/robotiq-3f-gripper_articulated/collision/link_2.STL" />
            </geometry>
            <material name="yellow" />
        </collision>
        <inertial>
            <origin rpy="0 0 0" xyz="0 0 0" />
            <mass value="0.15" />
            <inertia ixx="0.001859" ixy="-0.000376" ixz="0.000028" iyy="0.012756" iyz="0" izz="0.0024" />
        </inertial>
    </link>
    <link name="left_gripper_finger_1_link_3">
        <visual>
            <origin rpy="0 0 0.52" xyz="0 0 0" />
            <geometry>
                <mesh filename="package://robotiq_3f_gripper_visualization/meshes/robotiq-3f-gripper_articulated/visual/link_3.dae" />
            </geometry>
            <material name="gray" />
        </visual>
        <collision>
            <origin rpy="0 0 0.52" xyz="0 0 0" />
            <geometry>
                <mesh filename="package://robotiq_3f_gripper_visualization/meshes/robotiq-3f-gripper_articulated/collision/link_3.STL" />
            </geometry>
            <material name="yellow" />
        </collision>
        <inertial>
            <origin rpy="0 0 0" xyz="0 0 0" />
            <mass value="0.05" />
            <inertia ixx="0.001239" ixy="-0.000251" ixz="0.000019" iyy="0.00085" iyz="0" izz="0.001632" />
        </inertial>
    </link>
    <!-- end of link list -->
    <!-- joint list -->
    <joint name="left_gripper_finger_1_joint_1" type="revolute">
        <parent link="left_gripper_finger_1_link_0" />
        <child link="left_gripper_finger_1_link_1" />
        <axis xyz="0 0 1" />
        <origin rpy="0 0 0" xyz="0.020 0 0" />
        <limit effort="100" lower="0.0495" upper="1.2218" velocity="100" />
    </joint>
    <joint name="left_gripper_finger_1_joint_2" type="revolute">
        <parent link="left_gripper_finger_1_link_1" />
        <child link="left_gripper_finger_1_link_2" />
        <axis xyz="0 0 1" />
        <origin rpy="0 0 -0.52" xyz="0.050 -.028 0" />
        <limit effort="100" lower="0.0" upper="1.5708" velocity="100" />
    </joint>
    <joint name="left_gripper_finger_1_joint_3" type="revolute">
        <parent link="left_gripper_finger_1_link_2" />
        <child link="left_gripper_finger_1_link_3" />
        <axis xyz="0 0 1" />
        <origin rpy="0 0 0" xyz="0.039 0 0" />
        <limit effort="100" lower="-1.2217" upper="-0.0523" velocity="100" />
    </joint>
    <!-- end of joint list -->
    <!-- link list -->
    <link name="left_gripper_finger_2_link_0">
        <visual>
            <origin rpy="0 0 0" xyz="0.020 0 0" />
            <geometry>
                <mesh filename="package://robotiq_3f_gripper_visualization/meshes/robotiq-3f-gripper_articulated/visual/link_0.dae" />
            </geometry>
            <material name="gray">
                <color rgba="0.2 0.2 0.2 1" />
            </material>
        </visual>
        <collision>
            <origin rpy="0 0 0" xyz="0.020 0 0" />
            <geometry>
                <mesh filename="package://robotiq_3f_gripper_visualization/meshes/robotiq-3f-gripper_articulated/collision/link_0.STL" />
            </geometry>
            <material name="yellow">
                <color rgba="0 1 1 1" />
            </material>
        </collision>
        <inertial>
            <origin rpy="0 0 0" xyz="0 0 0" />
            <mass value="0.05" />
            <inertia ixx="0.01" ixy="-0.00002" ixz="0.00001" iyy="0.0008" iyz="0" izz="0.001" />
        </inertial>
    </link>
    <link name="left_gripper_finger_2_link_1">
        <visual>
            <origin rpy="0 0 -0.52" xyz="0.050 -.028 0" />
            <geometry>
                <mesh filename="package://robotiq_3f_gripper_visualization/meshes/robotiq-3f-gripper_articulated/visual/link_1.dae" />
            </geometry>
            <material name="gray" />
        </visual>
        <collision>
            <origin rpy="0 0 -0.52" xyz="0.050 -.028 0" />
            <geometry>
                <mesh filename="package://robotiq_3f_gripper_visualization/meshes/robotiq-3f-gripper_articulated/collision/link_1.STL" />
            </geometry>
            <material name="yellow" />
        </collision>
        <inertial>
            <origin rpy="0 0 0" xyz="0 0 0" />
            <mass value="0.15" />
            <inertia ixx="0.001859" ixy="-0.000376" ixz="0.000028" iyy="0.012756" iyz="0" izz="0.0024" />
        </inertial>
    </link>
    <link name="left_gripper_finger_2_link_2">
        <!--
			NOTE: This link has an offset in the z-direction based on the models that were
			used to generate grap-it poses.  With the offset below the model appears visually
			correct, but it is suspect.
			-->
        <visual>
            <origin rpy="0 0 0" xyz="0.039 0 0.0075" />
            <geometry>
                <mesh filename="package://robotiq_3f_gripper_visualization/meshes/robotiq-3f-gripper_articulated/visual/link_2.dae" />
            </geometry>
            <material name="gray" />
        </visual>
        <collision>
            <origin rpy="0 0 0" xyz="0.039 0 0.0075" />
            <geometry>
                <mesh filename="package://robotiq_3f_gripper_visualization/meshes/robotiq-3f-gripper_articulated/collision/link_2.STL" />
            </geometry>
            <material name="yellow" />
        </collision>
        <inertial>
            <origin rpy="0 0 0" xyz="0 0 0" />
            <mass value="0.15" />
            <inertia ixx="0.001859" ixy="-0.000376" ixz="0.000028" iyy="0.012756" iyz="0" izz="0.0024" />
        </inertial>
    </link>
    <link name="left_gripper_finger_2_link_3">
        <visual>
            <origin rpy="0 0 0.52" xyz="0 0 0" />
            <geometry>
                <mesh filename="package://robotiq_3f_gripper_visualization/meshes/robotiq-3f-gripper_articulated/visual/link_3.dae" />
            </geometry>
            <material name="gray" />
        </visual>
        <collision>
            <origin rpy="0 0 0.52" xyz="0 0 0" />
            <geometry>
                <mesh filename="package://robotiq_3f_gripper_visualization/meshes/robotiq-3f-gripper_articulated/collision/link_3.STL" />
            </geometry>
            <material name="yellow" />
        </collision>
        <inertial>
            <origin rpy="0 0 0" xyz="0 0 0" />
            <mass value="0.05" />
            <inertia ixx="0.001239" ixy="-0.000251" ixz="0.000019" iyy="0.00085" iyz="0" izz="0.001632" />
        </inertial>
    </link>
    <!-- end of link list -->
    <!-- joint list -->
    <joint name="left_gripper_finger_2_joint_1" type="revolute">
        <parent link="left_gripper_finger_2_link_0" />
        <child link="left_gripper_finger_2_link_1" />
        <axis xyz="0 0 1" />
        <origin rpy="0 0 0" xyz="0.020 0 0" />
        <limit effort="100" lower="0.0495" upper="1.2218" velocity="100" />
    </joint>
    <joint name="left_gripper_finger_2_joint_2" type="revolute">
        <parent link="left_gripper_finger_2_link_1" />
        <child link="left_gripper_finger_2_link_2" />
        <axis xyz="0 0 1" />
        <origin rpy="0 0 -0.52" xyz="0.050 -.028 0" />
        <limit effort="100" lower="0.0" upper="1.5708" velocity="100" />
    </joint>
    <joint name="left_gripper_finger_2_joint_3" type="revolute">
        <parent link="left_gripper_finger_2_link_2" />
        <child link="left_gripper_finger_2_link_3" />
        <axis xyz="0 0 1" />
        <origin rpy="0 0 0" xyz="0.039 0 0" />
        <limit effort="100" lower="-1.2217" upper="-0.0523" velocity="100" />
    </joint>
    <!-- end of joint list -->
    <!-- link list -->
    <link name="left_gripper_finger_middle_link_0">
        <visual>
            <origin rpy="0 0 0" xyz="0.020 0 0" />
            <geometry>
                <mesh filename="package://robotiq_3f_gripper_visualization/meshes/robotiq-3f-gripper_articulated/visual/link_0.dae" />
            </geometry>
            <material name="gray">
                <color rgba="0.2 0.2 0.2 1" />
            </material>
        </visual>
        <collision>
            <origin rpy="0 0 0" xyz="0.020 0 0" />
            <geometry>
                <mesh filename="package://robotiq_3f_gripper_visualization/meshes/robotiq-3f-gripper_articulated/collision/link_0.STL" />
            </geometry>
            <material name="yellow">
                <color rgba="0 1 1 1" />
            </material>
        </collision>
        <inertial>
            <origin rpy="0 0 0" xyz="0 0 0" />
            <mass value="0.05" />
            <inertia ixx="0.01" ixy="-0.00002" ixz="0.00001" iyy="0.0008" iyz="0" izz="0.001" />
        </inertial>
    </link>
    <link name="left_gripper_finger_middle_link_1">
        <visual>
            <origin rpy="0 0 -0.52" xyz="0.050 -.028 0" />
            <geometry>
                <mesh filename="package://robotiq_3f_gripper_visualization/meshes/robotiq-3f-gripper_articulated/visual/link_1.dae" />
            </geometry>
            <material name="gray" />
        </visual>
        <collision>
            <origin rpy="0 0 -0.52" xyz="0.050 -.028 0" />
            <geometry>
                <mesh filename="package://robotiq_3f_gripper_visualization/meshes/robotiq-3f-gripper_articulated/collision/link_1.STL" />
            </geometry>
            <material name="yellow" />
        </collision>
        <inertial>
            <origin rpy="0 0 0" xyz="0 0 0" />
            <mass value="0.15" />
            <inertia ixx="0.001859" ixy="-0.000376" ixz="0.000028" iyy="0.012756" iyz="0" izz="0.0024" />
        </inertial>
    </link>
    <link name="left_gripper_finger_middle_link_2">
        <!--
			NOTE: This link has an offset in the z-direction based on the models that were
			used to generate grap-it poses.  With the offset below the model appears visually
			correct, but it is suspect.
			-->
        <visual>
            <origin rpy="0 0 0" xyz="0.039 0 0.0075" />
            <geometry>
                <mesh filename="package://robotiq_3f_gripper_visualization/meshes/robotiq-3f-gripper_articulated/visual/link_2.dae" />
            </geometry>
            <material name="gray" />
        </visual>
        <collision>
            <origin rpy="0 0 0" xyz="0.039 0 0.0075" />
            <geometry>
                <mesh filename="package://robotiq_3f_gripper_visualization/meshes/robotiq-3f-gripper_articulated/collision/link_2.STL" />
            </geometry>
            <material name="yellow" />
        </collision>
        <inertial>
            <origin rpy="0 0 0" xyz="0 0 0" />
            <mass value="0.15" />
            <inertia ixx="0.001859" ixy="-0.000376" ixz="0.000028" iyy="0.012756" iyz="0" izz="0.0024" />
        </inertial>
    </link>
    <link name="left_gripper_finger_middle_link_3">
        <visual>
            <origin rpy="0 0 0.52" xyz="0 0 0" />
            <geometry>
                <mesh filename="package://robotiq_3f_gripper_visualization/meshes/robotiq-3f-gripper_articulated/visual/link_3.dae" />
            </geometry>
            <material name="gray" />
        </visual>
        <collision>
            <origin rpy="0 0 0.52" xyz="0 0 0" />
            <geometry>
                <mesh filename="package://robotiq_3f_gripper_visualization/meshes/robotiq-3f-gripper_articulated/collision/link_3.STL" />
            </geometry>
            <material name="yellow" />
        </collision>
        <inertial>
            <origin rpy="0 0 0" xyz="0 0 0" />
            <mass value="0.05" />
            <inertia ixx="0.001239" ixy="-0.000251" ixz="0.000019" iyy="0.00085" iyz="0" izz="0.001632" />
        </inertial>
    </link>
    <!-- end of link list -->
    <!-- joint list -->
    <joint name="left_gripper_finger_middle_joint_1" type="revolute">
        <parent link="left_gripper_finger_middle_link_0" />
        <child link="left_gripper_finger_middle_link_1" />
        <axis xyz="0 0 1" />
        <origin rpy="0 0 0" xyz="0.020 0 0" />
        <limit effort="100" lower="0.0495" upper="1.2218" velocity="100" />
    </joint>
    <joint name="left_gripper_finger_middle_joint_2" type="revolute">
        <parent link="left_gripper_finger_middle_link_1" />
        <child link="left_gripper_finger_middle_link_2" />
        <axis xyz="0 0 1" />
        <origin rpy="0 0 -0.52" xyz="0.050 -.028 0" />
        <limit effort="100" lower="0.0" upper="1.5708" velocity="100" />
    </joint>
    <joint name="left_gripper_finger_middle_joint_3" type="revolute">
        <parent link="left_gripper_finger_middle_link_2" />
        <child link="left_gripper_finger_middle_link_3" />
        <axis xyz="0 0 1" />
        <origin rpy="0 0 0" xyz="0.039 0 0" />
        <limit effort="100" lower="-1.2217" upper="-0.0523" velocity="100" />
    </joint>
    <!-- end of joint list -->
    <!-- link list -->
    <link name="left_gripper_palm">
        <visual>
            <geometry>
                <mesh filename="package://robotiq_3f_gripper_visualization/meshes/robotiq-3f-gripper_articulated/visual/palm.dae" />
            </geometry>
            <material name="gray">
                <color rgba="0.2 0.2 0.2 1" />
            </material>
        </visual>
        <collision>
            <geometry>
                <mesh filename="package://robotiq_3f_gripper_visualization/meshes/robotiq-3f-gripper_articulated/collision/palm.STL" />
            </geometry>
            <material name="yellow">
                <color rgba="0 1 1 1" />
            </material>
        </collision>
        <inertial>
            <mass value="0.1" />
            <origin xyz="0 0 0" rpy="0 0 0" />
            <inertia ixx="0.03" iyy="0.03" izz="0.03" ixy="0.0" ixz="0.0" iyz="0.0" />
        </inertial>
    </link>
    <link name="left_gripper_tool0" />
    <inertial>
        <origin rpy="0 0 0" xyz="0 0 0" />
        <mass value="1.3" />
        <inertia ixx="0.006012" ixy="0.000079" ixz="-0.00024" iyy="0.012892" iyz="0" izz="0.002435" />
    </inertial>
    <!-- end of link list -->
    <!-- joint list -->
    <joint name="left_gripper_palm_finger_1_joint" type="revolute">
        <parent link="left_gripper_palm" />
        <child link="left_gripper_finger_1_link_0" />
        <axis xyz="0 1 0" />
        <origin rpy="0 3.1416 -1.57" xyz="-0.0455 0.0214 0.036" />
        <limit effort="100" lower="-0.1784" upper="0.192" velocity="100" />
    </joint>
    <joint name="left_gripper_palm_finger_2_joint" type="revolute">
        <parent link="left_gripper_palm" />
        <child link="left_gripper_finger_2_link_0" />
        <axis xyz="0 1 0" />
        <origin rpy="0 3.1416 -1.57" xyz="-0.0455 0.0214 -0.036" />
        <limit effort="100" lower="-0.192" upper="0.1784" velocity="100" />
    </joint>
    <joint name="left_gripper_palm_finger_middle_joint" type="fixed">
        <parent link="left_gripper_palm" />
        <child link="left_gripper_finger_middle_link_0" />
        <axis xyz="0 0 1" />
        <origin rpy="0 0 1.57" xyz="0.0455 0.0214 0" />
    </joint>
    <joint name="left_gripper_palm_tool0" type="fixed">
        <parent link="left_gripper_palm" />
        <child link="left_gripper_tool0" />
        <origin rpy="0 0 1.5707" xyz="0.0 0.0875 0.0" />
    </joint>
    <!-- end of joint list -->
    <joint name="left_gripper_joint" type="fixed">
        <origin rpy="1.57079632679 0 -0.785398163397" xyz="0 0 0.068825" />
        <parent link="left_gripper_flange" />
        <child link="left_gripper_palm" />
    </joint>
    <!--
    Base UR robot series xacro macro.

    NOTE: this is NOT a URDF. It cannot directly be loaded by consumers
    expecting a flattened '.urdf' file. See the top-level '.xacro' for that
    (but note: that .xacro must still be processed by the xacro command).

    For use in '.launch' files: use one of the 'load_urX.launch' convenience
    launch files.

    This file models the base kinematic chain of a UR robot, which then gets
    parameterised by various configuration files to convert it into a UR3(e),
    UR5(e), UR10(e) or UR16e.

    NOTE: the default kinematic parameters (ie: link lengths, frame locations,
    offets, etc) do not correspond to any particular robot. They are defaults
    only. There WILL be non-zero offsets between the Forward Kinematics results
    in TF (ie: robot_state_publisher) and the values reported by the Teach
    Pendant.

    For accurate (and robot-specific) transforms, the 'kinematics_parameters_file'
    parameter MUST point to a .yaml file containing the appropriate values for
    the targetted robot.

    If using the UniversalRobots/Universal_Robots_ROS_Driver, follow the steps
    described in the readme of that repository to extract the kinematic
    calibration from the controller and generate the required .yaml file.

    Main author of the migration to yaml configs: Ludovic Delval.

    Contributors to previous versions (in no particular order):

     - Felix Messmer
     - Kelsey Hawkins
     - Wim Meeussen
     - Shaun Edwards
     - Nadia Hammoudeh Garcia
     - Dave Hershberger
     - G. vd. Hoorn
     - Philip Long
     - Dave Coleman
     - Miguel Prada
     - Mathias Luedtke
     - Marcel Schnirring
     - Felix von Drigalski
     - Felix Exner
     - Jimmy Da Silva
     - Ajit Krisshna N L
     - Muhammad Asif Rana
  -->
    <!--
    NOTE: the macro defined in this file is NOT part of the public API of this
          package. Users CANNOT rely on this file being available, or stored in
          this location. Nor can they rely on the existence of the macro.
  -->
    <transmission name="right_arm_shoulder_pan_trans">
        <type>transmission_interface/SimpleTransmission</type>
        <joint name="right_arm_shoulder_pan_joint">
            <hardwareInterface>hardware_interface/PositionJointInterface</hardwareInterface>
        </joint>
        <actuator name="right_arm_shoulder_pan_motor">
            <mechanicalReduction>1</mechanicalReduction>
            <hardwareInterface>hardware_interface/EffortJointInterface</hardwareInterface>
        </actuator>
    </transmission>
    <transmission name="right_arm_shoulder_lift_trans">
        <type>transmission_interface/SimpleTransmission</type>
        <joint name="right_arm_shoulder_lift_joint">
            <hardwareInterface>hardware_interface/PositionJointInterface</hardwareInterface>
        </joint>
        <actuator name="right_arm_shoulder_lift_motor">
            <mechanicalReduction>1</mechanicalReduction>
            <hardwareInterface>hardware_interface/EffortJointInterface</hardwareInterface>
        </actuator>
    </transmission>
    <transmission name="right_arm_elbow_trans">
        <type>transmission_interface/SimpleTransmission</type>
        <joint name="right_arm_elbow_joint">
            <hardwareInterface>hardware_interface/PositionJointInterface</hardwareInterface>
        </joint>
        <actuator name="right_arm_elbow_motor">
            <mechanicalReduction>1</mechanicalReduction>
            <hardwareInterface>hardware_interface/EffortJointInterface</hardwareInterface>
        </actuator>
    </transmission>
    <transmission name="right_arm_wrist_1_trans">
        <type>transmission_interface/SimpleTransmission</type>
        <joint name="right_arm_wrist_1_joint">
            <hardwareInterface>hardware_interface/PositionJointInterface</hardwareInterface>
        </joint>
        <actuator name="right_arm_wrist_1_motor">
            <mechanicalReduction>1</mechanicalReduction>
            <hardwareInterface>hardware_interface/EffortJointInterface</hardwareInterface>
        </actuator>
    </transmission>
    <transmission name="right_arm_wrist_2_trans">
        <type>transmission_interface/SimpleTransmission</type>
        <joint name="right_arm_wrist_2_joint">
            <hardwareInterface>hardware_interface/PositionJointInterface</hardwareInterface>
        </joint>
        <actuator name="right_arm_wrist_2_motor">
            <mechanicalReduction>1</mechanicalReduction>
            <hardwareInterface>hardware_interface/EffortJointInterface</hardwareInterface>
        </actuator>
    </transmission>
    <transmission name="right_arm_wrist_3_trans">
        <type>transmission_interface/SimpleTransmission</type>
        <joint name="right_arm_wrist_3_joint">
            <hardwareInterface>hardware_interface/PositionJointInterface</hardwareInterface>
        </joint>
        <actuator name="right_arm_wrist_3_motor">
            <mechanicalReduction>1</mechanicalReduction>
            <hardwareInterface>hardware_interface/EffortJointInterface</hardwareInterface>
        </actuator>
    </transmission>
    <!-- links: main serial chain -->
    <link name="right_arm_base_link" />
    <link name="right_arm_base_link_inertia">
        <visual>
            <origin rpy="0 0 3.14159265359" xyz="0 0 0" />
            <geometry>
                <mesh filename="package://ur_description/meshes/ur5e/visual/base.dae" />
            </geometry>
            <material name="LightGrey">
                <color rgba="0.7 0.7 0.7 1.0" />
            </material>
        </visual>
        <collision>
            <origin rpy="0 0 3.14159265359" xyz="0 0 0" />
            <geometry>
                <mesh filename="package://ur_description/meshes/ur5e/collision/base.stl" />
            </geometry>
        </collision>
        <inertial>
            <mass value="4.0" />
            <origin rpy="0 0 0" xyz="0 0 0" />
            <inertia ixx="0.00443333156" ixy="0.0" ixz="0.0" iyy="0.00443333156" iyz="0.0" izz="0.0072" />
        </inertial>
    </link>
    <link name="right_arm_shoulder_link">
        <visual>
            <origin rpy="0 0 3.14159265359" xyz="0 0 0" />
            <geometry>
                <mesh filename="package://ur_description/meshes/ur5e/visual/shoulder.dae" />
            </geometry>
            <material name="LightGrey">
                <color rgba="0.7 0.7 0.7 1.0" />
            </material>
        </visual>
        <collision>
            <origin rpy="0 0 3.14159265359" xyz="0 0 0" />
            <geometry>
                <mesh filename="package://ur_description/meshes/ur5e/collision/shoulder.stl" />
            </geometry>
        </collision>
        <inertial>
            <mass value="3.7" />
            <origin rpy="0 0 0" xyz="0 0 0" />
            <inertia ixx="0.010267495893" ixy="0.0" ixz="0.0" iyy="0.010267495893" iyz="0.0" izz="0.00666" />
        </inertial>
    </link>
    <link name="right_arm_upper_arm_link">
        <visual>
            <origin rpy="1.57079632679 0 -1.57079632679" xyz="0 0 0.138" />
            <geometry>
                <mesh filename="package://ur_description/meshes/ur5e/visual/upperarm.dae" />
            </geometry>
            <material name="LightGrey">
                <color rgba="0.7 0.7 0.7 1.0" />
            </material>
        </visual>
        <collision>
            <origin rpy="1.57079632679 0 -1.57079632679" xyz="0 0 0.138" />
            <geometry>
                <mesh filename="package://ur_description/meshes/ur5e/collision/upperarm.stl" />
            </geometry>
        </collision>
        <inertial>
            <mass value="8.393" />
            <origin rpy="0 1.57079632679 0" xyz="-0.2125 0.0 0.138" />
            <inertia ixx="0.133885781862" ixy="0.0" ixz="0.0" iyy="0.133885781862" iyz="0.0" izz="0.0151074" />
        </inertial>
    </link>
    <link name="right_arm_forearm_link">
        <visual>
            <origin rpy="1.57079632679 0 -1.57079632679" xyz="0 0 0.007" />
            <geometry>
                <mesh filename="package://ur_description/meshes/ur5e/visual/forearm.dae" />
            </geometry>
            <material name="LightGrey">
                <color rgba="0.7 0.7 0.7 1.0" />
            </material>
        </visual>
        <collision>
            <origin rpy="1.57079632679 0 -1.57079632679" xyz="0 0 0.007" />
            <geometry>
                <mesh filename="package://ur_description/meshes/ur5e/collision/forearm.stl" />
            </geometry>
        </collision>
        <inertial>
            <mass value="2.275" />
            <origin rpy="0 1.57079632679 0" xyz="-0.1961 0.0 0.007" />
            <inertia ixx="0.0312093550996" ixy="0.0" ixz="0.0" iyy="0.0312093550996" iyz="0.0" izz="0.004095" />
        </inertial>
    </link>
    <link name="right_arm_wrist_1_link">
        <visual>
            <!-- TODO: Move this to a parameter -->
            <origin rpy="1.57079632679 0 0" xyz="0 0 -0.127" />
            <geometry>
                <mesh filename="package://ur_description/meshes/ur5e/visual/wrist1.dae" />
            </geometry>
            <material name="LightGrey">
                <color rgba="0.7 0.7 0.7 1.0" />
            </material>
        </visual>
        <collision>
            <origin rpy="1.57079632679 0 0" xyz="0 0 -0.127" />
            <geometry>
                <mesh filename="package://ur_description/meshes/ur5e/collision/wrist1.stl" />
            </geometry>
        </collision>
        <inertial>
            <mass value="1.219" />
            <origin rpy="0 0 0" xyz="0 0 0" />
            <inertia ixx="0.00255989897604" ixy="0.0" ixz="0.0" iyy="0.00255989897604" iyz="0.0" izz="0.0021942" />
        </inertial>
    </link>
    <link name="right_arm_wrist_2_link">
        <visual>
            <origin rpy="0 0 0" xyz="0 0 -0.0997" />
            <geometry>
                <mesh filename="package://ur_description/meshes/ur5e/visual/wrist2.dae" />
            </geometry>
            <material name="LightGrey">
                <color rgba="0.7 0.7 0.7 1.0" />
            </material>
        </visual>
        <collision>
            <origin rpy="0 0 0" xyz="0 0 -0.0997" />
            <geometry>
                <mesh filename="package://ur_description/meshes/ur5e/collision/wrist2.stl" />
            </geometry>
        </collision>
        <inertial>
            <mass value="1.219" />
            <origin rpy="0 0 0" xyz="0 0 0" />
            <inertia ixx="0.00255989897604" ixy="0.0" ixz="0.0" iyy="0.00255989897604" iyz="0.0" izz="0.0021942" />
        </inertial>
    </link>
    <link name="right_arm_wrist_3_link">
        <visual>
            <origin rpy="1.57079632679 0 0" xyz="0 0 -0.0989" />
            <geometry>
                <mesh filename="package://ur_description/meshes/ur5e/visual/wrist3.dae" />
            </geometry>
            <material name="LightGrey">
                <color rgba="0.7 0.7 0.7 1.0" />
            </material>
        </visual>
        <collision>
            <origin rpy="1.57079632679 0 0" xyz="0 0 -0.0989" />
            <geometry>
                <mesh filename="package://ur_description/meshes/ur5e/collision/wrist3.stl" />
            </geometry>
        </collision>
        <inertial>
            <mass value="0.1879" />
            <origin rpy="0 0 0" xyz="0.0 0.0 -0.0229" />
            <inertia ixx="9.89041005217e-05" ixy="0.0" ixz="0.0" iyy="9.89041005217e-05" iyz="0.0" izz="0.0001321171875" />
        </inertial>
    </link>
    <!-- joints: main serial chain -->
    <joint name="right_arm_base_link-base_link_inertia" type="fixed">
        <parent link="right_arm_base_link" />
        <child link="right_arm_base_link_inertia" />
        <!-- 'base_link' is REP-103 aligned (so X+ forward), while the internal
           frames of the robot/controller have X+ pointing backwards.
           Use the joint between 'base_link' and 'base_link_inertia' (a dummy
           link/frame) to introduce the necessary rotation over Z (of pi rad).
      -->
        <origin rpy="0 0 3.14159265359" xyz="0 0 0" />
    </joint>
    <joint name="right_arm_shoulder_pan_joint" type="revolute">
        <parent link="right_arm_base_link_inertia" />
        <child link="right_arm_shoulder_link" />
        <origin rpy="0 0 0" xyz="0 0 0.1625" />
        <axis xyz="0 0 1" />
        <limit effort="150.0" lower="-6.28318530718" upper="6.28318530718" velocity="3.14159265359" />
        <dynamics damping="0" friction="0" />
    </joint>
    <joint name="right_arm_shoulder_lift_joint" type="revolute">
        <parent link="right_arm_shoulder_link" />
        <child link="right_arm_upper_arm_link" />
        <origin rpy="1.570796327 0 0" xyz="0 0 0" />
        <axis xyz="0 0 1" />
        <limit effort="150.0" lower="-6.28318530718" upper="6.28318530718" velocity="3.14159265359" />
        <dynamics damping="0" friction="0" />
    </joint>
    <joint name="right_arm_elbow_joint" type="revolute">
        <parent link="right_arm_upper_arm_link" />
        <child link="right_arm_forearm_link" />
        <origin rpy="0 0 0" xyz="-0.425 0 0" />
        <axis xyz="0 0 1" />
        <limit effort="150.0" lower="-3.14159265359" upper="3.14159265359" velocity="3.14159265359" />
        <dynamics damping="0" friction="0" />
    </joint>
    <joint name="right_arm_wrist_1_joint" type="revolute">
        <parent link="right_arm_forearm_link" />
        <child link="right_arm_wrist_1_link" />
        <origin rpy="0 0 0" xyz="-0.3922 0 0.1333" />
        <axis xyz="0 0 1" />
        <limit effort="28.0" lower="-6.28318530718" upper="6.28318530718" velocity="3.14159265359" />
        <dynamics damping="0" friction="0" />
    </joint>
    <joint name="right_arm_wrist_2_joint" type="revolute">
        <parent link="right_arm_wrist_1_link" />
        <child link="right_arm_wrist_2_link" />
        <origin rpy="1.570796327 0 0" xyz="0 -0.0997 -2.0448811823e-11" />
        <axis xyz="0 0 1" />
        <limit effort="28.0" lower="-6.28318530718" upper="6.28318530718" velocity="3.14159265359" />
        <dynamics damping="0" friction="0" />
    </joint>
    <joint name="right_arm_wrist_3_joint" type="revolute">
        <parent link="right_arm_wrist_2_link" />
        <child link="right_arm_wrist_3_link" />
        <origin rpy="1.57079632659 3.14159265359 3.14159265359" xyz="0 0.0996 -2.04283014801e-11" />
        <axis xyz="0 0 1" />
        <limit effort="28.0" lower="-6.28318530718" upper="6.28318530718" velocity="3.14159265359" />
        <dynamics damping="0" friction="0" />
    </joint>
    <!-- ROS-Industrial 'base' frame: base_link to UR 'Base' Coordinates transform -->
    <link name="right_arm_base" />
    <joint name="right_arm_base_link-base_fixed_joint" type="fixed">
        <!-- Note the rotation over Z of pi radians: as base_link is REP-103
           aligned (ie: has X+ forward, Y+ left and Z+ up), this is needed
           to correctly align 'base' with the 'Base' coordinate system of
           the UR controller.
      -->
        <origin rpy="0 0 3.14159265359" xyz="0 0 0" />
        <parent link="right_arm_base_link" />
        <child link="right_arm_base" />
    </joint>
    <!-- ROS-Industrial 'flange' frame: attachment point for EEF models -->
    <link name="right_arm_flange" />
    <joint name="right_arm_wrist_3-flange" type="fixed">
        <parent link="right_arm_wrist_3_link" />
        <child link="right_arm_flange" />
        <origin rpy="0 -1.57079632679 -1.57079632679" xyz="0 0 0" />
    </joint>
    <!-- ROS-Industrial 'tool0' frame: all-zeros tool frame -->
    <link name="right_arm_tool0" />
    <joint name="right_arm_flange-tool0" type="fixed">
        <!-- default toolframe: X+ left, Y+ up, Z+ front -->
        <origin rpy="1.57079632679 0 1.57079632679" xyz="0 0 0" />
        <parent link="right_arm_flange" />
        <child link="right_arm_tool0" />
    </joint>
    <joint name="right_arm_joint" type="fixed">
        <origin rpy="1.57079632679 1.57079632679 0" xyz="0 0 0" />
        <parent link="right_body_link" />
        <child link="right_arm_base_link" />
    </joint>
    <!-- right gipper flange -->
    <link name="right_gripper_flange">
        <visual>
            <origin rpy="0 0 0" xyz="0 0 0" />
            <geometry>
                <mesh filename="package://ridgeback_dual_arm_description/mesh/3-finger-gripper_fixed-urdf.stl" />
            </geometry>
            <material name="">
                <color rgba="0.2 0.2 0.2 1" />
            </material>
        </visual>
    </link>
    <joint name="right_gripper_flange_joint" type="fixed">
        <origin rpy="0 0 0" xyz="0 0 0" />
        <parent link="right_arm_tool0" />
        <child link="right_gripper_flange" />
    </joint>
    <!-- link list -->
    <link name="right_gripper_finger_1_link_0">
        <visual>
            <origin rpy="0 0 0" xyz="0.020 0 0" />
            <geometry>
                <mesh filename="package://robotiq_3f_gripper_visualization/meshes/robotiq-3f-gripper_articulated/visual/link_0.dae" />
            </geometry>
            <material name="gray">
                <color rgba="0.2 0.2 0.2 1" />
            </material>
        </visual>
        <collision>
            <origin rpy="0 0 0" xyz="0.020 0 0" />
            <geometry>
                <mesh filename="package://robotiq_3f_gripper_visualization/meshes/robotiq-3f-gripper_articulated/collision/link_0.STL" />
            </geometry>
            <material name="yellow">
                <color rgba="0 1 1 1" />
            </material>
        </collision>
        <inertial>
            <origin rpy="0 0 0" xyz="0 0 0" />
            <mass value="0.05" />
            <inertia ixx="0.01" ixy="-0.00002" ixz="0.00001" iyy="0.0008" iyz="0" izz="0.001" />
        </inertial>
    </link>
    <link name="right_gripper_finger_1_link_1">
        <visual>
            <origin rpy="0 0 -0.52" xyz="0.050 -.028 0" />
            <geometry>
                <mesh filename="package://robotiq_3f_gripper_visualization/meshes/robotiq-3f-gripper_articulated/visual/link_1.dae" />
            </geometry>
            <material name="gray" />
        </visual>
        <collision>
            <origin rpy="0 0 -0.52" xyz="0.050 -.028 0" />
            <geometry>
                <mesh filename="package://robotiq_3f_gripper_visualization/meshes/robotiq-3f-gripper_articulated/collision/link_1.STL" />
            </geometry>
            <material name="yellow" />
        </collision>
        <inertial>
            <origin rpy="0 0 0" xyz="0 0 0" />
            <mass value="0.15" />
            <inertia ixx="0.001859" ixy="-0.000376" ixz="0.000028" iyy="0.012756" iyz="0" izz="0.0024" />
        </inertial>
    </link>
    <link name="right_gripper_finger_1_link_2">
        <!--
			NOTE: This link has an offset in the z-direction based on the models that were
			used to generate grap-it poses.  With the offset below the model appears visually
			correct, but it is suspect.
			-->
        <visual>
            <origin rpy="0 0 0" xyz="0.039 0 0.0075" />
            <geometry>
                <mesh filename="package://robotiq_3f_gripper_visualization/meshes/robotiq-3f-gripper_articulated/visual/link_2.dae" />
            </geometry>
            <material name="gray" />
        </visual>
        <collision>
            <origin rpy="0 0 0" xyz="0.039 0 0.0075" />
            <geometry>
                <mesh filename="package://robotiq_3f_gripper_visualization/meshes/robotiq-3f-gripper_articulated/collision/link_2.STL" />
            </geometry>
            <material name="yellow" />
        </collision>
        <inertial>
            <origin rpy="0 0 0" xyz="0 0 0" />
            <mass value="0.15" />
            <inertia ixx="0.001859" ixy="-0.000376" ixz="0.000028" iyy="0.012756" iyz="0" izz="0.0024" />
        </inertial>
    </link>
    <link name="right_gripper_finger_1_link_3">
        <visual>
            <origin rpy="0 0 0.52" xyz="0 0 0" />
            <geometry>
                <mesh filename="package://robotiq_3f_gripper_visualization/meshes/robotiq-3f-gripper_articulated/visual/link_3.dae" />
            </geometry>
            <material name="gray" />
        </visual>
        <collision>
            <origin rpy="0 0 0.52" xyz="0 0 0" />
            <geometry>
                <mesh filename="package://robotiq_3f_gripper_visualization/meshes/robotiq-3f-gripper_articulated/collision/link_3.STL" />
            </geometry>
            <material name="yellow" />
        </collision>
        <inertial>
            <origin rpy="0 0 0" xyz="0 0 0" />
            <mass value="0.05" />
            <inertia ixx="0.001239" ixy="-0.000251" ixz="0.000019" iyy="0.00085" iyz="0" izz="0.001632" />
        </inertial>
    </link>
    <!-- end of link list -->
    <!-- joint list -->
    <joint name="right_gripper_finger_1_joint_1" type="revolute">
        <parent link="right_gripper_finger_1_link_0" />
        <child link="right_gripper_finger_1_link_1" />
        <axis xyz="0 0 1" />
        <origin rpy="0 0 0" xyz="0.020 0 0" />
        <limit effort="100" lower="0.0495" upper="1.2218" velocity="100" />
    </joint>
    <joint name="right_gripper_finger_1_joint_2" type="revolute">
        <parent link="right_gripper_finger_1_link_1" />
        <child link="right_gripper_finger_1_link_2" />
        <axis xyz="0 0 1" />
        <origin rpy="0 0 -0.52" xyz="0.050 -.028 0" />
        <limit effort="100" lower="0.0" upper="1.5708" velocity="100" />
    </joint>
    <joint name="right_gripper_finger_1_joint_3" type="revolute">
        <parent link="right_gripper_finger_1_link_2" />
        <child link="right_gripper_finger_1_link_3" />
        <axis xyz="0 0 1" />
        <origin rpy="0 0 0" xyz="0.039 0 0" />
        <limit effort="100" lower="-1.2217" upper="-0.0523" velocity="100" />
    </joint>
    <!-- end of joint list -->
    <!-- link list -->
    <link name="right_gripper_finger_2_link_0">
        <visual>
            <origin rpy="0 0 0" xyz="0.020 0 0" />
            <geometry>
                <mesh filename="package://robotiq_3f_gripper_visualization/meshes/robotiq-3f-gripper_articulated/visual/link_0.dae" />
            </geometry>
            <material name="gray">
                <color rgba="0.2 0.2 0.2 1" />
            </material>
        </visual>
        <collision>
            <origin rpy="0 0 0" xyz="0.020 0 0" />
            <geometry>
                <mesh filename="package://robotiq_3f_gripper_visualization/meshes/robotiq-3f-gripper_articulated/collision/link_0.STL" />
            </geometry>
            <material name="yellow">
                <color rgba="0 1 1 1" />
            </material>
        </collision>
        <inertial>
            <origin rpy="0 0 0" xyz="0 0 0" />
            <mass value="0.05" />
            <inertia ixx="0.01" ixy="-0.00002" ixz="0.00001" iyy="0.0008" iyz="0" izz="0.001" />
        </inertial>
    </link>
    <link name="right_gripper_finger_2_link_1">
        <visual>
            <origin rpy="0 0 -0.52" xyz="0.050 -.028 0" />
            <geometry>
                <mesh filename="package://robotiq_3f_gripper_visualization/meshes/robotiq-3f-gripper_articulated/visual/link_1.dae" />
            </geometry>
            <material name="gray" />
        </visual>
        <collision>
            <origin rpy="0 0 -0.52" xyz="0.050 -.028 0" />
            <geometry>
                <mesh filename="package://robotiq_3f_gripper_visualization/meshes/robotiq-3f-gripper_articulated/collision/link_1.STL" />
            </geometry>
            <material name="yellow" />
        </collision>
        <inertial>
            <origin rpy="0 0 0" xyz="0 0 0" />
            <mass value="0.15" />
            <inertia ixx="0.001859" ixy="-0.000376" ixz="0.000028" iyy="0.012756" iyz="0" izz="0.0024" />
        </inertial>
    </link>
    <link name="right_gripper_finger_2_link_2">
        <!--
			NOTE: This link has an offset in the z-direction based on the models that were
			used to generate grap-it poses.  With the offset below the model appears visually
			correct, but it is suspect.
			-->
        <visual>
            <origin rpy="0 0 0" xyz="0.039 0 0.0075" />
            <geometry>
                <mesh filename="package://robotiq_3f_gripper_visualization/meshes/robotiq-3f-gripper_articulated/visual/link_2.dae" />
            </geometry>
            <material name="gray" />
        </visual>
        <collision>
            <origin rpy="0 0 0" xyz="0.039 0 0.0075" />
            <geometry>
                <mesh filename="package://robotiq_3f_gripper_visualization/meshes/robotiq-3f-gripper_articulated/collision/link_2.STL" />
            </geometry>
            <material name="yellow" />
        </collision>
        <inertial>
            <origin rpy="0 0 0" xyz="0 0 0" />
            <mass value="0.15" />
            <inertia ixx="0.001859" ixy="-0.000376" ixz="0.000028" iyy="0.012756" iyz="0" izz="0.0024" />
        </inertial>
    </link>
    <link name="right_gripper_finger_2_link_3">
        <visual>
            <origin rpy="0 0 0.52" xyz="0 0 0" />
            <geometry>
                <mesh filename="package://robotiq_3f_gripper_visualization/meshes/robotiq-3f-gripper_articulated/visual/link_3.dae" />
            </geometry>
            <material name="gray" />
        </visual>
        <collision>
            <origin rpy="0 0 0.52" xyz="0 0 0" />
            <geometry>
                <mesh filename="package://robotiq_3f_gripper_visualization/meshes/robotiq-3f-gripper_articulated/collision/link_3.STL" />
            </geometry>
            <material name="yellow" />
        </collision>
        <inertial>
            <origin rpy="0 0 0" xyz="0 0 0" />
            <mass value="0.05" />
            <inertia ixx="0.001239" ixy="-0.000251" ixz="0.000019" iyy="0.00085" iyz="0" izz="0.001632" />
        </inertial>
    </link>
    <!-- end of link list -->
    <!-- joint list -->
    <joint name="right_gripper_finger_2_joint_1" type="revolute">
        <parent link="right_gripper_finger_2_link_0" />
        <child link="right_gripper_finger_2_link_1" />
        <axis xyz="0 0 1" />
        <origin rpy="0 0 0" xyz="0.020 0 0" />
        <limit effort="100" lower="0.0495" upper="1.2218" velocity="100" />
    </joint>
    <joint name="right_gripper_finger_2_joint_2" type="revolute">
        <parent link="right_gripper_finger_2_link_1" />
        <child link="right_gripper_finger_2_link_2" />
        <axis xyz="0 0 1" />
        <origin rpy="0 0 -0.52" xyz="0.050 -.028 0" />
        <limit effort="100" lower="0.0" upper="1.5708" velocity="100" />
    </joint>
    <joint name="right_gripper_finger_2_joint_3" type="revolute">
        <parent link="right_gripper_finger_2_link_2" />
        <child link="right_gripper_finger_2_link_3" />
        <axis xyz="0 0 1" />
        <origin rpy="0 0 0" xyz="0.039 0 0" />
        <limit effort="100" lower="-1.2217" upper="-0.0523" velocity="100" />
    </joint>
    <!-- end of joint list -->
    <!-- link list -->
    <link name="right_gripper_finger_middle_link_0">
        <visual>
            <origin rpy="0 0 0" xyz="0.020 0 0" />
            <geometry>
                <mesh filename="package://robotiq_3f_gripper_visualization/meshes/robotiq-3f-gripper_articulated/visual/link_0.dae" />
            </geometry>
            <material name="gray">
                <color rgba="0.2 0.2 0.2 1" />
            </material>
        </visual>
        <collision>
            <origin rpy="0 0 0" xyz="0.020 0 0" />
            <geometry>
                <mesh filename="package://robotiq_3f_gripper_visualization/meshes/robotiq-3f-gripper_articulated/collision/link_0.STL" />
            </geometry>
            <material name="yellow">
                <color rgba="0 1 1 1" />
            </material>
        </collision>
        <inertial>
            <origin rpy="0 0 0" xyz="0 0 0" />
            <mass value="0.05" />
            <inertia ixx="0.01" ixy="-0.00002" ixz="0.00001" iyy="0.0008" iyz="0" izz="0.001" />
        </inertial>
    </link>
    <link name="right_gripper_finger_middle_link_1">
        <visual>
            <origin rpy="0 0 -0.52" xyz="0.050 -.028 0" />
            <geometry>
                <mesh filename="package://robotiq_3f_gripper_visualization/meshes/robotiq-3f-gripper_articulated/visual/link_1.dae" />
            </geometry>
            <material name="gray" />
        </visual>
        <collision>
            <origin rpy="0 0 -0.52" xyz="0.050 -.028 0" />
            <geometry>
                <mesh filename="package://robotiq_3f_gripper_visualization/meshes/robotiq-3f-gripper_articulated/collision/link_1.STL" />
            </geometry>
            <material name="yellow" />
        </collision>
        <inertial>
            <origin rpy="0 0 0" xyz="0 0 0" />
            <mass value="0.15" />
            <inertia ixx="0.001859" ixy="-0.000376" ixz="0.000028" iyy="0.012756" iyz="0" izz="0.0024" />
        </inertial>
    </link>
    <link name="right_gripper_finger_middle_link_2">
        <!--
			NOTE: This link has an offset in the z-direction based on the models that were
			used to generate grap-it poses.  With the offset below the model appears visually
			correct, but it is suspect.
			-->
        <visual>
            <origin rpy="0 0 0" xyz="0.039 0 0.0075" />
            <geometry>
                <mesh filename="package://robotiq_3f_gripper_visualization/meshes/robotiq-3f-gripper_articulated/visual/link_2.dae" />
            </geometry>
            <material name="gray" />
        </visual>
        <collision>
            <origin rpy="0 0 0" xyz="0.039 0 0.0075" />
            <geometry>
                <mesh filename="package://robotiq_3f_gripper_visualization/meshes/robotiq-3f-gripper_articulated/collision/link_2.STL" />
            </geometry>
            <material name="yellow" />
        </collision>
        <inertial>
            <origin rpy="0 0 0" xyz="0 0 0" />
            <mass value="0.15" />
            <inertia ixx="0.001859" ixy="-0.000376" ixz="0.000028" iyy="0.012756" iyz="0" izz="0.0024" />
        </inertial>
    </link>
    <link name="right_gripper_finger_middle_link_3">
        <visual>
            <origin rpy="0 0 0.52" xyz="0 0 0" />
            <geometry>
                <mesh filename="package://robotiq_3f_gripper_visualization/meshes/robotiq-3f-gripper_articulated/visual/link_3.dae" />
            </geometry>
            <material name="gray" />
        </visual>
        <collision>
            <origin rpy="0 0 0.52" xyz="0 0 0" />
            <geometry>
                <mesh filename="package://robotiq_3f_gripper_visualization/meshes/robotiq-3f-gripper_articulated/collision/link_3.STL" />
            </geometry>
            <material name="yellow" />
        </collision>
        <inertial>
            <origin rpy="0 0 0" xyz="0 0 0" />
            <mass value="0.05" />
            <inertia ixx="0.001239" ixy="-0.000251" ixz="0.000019" iyy="0.00085" iyz="0" izz="0.001632" />
        </inertial>
    </link>
    <!-- end of link list -->
    <!-- joint list -->
    <joint name="right_gripper_finger_middle_joint_1" type="revolute">
        <parent link="right_gripper_finger_middle_link_0" />
        <child link="right_gripper_finger_middle_link_1" />
        <axis xyz="0 0 1" />
        <origin rpy="0 0 0" xyz="0.020 0 0" />
        <limit effort="100" lower="0.0495" upper="1.2218" velocity="100" />
    </joint>
    <joint name="right_gripper_finger_middle_joint_2" type="revolute">
        <parent link="right_gripper_finger_middle_link_1" />
        <child link="right_gripper_finger_middle_link_2" />
        <axis xyz="0 0 1" />
        <origin rpy="0 0 -0.52" xyz="0.050 -.028 0" />
        <limit effort="100" lower="0.0" upper="1.5708" velocity="100" />
    </joint>
    <joint name="right_gripper_finger_middle_joint_3" type="revolute">
        <parent link="right_gripper_finger_middle_link_2" />
        <child link="right_gripper_finger_middle_link_3" />
        <axis xyz="0 0 1" />
        <origin rpy="0 0 0" xyz="0.039 0 0" />
        <limit effort="100" lower="-1.2217" upper="-0.0523" velocity="100" />
    </joint>
    <!-- end of joint list -->
    <!-- link list -->
    <link name="right_gripper_palm">
        <visual>
            <geometry>
                <mesh filename="package://robotiq_3f_gripper_visualization/meshes/robotiq-3f-gripper_articulated/visual/palm.dae" />
            </geometry>
            <material name="gray">
                <color rgba="0.2 0.2 0.2 1" />
            </material>
        </visual>
        <collision>
            <geometry>
                <mesh filename="package://robotiq_3f_gripper_visualization/meshes/robotiq-3f-gripper_articulated/collision/palm.STL" />
            </geometry>
            <material name="yellow">
                <color rgba="0 1 1 1" />
            </material>
        </collision>
        <inertial>
            <mass value="0.1" />
            <origin xyz="0 0 0" rpy="0 0 0" />
            <inertia ixx="0.03" iyy="0.03" izz="0.03" ixy="0.0" ixz="0.0" iyz="0.0" />
        </inertial>
    </link>
    <link name="right_gripper_tool0" />
    <inertial>
        <origin rpy="0 0 0" xyz="0 0 0" />
        <mass value="1.3" />
        <inertia ixx="0.006012" ixy="0.000079" ixz="-0.00024" iyy="0.012892" iyz="0" izz="0.002435" />
    </inertial>
    <!-- end of link list -->
    <!-- joint list -->
    <joint name="right_gripper_palm_finger_1_joint" type="revolute">
        <parent link="right_gripper_palm" />
        <child link="right_gripper_finger_1_link_0" />
        <axis xyz="0 1 0" />
        <origin rpy="0 3.1416 -1.57" xyz="-0.0455 0.0214 0.036" />
        <limit effort="100" lower="-0.1784" upper="0.192" velocity="100" />
    </joint>
    <joint name="right_gripper_palm_finger_2_joint" type="revolute">
        <parent link="right_gripper_palm" />
        <child link="right_gripper_finger_2_link_0" />
        <axis xyz="0 1 0" />
        <origin rpy="0 3.1416 -1.57" xyz="-0.0455 0.0214 -0.036" />
        <limit effort="100" lower="-0.192" upper="0.1784" velocity="100" />
    </joint>
    <joint name="right_gripper_palm_finger_middle_joint" type="fixed">
        <parent link="right_gripper_palm" />
        <child link="right_gripper_finger_middle_link_0" />
        <axis xyz="0 0 1" />
        <origin rpy="0 0 1.57" xyz="0.0455 0.0214 0" />
    </joint>
    <joint name="right_gripper_palm_tool0" type="fixed">
        <parent link="right_gripper_palm" />
        <child link="right_gripper_tool0" />
        <origin rpy="0 0 1.5707" xyz="0.0 0.0875 0.0" />
    </joint>
    <!-- end of joint list -->
    <joint name="right_gripper_joint" type="fixed">
        <origin rpy="1.57079632679 0 -0.785398163397" xyz="0 0 0.068825" />
        <parent link="right_gripper_flange" />
        <child link="right_gripper_palm" />
    </joint>
    <!-- left_arm_gripper_connect_1 -->
    <link name="left_arm_gripper_connect_1">
        <visual>
            <geometry>
                <cylinder length="0.07" radius="0.009" />
            </geometry>
        </visual>
    </link>
    <joint name="left_arm_gripper_connect_1_joint" type="fixed">
        <origin rpy="0 1.57079632679   0" xyz="0.055 0 0.02675 " />
        <parent link="left_gripper_palm" />
        <child link="left_arm_gripper_connect_1" />
    </joint>
    <!-- left_arm_gripper_connect_2 -->
    <link name="left_arm_gripper_connect_2">
        <visual>
            <geometry>
                <cylinder length="0.07" radius="0.0075" />
            </geometry>
        </visual>
    </link>
    <joint name="left_arm_gripper_connect_2_joint" type="fixed">
        <origin rpy="0 1.57079632679   0" xyz="0.055 0 -0.02675 " />
        <parent link="left_gripper_palm" />
        <child link="left_arm_gripper_connect_2" />
    </joint>
    <!-- right_arm_gripper_connect_1 -->
    <link name="right_arm_gripper_connect_1">
        <visual>
            <geometry>
                <cylinder length="0.07" radius="0.009" />
            </geometry>
        </visual>
    </link>
    <joint name="right_arm_gripper_connect_1_joint" type="fixed">
        <origin rpy="0 1.57079632679   0" xyz="0.055 0 0.02675 " />
        <parent link="right_gripper_palm" />
        <child link="right_arm_gripper_connect_1" />
    </joint>
    <!-- right_arm_gripper_connect_2 -->
    <link name="right_arm_gripper_connect_2">
        <visual>
            <geometry>
                <cylinder length="0.07" radius="0.0075" />
            </geometry>
        </visual>
    </link>
    <joint name="right_arm_gripper_connect_2_joint" type="fixed">
        <origin rpy="0 1.57079632679   0" xyz="0.055 0 -0.02675 " />
        <parent link="right_gripper_palm" />
        <child link="right_arm_gripper_connect_2" />
    </joint>
    <!-- Setup Environment -->
    <!-- 
    link order: world link -> virtual_base_x -> virtual_base_y -> virtual_base_theta -> base_link 
  -->
    <link name="virtual_base_theta" />
    <joint name="base_link_base_theta" type="revolute">
        <parent link="virtual_base_theta" />
        <origin rpy="0 0 0" xyz="0.0 0.0 0.0" />
        <child link="base_link" />
        <axis xyz="0 0 1" />
        <limit effort="20" lower="-3.14" upper="3.14" velocity="5.0" />
    </joint>
    <link name="virtual_base_y" />
    <joint name="base_theta_base_y" type="prismatic">
        <parent link="virtual_base_y" />
        <origin rpy="0 0 0" xyz="0.0 0.0 0.0" />
        <child link="virtual_base_theta" />
        <axis xyz="0 1 0" />
        <limit effort="20" lower="-10" upper="10" velocity="5.0" />
    </joint>
    <link name="virtual_base_x" />
    <joint name="base_y_base_x" type="prismatic">
        <parent link="virtual_base_x" />
        <origin rpy="0 0 0" xyz="0.0 0.0 0.0" />
        <child link="virtual_base_y" />
        <axis xyz="1 0 0" />
        <limit effort="20" lower="-10" upper="10" velocity="5.0" />
    </joint>
    <link name="world" />
    <joint name="world_to_base_footprint" type="fixed">
        <parent link="world" />
        <child link="virtual_base_x" />
        <origin rpy="0 0 0.0" xyz="0.0 0.0 0.0" />
    </joint>
    <!-- ridgeback robot end -->
    <transmission name="trans_front_rocker">
        <type>transmission_interface/SimpleTransmission</type>
        <joint name="front_rocker">
            <hardwareInterface>hardware_interface/EffortJointInterface</hardwareInterface>
        </joint>
        <actuator name="front_rocker_motor">
            <hardwareInterface>hardware_interface/EffortJointInterface</hardwareInterface>
            <mechanicalReduction>1</mechanicalReduction>
        </actuator>
    </transmission>
    <transmission name="trans_pan_tilt_yaw_joint">
        <type>transmission_interface/SimpleTransmission</type>
        <joint name="pan_tilt_yaw_joint">
            <hardwareInterface>hardware_interface/EffortJointInterface</hardwareInterface>
        </joint>
        <actuator name="pan_tilt_yaw_joint_motor">
            <hardwareInterface>hardware_interface/EffortJointInterface</hardwareInterface>
            <mechanicalReduction>1</mechanicalReduction>
        </actuator>
    </transmission>
    <transmission name="trans_pan_tilt_pitch_joint">
        <type>transmission_interface/SimpleTransmission</type>
        <joint name="pan_tilt_pitch_joint">
            <hardwareInterface>hardware_interface/EffortJointInterface</hardwareInterface>
        </joint>
        <actuator name="pan_tilt_pitch_joint_motor">
            <hardwareInterface>hardware_interface/EffortJointInterface</hardwareInterface>
            <mechanicalReduction>1</mechanicalReduction>
        </actuator>
    </transmission>
    <transmission name="trans_left_gripper_finger_1_joint_1">
        <type>transmission_interface/SimpleTransmission</type>
        <joint name="left_gripper_finger_1_joint_1">
            <hardwareInterface>hardware_interface/EffortJointInterface</hardwareInterface>
        </joint>
        <actuator name="left_gripper_finger_1_joint_1_motor">
            <hardwareInterface>hardware_interface/EffortJointInterface</hardwareInterface>
            <mechanicalReduction>1</mechanicalReduction>
        </actuator>
    </transmission>
    <transmission name="trans_left_gripper_finger_1_joint_2">
        <type>transmission_interface/SimpleTransmission</type>
        <joint name="left_gripper_finger_1_joint_2">
            <hardwareInterface>hardware_interface/EffortJointInterface</hardwareInterface>
        </joint>
        <actuator name="left_gripper_finger_1_joint_2_motor">
            <hardwareInterface>hardware_interface/EffortJointInterface</hardwareInterface>
            <mechanicalReduction>1</mechanicalReduction>
        </actuator>
    </transmission>
    <transmission name="trans_left_gripper_finger_1_joint_3">
        <type>transmission_interface/SimpleTransmission</type>
        <joint name="left_gripper_finger_1_joint_3">
            <hardwareInterface>hardware_interface/EffortJointInterface</hardwareInterface>
        </joint>
        <actuator name="left_gripper_finger_1_joint_3_motor">
            <hardwareInterface>hardware_interface/EffortJointInterface</hardwareInterface>
            <mechanicalReduction>1</mechanicalReduction>
        </actuator>
    </transmission>
    <transmission name="trans_left_gripper_finger_2_joint_1">
        <type>transmission_interface/SimpleTransmission</type>
        <joint name="left_gripper_finger_2_joint_1">
            <hardwareInterface>hardware_interface/EffortJointInterface</hardwareInterface>
        </joint>
        <actuator name="left_gripper_finger_2_joint_1_motor">
            <hardwareInterface>hardware_interface/EffortJointInterface</hardwareInterface>
            <mechanicalReduction>1</mechanicalReduction>
        </actuator>
    </transmission>
    <transmission name="trans_left_gripper_finger_2_joint_2">
        <type>transmission_interface/SimpleTransmission</type>
        <joint name="left_gripper_finger_2_joint_2">
            <hardwareInterface>hardware_interface/EffortJointInterface</hardwareInterface>
        </joint>
        <actuator name="left_gripper_finger_2_joint_2_motor">
            <hardwareInterface>hardware_interface/EffortJointInterface</hardwareInterface>
            <mechanicalReduction>1</mechanicalReduction>
        </actuator>
    </transmission>
    <transmission name="trans_left_gripper_finger_2_joint_3">
        <type>transmission_interface/SimpleTransmission</type>
        <joint name="left_gripper_finger_2_joint_3">
            <hardwareInterface>hardware_interface/EffortJointInterface</hardwareInterface>
        </joint>
        <actuator name="left_gripper_finger_2_joint_3_motor">
            <hardwareInterface>hardware_interface/EffortJointInterface</hardwareInterface>
            <mechanicalReduction>1</mechanicalReduction>
        </actuator>
    </transmission>
    <transmission name="trans_left_gripper_finger_middle_joint_1">
        <type>transmission_interface/SimpleTransmission</type>
        <joint name="left_gripper_finger_middle_joint_1">
            <hardwareInterface>hardware_interface/EffortJointInterface</hardwareInterface>
        </joint>
        <actuator name="left_gripper_finger_middle_joint_1_motor">
            <hardwareInterface>hardware_interface/EffortJointInterface</hardwareInterface>
            <mechanicalReduction>1</mechanicalReduction>
        </actuator>
    </transmission>
    <transmission name="trans_left_gripper_finger_middle_joint_2">
        <type>transmission_interface/SimpleTransmission</type>
        <joint name="left_gripper_finger_middle_joint_2">
            <hardwareInterface>hardware_interface/EffortJointInterface</hardwareInterface>
        </joint>
        <actuator name="left_gripper_finger_middle_joint_2_motor">
            <hardwareInterface>hardware_interface/EffortJointInterface</hardwareInterface>
            <mechanicalReduction>1</mechanicalReduction>
        </actuator>
    </transmission>
    <transmission name="trans_left_gripper_finger_middle_joint_3">
        <type>transmission_interface/SimpleTransmission</type>
        <joint name="left_gripper_finger_middle_joint_3">
            <hardwareInterface>hardware_interface/EffortJointInterface</hardwareInterface>
        </joint>
        <actuator name="left_gripper_finger_middle_joint_3_motor">
            <hardwareInterface>hardware_interface/EffortJointInterface</hardwareInterface>
            <mechanicalReduction>1</mechanicalReduction>
        </actuator>
    </transmission>
    <transmission name="trans_left_gripper_palm_finger_1_joint">
        <type>transmission_interface/SimpleTransmission</type>
        <joint name="left_gripper_palm_finger_1_joint">
            <hardwareInterface>hardware_interface/EffortJointInterface</hardwareInterface>
        </joint>
        <actuator name="left_gripper_palm_finger_1_joint_motor">
            <hardwareInterface>hardware_interface/EffortJointInterface</hardwareInterface>
            <mechanicalReduction>1</mechanicalReduction>
        </actuator>
    </transmission>
    <transmission name="trans_left_gripper_palm_finger_2_joint">
        <type>transmission_interface/SimpleTransmission</type>
        <joint name="left_gripper_palm_finger_2_joint">
            <hardwareInterface>hardware_interface/EffortJointInterface</hardwareInterface>
        </joint>
        <actuator name="left_gripper_palm_finger_2_joint_motor">
            <hardwareInterface>hardware_interface/EffortJointInterface</hardwareInterface>
            <mechanicalReduction>1</mechanicalReduction>
        </actuator>
    </transmission>
    <transmission name="trans_right_gripper_finger_1_joint_1">
        <type>transmission_interface/SimpleTransmission</type>
        <joint name="right_gripper_finger_1_joint_1">
            <hardwareInterface>hardware_interface/EffortJointInterface</hardwareInterface>
        </joint>
        <actuator name="right_gripper_finger_1_joint_1_motor">
            <hardwareInterface>hardware_interface/EffortJointInterface</hardwareInterface>
            <mechanicalReduction>1</mechanicalReduction>
        </actuator>
    </transmission>
    <transmission name="trans_right_gripper_finger_1_joint_2">
        <type>transmission_interface/SimpleTransmission</type>
        <joint name="right_gripper_finger_1_joint_2">
            <hardwareInterface>hardware_interface/EffortJointInterface</hardwareInterface>
        </joint>
        <actuator name="right_gripper_finger_1_joint_2_motor">
            <hardwareInterface>hardware_interface/EffortJointInterface</hardwareInterface>
            <mechanicalReduction>1</mechanicalReduction>
        </actuator>
    </transmission>
    <transmission name="trans_right_gripper_finger_1_joint_3">
        <type>transmission_interface/SimpleTransmission</type>
        <joint name="right_gripper_finger_1_joint_3">
            <hardwareInterface>hardware_interface/EffortJointInterface</hardwareInterface>
        </joint>
        <actuator name="right_gripper_finger_1_joint_3_motor">
            <hardwareInterface>hardware_interface/EffortJointInterface</hardwareInterface>
            <mechanicalReduction>1</mechanicalReduction>
        </actuator>
    </transmission>
    <transmission name="trans_right_gripper_finger_2_joint_1">
        <type>transmission_interface/SimpleTransmission</type>
        <joint name="right_gripper_finger_2_joint_1">
            <hardwareInterface>hardware_interface/EffortJointInterface</hardwareInterface>
        </joint>
        <actuator name="right_gripper_finger_2_joint_1_motor">
            <hardwareInterface>hardware_interface/EffortJointInterface</hardwareInterface>
            <mechanicalReduction>1</mechanicalReduction>
        </actuator>
    </transmission>
    <transmission name="trans_right_gripper_finger_2_joint_2">
        <type>transmission_interface/SimpleTransmission</type>
        <joint name="right_gripper_finger_2_joint_2">
            <hardwareInterface>hardware_interface/EffortJointInterface</hardwareInterface>
        </joint>
        <actuator name="right_gripper_finger_2_joint_2_motor">
            <hardwareInterface>hardware_interface/EffortJointInterface</hardwareInterface>
            <mechanicalReduction>1</mechanicalReduction>
        </actuator>
    </transmission>
    <transmission name="trans_right_gripper_finger_2_joint_3">
        <type>transmission_interface/SimpleTransmission</type>
        <joint name="right_gripper_finger_2_joint_3">
            <hardwareInterface>hardware_interface/EffortJointInterface</hardwareInterface>
        </joint>
        <actuator name="right_gripper_finger_2_joint_3_motor">
            <hardwareInterface>hardware_interface/EffortJointInterface</hardwareInterface>
            <mechanicalReduction>1</mechanicalReduction>
        </actuator>
    </transmission>
    <transmission name="trans_right_gripper_finger_middle_joint_1">
        <type>transmission_interface/SimpleTransmission</type>
        <joint name="right_gripper_finger_middle_joint_1">
            <hardwareInterface>hardware_interface/EffortJointInterface</hardwareInterface>
        </joint>
        <actuator name="right_gripper_finger_middle_joint_1_motor">
            <hardwareInterface>hardware_interface/EffortJointInterface</hardwareInterface>
            <mechanicalReduction>1</mechanicalReduction>
        </actuator>
    </transmission>
    <transmission name="trans_right_gripper_finger_middle_joint_2">
        <type>transmission_interface/SimpleTransmission</type>
        <joint name="right_gripper_finger_middle_joint_2">
            <hardwareInterface>hardware_interface/EffortJointInterface</hardwareInterface>
        </joint>
        <actuator name="right_gripper_finger_middle_joint_2_motor">
            <hardwareInterface>hardware_interface/EffortJointInterface</hardwareInterface>
            <mechanicalReduction>1</mechanicalReduction>
        </actuator>
    </transmission>
    <transmission name="trans_right_gripper_finger_middle_joint_3">
        <type>transmission_interface/SimpleTransmission</type>
        <joint name="right_gripper_finger_middle_joint_3">
            <hardwareInterface>hardware_interface/EffortJointInterface</hardwareInterface>
        </joint>
        <actuator name="right_gripper_finger_middle_joint_3_motor">
            <hardwareInterface>hardware_interface/EffortJointInterface</hardwareInterface>
            <mechanicalReduction>1</mechanicalReduction>
        </actuator>
    </transmission>
    <transmission name="trans_right_gripper_palm_finger_1_joint">
        <type>transmission_interface/SimpleTransmission</type>
        <joint name="right_gripper_palm_finger_1_joint">
            <hardwareInterface>hardware_interface/EffortJointInterface</hardwareInterface>
        </joint>
        <actuator name="right_gripper_palm_finger_1_joint_motor">
            <hardwareInterface>hardware_interface/EffortJointInterface</hardwareInterface>
            <mechanicalReduction>1</mechanicalReduction>
        </actuator>
    </transmission>
    <transmission name="trans_right_gripper_palm_finger_2_joint">
        <type>transmission_interface/SimpleTransmission</type>
        <joint name="right_gripper_palm_finger_2_joint">
            <hardwareInterface>hardware_interface/EffortJointInterface</hardwareInterface>
        </joint>
        <actuator name="right_gripper_palm_finger_2_joint_motor">
            <hardwareInterface>hardware_interface/EffortJointInterface</hardwareInterface>
            <mechanicalReduction>1</mechanicalReduction>
        </actuator>
    </transmission>
    <transmission name="trans_base_link_base_theta">
        <type>transmission_interface/SimpleTransmission</type>
        <joint name="base_link_base_theta">
            <hardwareInterface>hardware_interface/EffortJointInterface</hardwareInterface>
        </joint>
        <actuator name="base_link_base_theta_motor">
            <hardwareInterface>hardware_interface/EffortJointInterface</hardwareInterface>
            <mechanicalReduction>1</mechanicalReduction>
        </actuator>
    </transmission>
    <transmission name="trans_base_theta_base_y">
        <type>transmission_interface/SimpleTransmission</type>
        <joint name="base_theta_base_y">
            <hardwareInterface>hardware_interface/EffortJointInterface</hardwareInterface>
        </joint>
        <actuator name="base_theta_base_y_motor">
            <hardwareInterface>hardware_interface/EffortJointInterface</hardwareInterface>
            <mechanicalReduction>1</mechanicalReduction>
        </actuator>
    </transmission>
    <transmission name="trans_base_y_base_x">
        <type>transmission_interface/SimpleTransmission</type>
        <joint name="base_y_base_x">
            <hardwareInterface>hardware_interface/EffortJointInterface</hardwareInterface>
        </joint>
        <actuator name="base_y_base_x_motor">
            <hardwareInterface>hardware_interface/EffortJointInterface</hardwareInterface>
            <mechanicalReduction>1</mechanicalReduction>
        </actuator>
    </transmission>
</robot>

